Workbook

Sheet Color clustering
B1: image | C1: Pre-alignement | G1: Post-alignement
G2: Random correction | K2: Color classification
A3: 2_filled_cuboid/f_cub_z/Col_clust | C3: #e3bb38 | D3: #e55a49 | E3: #efb58d | F3: #fefefe | G3: #e3bb38 | H3: #e55a49 | I3: #efb58d | J3: #fefefe | K3: #e3bb38 | L3: #e55a49 | M3: #efb58d | N3: #fefefe
B4: 0 | C4: 38025 | D4: 0 | E4: 0 | F4: 121975 | G4: 38025 | H4: 0 | I4: 0 | J4: 121975 | K4: 38025 | L4: 0 | M4: 0 | N4: 121975
B5: 1 | C5: 37618 | D5: 0 | E5: 678 | F5: 121704 | G5: 37862 | H5: 0 | I5: 9 | J5: 122129 | K5: 37623 | L5: 0 | M5: 676 | N5: 121701
B6: 2 | C6: 37817 | D6: 0 | E6: 340 | F6: 121843 | G6: 37917 | H6: 0 | I6: 0 | J6: 122083 | K6: 37748 | L6: 0 | M6: 405 | N6: 121847
B7: 3 | C7: 37738 | D7: 0 | E7: 455 | F7: 121807 | G7: 37896 | H7: 0 | I7: 0 | J7: 122104 | K7: 37716 | L7: 0 | M7: 461 | N7: 121823
B8: 4 | C8: 37782 | D8: 0 | E8: 395 | F8: 121823 | G8: 37950 | H8: 0 | I8: 0 | J8: 122050 | K8: 37726 | L8: 0 | M8: 453 | N8: 121821
B9: 5 | C9: 37663 | D9: 0 | E9: 574 | F9: 121763 | G9: 37916 | H9: 0 | I9: 7 | J9: 122077 | K9: 37654 | L9: 0 | M9: 584 | N9: 121762
B10: 6 | C10: 37636 | D10: 0 | E10: 776 | F10: 121588 | G10: 38037 | H10: 0 | I10: 0 | J10: 121963 | K10: 37715 | L10: 0 | M10: 756 | N10: 121529
B11: 7 | C11: 37592 | D11: 0 | E11: 648 | F11: 121760 | G11: 37895 | H11: 0 | I11: 13 | J11: 122092 | K11: 37596 | L11: 0 | M11: 647 | N11: 121757
B12: 8 | C12: 37821 | D12: 0 | E12: 332 | F12: 121847 | G12: 37940 | H12: 0 | I12: 0 | J12: 122060 | K12: 37754 | L12: 0 | M12: 386 | N12: 121860
B13: 9 | C13: 37727 | D13: 0 | E13: 466 | F13: 121807 | G13: 37879 | H13: 0 | I13: 4 | J13: 122117 | K13: 37681 | L13: 0 | M13: 506 | N13: 121813
B14: 10 | C14: 37813 | D14: 0 | E14: 344 | F14: 121843 | G14: 37977 | H14: 0 | I14: 0 | J14: 122023 | K14: 37739 | L14: 0 | M14: 399 | N14: 121862
B15: 11 | C15: 37672 | D15: 0 | E15: 561 | F15: 121767 | G15: 37917 | H15: 0 | I15: 12 | J15: 122071 | K15: 37658 | L15: 0 | M15: 578 | N15: 121764
... B201: 197 | C201: 37786 | D201: 0 | E201: 434 | F201: 121780 | G201: 38081 | H201: 0 | I201: 0 | J201: 121919 | K201: 37786 | L201: 0 | M201: 434 | N201: 121780
B202: Total | C202: =SUM(C4:C201) -> 7184773 | D202: =SUM(D4:D201) -> 213772 | E202: =SUM(E4:E201) -> 163889 | F202: =SUM(F4:F201) -> 24117566 | G202: =SUM(G4:G201) -> 7407877 | H202: =SUM(H4:H201) -> 1930 | I202: =SUM(I4:I201) -> 102161 | J202: =SUM(J4:J201) -> 24168032 | ... N202: =SUM(N4:N201) -> 24118688
B207: image | C207: Absolute Error | K207: SMAPE
C208: Random correction | G208: Color classification | K208: Random correction | P208: Color classification
A209: 2_filled_cuboid/f_cub_x/Col_clust | C209: #e2bb37 | D209: #e55a49 | E209: #efaa8d | F209: #fefefe | G209: #e2bb37 | H209: #e55a49 | I209: #efaa8d | J209: #fefefe | K209: #e2bb37 | L209: #e55a49 | M209: #efaa8d | N209: #fefefe | P209: #e2bb37 | Q209: #e55a49 | R209: #efaa8d | S209: #fefefe
B210: 0 | C210: =ABS(G4-C4) -> 0 | D210: =ABS(H4-D4) -> 0 | E210: =ABS(I4-E4) -> 0 | F210: =ABS(J4-F4) -> 0 | G210: =ABS(K4-C4) -> 0 | H210: =ABS(L4-D4) -> 0 | I210: =ABS(M4-E4) -> 0 | J210: =ABS(N4-F4) -> 0 | K210: =IF(AND(C4=0, G4=0), 0, ABS(C4-G4)/((ABS(C4)+ABS(G4))/2)) -> 0 | L210: =IF(AND(D4=0, H4=0), 0, ABS(D4-H4)/((ABS(D4)+ABS(H4))/2)) -> 0 | M210: =IF(AND(E4=0, I4=0), 0, ABS(E4-I4)/((ABS(E4)+ABS(I4))/2)) -> 0 | N210: =IF(AND(F4=0, J4=0), 0, ABS(F4-J4)/((ABS(F4)+ABS(J4))/2)) -> 0 | P210: =IF(AND(C4=0, K4=0), 0, ABS(C4-K4)/((ABS(C4)+ABS(K4))/2)) -> 0 | Q210: =IF(AND(D4=0, L4=0), 0, ABS(D4-L4)/((ABS(D4)+ABS(L4))/2)) -> 0 | R210: =IF(AND(E4=0, M4=0), 0, ABS(E4-M4)/((ABS(E4)+ABS(M4))/2)) -> 0 | S210: =IF(AND(F4=0, N4=0), 0, ABS(F4-N4)/((ABS(F4)+ABS(N4))/2)) -> 0
B211: 1 | C211: =ABS(G5-C5) -> 244 | D211: =ABS(H5-D5) -> 0 | E211: =ABS(I5-E5) -> 669 | F211: =ABS(J5-F5) -> 425 | G211: =ABS(K5-C5) -> 5 | H211: =ABS(L5-D5) -> 0 | I211: =ABS(M5-E5) -> 2 | J211: =ABS(N5-F5) -> 3 | K211: =IF(AND(C5=0, G5=0), 0, ABS(C5-G5)/((ABS(C5)+ABS(G5))/2)) -> 0.0064652888 | L211: =IF(AND(D5=0, H5=0), 0, ABS(D5-H5)/((ABS(D5)+ABS(H5))/2)) -> 0 | M211: =IF(AND(E5=0, I5=0), 0, ABS(E5-I5)/((ABS(E5)+ABS(I5))/2)) -> 1.9475983 | N211: =IF(AND(F5=0, J5=0), 0, ABS(F5-J5)/((ABS(F5)+ABS(J5))/2)) -> 0.0034859925 | P211: =IF(AND(C5=0, K5=0), 0, ABS(C5-K5)/((ABS(C5)+ABS(K5))/2)) -> 0.00013290626 | Q211: =IF(AND(D5=0, L5=0), 0, ABS(D5-L5)/((ABS(D5)+ABS(L5))/2)) -> 0 | R211: =IF(AND(E5=0, M5=0), 0, ABS(E5-M5)/((ABS(E5)+ABS(M5))/2)) -> 0.0029542097 | S211: =IF(AND(F5=0, N5=0), 0, ABS(F5-N5)/((ABS(F5)+ABS(N5))/2)) -> 2.4650274e-05
B212: 2 | C212: =ABS(G6-C6) -> 100 | D212: =ABS(H6-D6) -> 0 | E212: =ABS(I6-E6) -> 340 | F212: =ABS(J6-F6) -> 240 | G212: =ABS(K6-C6) -> 69 | H212: =ABS(L6-D6) -> 0 | I212: =ABS(M6-E6) -> 65 | J212: =ABS(N6-F6) -> 4 | K212: =IF(AND(C6=0, G6=0), 0, ABS(C6-G6)/((ABS(C6)+ABS(G6))/2)) -> 0.0026408218 | L212: =IF(AND(D6=0, H6=0), 0, ABS(D6-H6)/((ABS(D6)+ABS(H6))/2)) -> 0 | M212: =IF(AND(E6=0, I6=0), 0, ABS(E6-I6)/((ABS(E6)+ABS(I6))/2)) -> 2 | N212: =IF(AND(F6=0, J6=0), 0, ABS(F6-J6)/((ABS(F6)+ABS(J6))/2)) -> 0.0019678099 | P212: =IF(AND(C6=0, K6=0), 0, ABS(C6-K6)/((ABS(C6)+ABS(K6))/2)) -> 0.0018262423 | Q212: =IF(AND(D6=0, L6=0), 0, ABS(D6-L6)/((ABS(D6)+ABS(L6))/2)) -> 0 | R212: =IF(AND(E6=0, M6=0), 0, ABS(E6-M6)/((ABS(E6)+ABS(M6))/2)) -> 0.17449664 | S212: =IF(AND(F6=0, N6=0), 0, ABS(F6-N6)/((ABS(F6)+ABS(N6))/2)) -> 3.2828594e-05
B213: 3 | C213: =ABS(G7-C7) -> 158 | D213: =ABS(H7-D7) -> 0 | E213: =ABS(I7-E7) -> 455 | F213: =ABS(J7-F7) -> 297 | G213: =ABS(K7-C7) -> 22 | H213: =ABS(L7-D7) -> 0 | I213: =ABS(M7-E7) -> 6 | J213: =ABS(N7-F7) -> 16 | K213: =IF(AND(C7=0, G7=0), 0, ABS(C7-G7)/((ABS(C7)+ABS(G7))/2)) -> 0.0041780152 | L213: =IF(AND(D7=0, H7=0), 0, ABS(D7-H7)/((ABS(D7)+ABS(H7))/2)) -> 0 | M213: =IF(AND(E7=0, I7=0), 0, ABS(E7-I7)/((ABS(E7)+ABS(I7))/2)) -> 2 | N213: =IF(AND(F7=0, J7=0), 0, ABS(F7-J7)/((ABS(F7)+ABS(J7))/2)) -> 0.0024353145 | P213: =IF(AND(C7=0, K7=0), 0, ABS(C7-K7)/((ABS(C7)+ABS(K7))/2)) -> 0.00058313675 | Q213: =IF(AND(D7=0, L7=0), 0, ABS(D7-L7)/((ABS(D7)+ABS(L7))/2)) -> 0 | R213: =IF(AND(E7=0, M7=0), 0, ABS(E7-M7)/((ABS(E7)+ABS(M7))/2)) -> 0.013100437 | S213: =IF(AND(F7=0, N7=0), 0, ABS(F7-N7)/((ABS(F7)+ABS(N7))/2)) -> 0.00013134671
B214: 4 | C214: =ABS(G8-C8) -> 168 | D214: =ABS(H8-D8) -> 0 | E214: =ABS(I8-E8) -> 395 | F214: =ABS(J8-F8) -> 227 | G214: =ABS(K8-C8) -> 56 | H214: =ABS(L8-D8) -> 0 | I214: =ABS(M8-E8) -> 58 | J214: =ABS(N8-F8) -> 2 | K214: =IF(AND(C8=0, G8=0), 0, ABS(C8-G8)/((ABS(C8)+ABS(G8))/2)) -> 0.0044366978 | L214: =IF(AND(D8=0, H8=0), 0, ABS(D8-H8)/((ABS(D8)+ABS(H8))/2)) -> 0 | M214: =IF(AND(E8=0, I8=0), 0, ABS(E8-I8)/((ABS(E8)+ABS(I8))/2)) -> 2 | N214: =IF(AND(F8=0, J8=0), 0, ABS(F8-J8)/((ABS(F8)+ABS(J8))/2)) -> 0.0018616247 | P214: =IF(AND(C8=0, K8=0), 0, ABS(C8-K8)/((ABS(C8)+ABS(K8))/2)) -> 0.0014832865 | Q214: =IF(AND(D8=0, L8=0), 0, ABS(D8-L8)/((ABS(D8)+ABS(L8))/2)) -> 0 | R214: =IF(AND(E8=0, M8=0), 0, ABS(E8-M8)/((ABS(E8)+ABS(M8))/2)) -> 0.13679245 | S214: =IF(AND(F8=0, N8=0), 0, ABS(F8-N8)/((ABS(F8)+ABS(N8))/2)) -> 1.6417396e-05
B215: 5 | C215: =ABS(G9-C9) -> 253 | D215: =ABS(H9-D9) -> 0 | E215: =ABS(I9-E9) -> 567 | F215: =ABS(J9-F9) -> 314 | G215: =ABS(K9-C9) -> 9 | H215: =ABS(L9-D9) -> 0 | I215: =ABS(M9-E9) -> 10 | J215: =ABS(N9-F9) -> 1 | K215: =IF(AND(C9=0, G9=0), 0, ABS(C9-G9)/((ABS(C9)+ABS(G9))/2)) -> 0.0066949814 | L215: =IF(AND(D9=0, H9=0), 0, ABS(D9-H9)/((ABS(D9)+ABS(H9))/2)) -> 0 | M215: =IF(AND(E9=0, I9=0), 0, ABS(E9-I9)/((ABS(E9)+ABS(I9))/2)) -> 1.9518072 | N215: =IF(AND(F9=0, J9=0), 0, ABS(F9-J9)/((ABS(F9)+ABS(J9))/2)) -> 0.0025754593 | P215: =IF(AND(C9=0, K9=0), 0, ABS(C9-K9)/((ABS(C9)+ABS(K9))/2)) -> 0.00023898987 | Q215: =IF(AND(D9=0, L9=0), 0, ABS(D9-L9)/((ABS(D9)+ABS(L9))/2)) -> 0 | R215: =IF(AND(E9=0, M9=0), 0, ABS(E9-M9)/((ABS(E9)+ABS(M9))/2)) -> 0.017271157 | S215: =IF(AND(F9=0, N9=0), 0, ABS(F9-N9)/((ABS(F9)+ABS(N9))/2)) -> 8.2127092e-06
B216: 6 | C216: =ABS(G10-C10) -> 401 | D216: =ABS(H10-D10) -> 0 | E216: =ABS(I10-E10) -> 776 | F216: =ABS(J10-F10) -> 375 | G216: =ABS(K10-C10) -> 79 | H216: =ABS(L10-D10) -> 0 | I216: =ABS(M10-E10) -> 20 | J216: =ABS(N10-F10) -> 59 | K216: =IF(AND(C10=0, G10=0), 0, ABS(C10-G10)/((ABS(C10)+ABS(G10))/2)) -> 0.010598232 | L216: =IF(AND(D10=0, H10=0), 0, ABS(D10-H10)/((ABS(D10)+ABS(H10))/2)) -> 0 | M216: =IF(AND(E10=0, I10=0), 0, ABS(E10-I10)/((ABS(E10)+ABS(I10))/2)) -> 2 | N216: =IF(AND(F10=0, J10=0), 0, ABS(F10-J10)/((ABS(F10)+ABS(J10))/2)) -> 0.0030794372 | P216: =IF(AND(C10=0, K10=0), 0, ABS(C10-K10)/((ABS(C10)+ABS(K10))/2)) -> 0.0020968534 | Q216: =IF(AND(D10=0, L10=0), 0, ABS(D10-L10)/((ABS(D10)+ABS(L10))/2)) -> 0 | R216: =IF(AND(E10=0, M10=0), 0, ABS(E10-M10)/((ABS(E10)+ABS(M10))/2)) -> 0.026109661 | S216: =IF(AND(F10=0, N10=0), 0, ABS(F10-N10)/((ABS(F10)+ABS(N10))/2)) -> 0.00048536301
B217: 7 | C217: =ABS(G11-C11) -> 303 | D217: =ABS(H11-D11) -> 0 | E217: =ABS(I11-E11) -> 635 | F217: =ABS(J11-F11) -> 332 | G217: =ABS(K11-C11) -> 4 | H217: =ABS(L11-D11) -> 0 | I217: =ABS(M11-E11) -> 1 | J217: =ABS(N11-F11) -> 3 | K217: =IF(AND(C11=0, G11=0), 0, ABS(C11-G11)/((ABS(C11)+ABS(G11))/2)) -> 0.0080278723 | L217: =IF(AND(D11=0, H11=0), 0, ABS(D11-H11)/((ABS(D11)+ABS(H11))/2)) -> 0 | M217: =IF(AND(E11=0, I11=0), 0, ABS(E11-I11)/((ABS(E11)+ABS(I11))/2)) -> 1.9213313 | N217: =IF(AND(F11=0, J11=0), 0, ABS(F11-J11)/((ABS(F11)+ABS(J11))/2)) -> 0.0027229631 | P217: =IF(AND(C11=0, K11=0), 0, ABS(C11-K11)/((ABS(C11)+ABS(K11))/2)) -> 0.00010639996 | Q217: =IF(AND(D11=0, L11=0), 0, ABS(D11-L11)/((ABS(D11)+ABS(L11))/2)) -> 0 | R217: =IF(AND(E11=0, M11=0), 0, ABS(E11-M11)/((ABS(E11)+ABS(M11))/2)) -> 0.0015444015 | S217: =IF(AND(F11=0, N11=0), 0, ABS(F11-N11)/((ABS(F11)+ABS(N11))/2)) -> 2.4638937e-05
B218: 8 | C218: =ABS(G12-C12) -> 119 | D218: =ABS(H12-D12) -> 0 | E218: =ABS(I12-E12) -> 332 | F218: =ABS(J12-F12) -> 213 | G218: =ABS(K12-C12) -> 67 | H218: =ABS(L12-D12) -> 0 | I218: =ABS(M12-E12) -> 54 | J218: =ABS(N12-F12) -> 13 | K218: =IF(AND(C12=0, G12=0), 0, ABS(C12-G12)/((ABS(C12)+ABS(G12))/2)) -> 0.003141458 | L218: =IF(AND(D12=0, H12=0), 0, ABS(D12-H12)/((ABS(D12)+ABS(H12))/2)) -> 0 | M218: =IF(AND(E12=0, I12=0), 0, ABS(E12-I12)/((ABS(E12)+ABS(I12))/2)) -> 2 | N218: =IF(AND(F12=0, J12=0), 0, ABS(F12-J12)/((ABS(F12)+ABS(J12))/2)) -> 0.0017465673 | P218: =IF(AND(C12=0, K12=0), 0, ABS(C12-K12)/((ABS(C12)+ABS(K12))/2)) -> 0.0017730731 | Q218: =IF(AND(D12=0, L12=0), 0, ABS(D12-L12)/((ABS(D12)+ABS(L12))/2)) -> 0 | R218: =IF(AND(E12=0, M12=0), 0, ABS(E12-M12)/((ABS(E12)+ABS(M12))/2)) -> 0.15041783 | S218: =IF(AND(F12=0, N12=0), 0, ABS(F12-N12)/((ABS(F12)+ABS(N12))/2)) -> 0.00010668549
B219: 9 | C219: =ABS(G13-C13) -> 152 | D219: =ABS(H13-D13) -> 0 | E219: =ABS(I13-E13) -> 462 | F219: =ABS(J13-F13) -> 310 | G219: =ABS(K13-C13) -> 46 | H219: =ABS(L13-D13) -> 0 | I219: =ABS(M13-E13) -> 40 | J219: =ABS(N13-F13) -> 6 | K219: =IF(AND(C13=0, G13=0), 0, ABS(C13-G13)/((ABS(C13)+ABS(G13))/2)) -> 0.0040208449 | L219: =IF(AND(D13=0, H13=0), 0, ABS(D13-H13)/((ABS(D13)+ABS(H13))/2)) -> 0 | M219: =IF(AND(E13=0, I13=0), 0, ABS(E13-I13)/((ABS(E13)+ABS(I13))/2)) -> 1.9659574 | N219: =IF(AND(F13=0, J13=0), 0, ABS(F13-J13)/((ABS(F13)+ABS(J13))/2)) -> 0.0025417753 | P219: =IF(AND(C13=0, K13=0), 0, ABS(C13-K13)/((ABS(C13)+ABS(K13))/2)) -> 0.0012200297 | Q219: =IF(AND(D13=0, L13=0), 0, ABS(D13-L13)/((ABS(D13)+ABS(L13))/2)) -> 0 | R219: =IF(AND(E13=0, M13=0), 0, ABS(E13-M13)/((ABS(E13)+ABS(M13))/2)) -> 0.082304527 | S219: =IF(AND(F13=0, N13=0), 0, ABS(F13-N13)/((ABS(F13)+ABS(N13))/2)) -> 4.925704e-05
B220: 10 | C220: =ABS(G14-C14) -> 164 | D220: =ABS(H14-D14) -> 0 | E220: =ABS(I14-E14) -> 344 | F220: =ABS(J14-F14) -> 180 | G220: =ABS(K14-C14) -> 74 | H220: =ABS(L14-D14) -> 0 | I220: =ABS(M14-E14) -> 55 | J220: =ABS(N14-F14) -> 19 | K220: =IF(AND(C14=0, G14=0), 0, ABS(C14-G14)/((ABS(C14)+ABS(G14))/2)) -> 0.0043277477 | L220: =IF(AND(D14=0, H14=0), 0, ABS(D14-H14)/((ABS(D14)+ABS(H14))/2)) -> 0 | M220: =IF(AND(E14=0, I14=0), 0, ABS(E14-I14)/((ABS(E14)+ABS(I14))/2)) -> 2 | N220: =IF(AND(F14=0, J14=0), 0, ABS(F14-J14)/((ABS(F14)+ABS(J14))/2)) -> 0.0014762205 | P220: =IF(AND(C14=0, K14=0), 0, ABS(C14-K14)/((ABS(C14)+ABS(K14))/2)) -> 0.0019589157 | Q220: =IF(AND(D14=0, L14=0), 0, ABS(D14-L14)/((ABS(D14)+ABS(L14))/2)) -> 0 | R220: =IF(AND(E14=0, M14=0), 0, ABS(E14-M14)/((ABS(E14)+ABS(M14))/2)) -> 0.14804845 | S220: =IF(AND(F14=0, N14=0), 0, ABS(F14-N14)/((ABS(F14)+ABS(N14))/2)) -> 0.00015592622
B221: 11 | C221: =ABS(G15-C15) -> 245 | D221: =ABS(H15-D15) -> 0 | E221: =ABS(I15-E15) -> 549 | F221: =ABS(J15-F15) -> 304 | G221: =ABS(K15-C15) -> 14 | H221: =ABS(L15-D15) -> 0 | I221: =ABS(M15-E15) -> 17 | J221: =ABS(N15-F15) -> 3 | K221: =IF(AND(C15=0, G15=0), 0, ABS(C15-G15)/((ABS(C15)+ABS(G15))/2)) -> 0.0064824247 | L221: =IF(AND(D15=0, H15=0), 0, ABS(D15-H15)/((ABS(D15)+ABS(H15))/2)) -> 0 | M221: =IF(AND(E15=0, I15=0), 0, ABS(E15-I15)/((ABS(E15)+ABS(I15))/2)) -> 1.9162304 | N221: =IF(AND(F15=0, J15=0), 0, ABS(F15-J15)/((ABS(F15)+ABS(J15))/2)) -> 0.0024934588 | P221: =IF(AND(C15=0, K15=0), 0, ABS(C15-K15)/((ABS(C15)+ABS(K15))/2)) -> 0.00037169786 | Q221: =IF(AND(D15=0, L15=0), 0, ABS(D15-L15)/((ABS(D15)+ABS(L15))/2)) -> 0 | R221: =IF(AND(E15=0, M15=0), 0, ABS(E15-M15)/((ABS(E15)+ABS(M15))/2)) -> 0.029850746 | S221: =IF(AND(F15=0, N15=0), 0, ABS(F15-N15)/((ABS(F15)+ABS(N15))/2)) -> 2.463752e-05
... B406: 196 | C406: =ABS(G200-C200) -> 254 | D406: =ABS(H200-D200) -> 0 | E406: =ABS(I200-E200) -> 553 | F406: =ABS(J200-F200) -> 299 | G406: =ABS(K200-C200) -> 14 | H406: =ABS(L200-D200) -> 0 | I406: =ABS(M200-E200) -> 16 | J406: =ABS(N200-F200) -> 2 | K406: =IF(AND(C200=0, G200=0), 0, ABS(C200-G200)/((ABS(C200)+ABS(G200))/2)) -> 0.0067206435 | L406: =IF(AND(D200=0, H200=0), 0, ABS(D200-H200)/((ABS(D200)+ABS(H200))/2)) -> 0 | M406: =IF(AND(E200=0, I200=0), 0, ABS(E200-I200)/((ABS(E200)+ABS(I200))/2)) -> 1.930192 | N406: =IF(AND(F200=0, J200=0), 0, ABS(F200-J200)/((ABS(F200)+ABS(J200))/2)) -> 0.0024524379 | P406: =IF(AND(C200=0, K200=0), 0, ABS(C200-K200)/((ABS(C200)+ABS(K200))/2)) -> 0.00037174721 | Q406: =IF(AND(D200=0, L200=0), 0, ABS(D200-L200)/((ABS(D200)+ABS(L200))/2)) -> 0 | R406: =IF(AND(E200=0, M200=0), 0, ABS(E200-M200)/((ABS(E200)+ABS(M200))/2)) -> 0.028021016 | S406: =IF(AND(F200=0, N200=0), 0, ABS(F200-N200)/((ABS(F200)+ABS(N200))/2)) -> 1.6424542e-05
B407: 197 | C407: =ABS(G201-C201) -> 295 | D407: =ABS(H201-D201) -> 0 | E407: =ABS(I201-E201) -> 434 | F407: =ABS(J201-F201) -> 139 | G407: =ABS(K201-C201) -> 0 | H407: =ABS(L201-D201) -> 0 | I407: =ABS(M201-E201) -> 0 | J407: =ABS(N201-F201) -> 0 | K407: =IF(AND(C201=0, G201=0), 0, ABS(C201-G201)/((ABS(C201)+ABS(G201))/2)) -> 0.0077767672 | L407: =IF(AND(D201=0, H201=0), 0, ABS(D201-H201)/((ABS(D201)+ABS(H201))/2)) -> 0 | M407: =IF(AND(E201=0, I201=0), 0, ABS(E201-I201)/((ABS(E201)+ABS(I201))/2)) -> 2 | N407: =IF(AND(F201=0, J201=0), 0, ABS(F201-J201)/((ABS(F201)+ABS(J201))/2)) -> 0.0011407515 | O407: Total | P407: =IF(AND(C201=0, K201=0), 0, ABS(C201-K201)/((ABS(C201)+ABS(K201))/2)) -> 0 | Q407: =IF(AND(D201=0, L201=0), 0, ABS(D201-L201)/((ABS(D201)+ABS(L201))/2)) -> 0 | R407: =IF(AND(E201=0, M201=0), 0, ABS(E201-M201)/((ABS(E201)+ABS(M201))/2)) -> 0 | S407: =IF(AND(F201=0, N201=0), 0, ABS(F201-N201)/((ABS(F201)+ABS(N201))/2)) -> 0 | T407: Total
B408: Total | C408: =SUM(C210:C407)/198 -> 1127.303 | D408: =SUM(D210:D407)/198 -> 1069.9091 | E408: =SUM(E210:E407)/198 -> 507.84848 | F408: =SUM(F210:F407)/198 -> 254.87879 | G408: =SUM(G210:G407)/198 -> 40.055556 | H408: =SUM(H210:H407)/198 -> 0.55050505 | I408: =SUM(I210:I407)/198 -> 34.121212 | J408: =SUM(J210:J407)/198 -> 7.9191919 | K408: =SUM(K210:K407)/COUNT(K210:K407) -> 0.031766116 | L408: =SUM(L210:L407)/COUNT(L210:L407) -> 0.60435765 | M408: =SUM(M210:M407)/COUNT(M210:M407) -> 1.2222978 | N408: =SUM(N210:N407)/COUNT(N210:N407) -> 0.002090343 | O408: =SUM(K210:N407)/COUNT(K210:N407) -> 0.46512798 | P408: =SUM(P210:P407)/COUNT(P210:P407) -> 0.0011086616 | Q408: =SUM(Q210:Q407)/COUNT(Q210:Q407) -> 0.00015845798 | R408: =SUM(R210:R407)/COUNT(R210:R407) -> 0.055823623 | S408: =SUM(S210:S407)/COUNT(S210:S407) -> 6.5012049e-05 | T408: =SUM(P210:S407)/COUNT(P210:S407) -> 0.014288939

Sheet Color classification
B1: image | C1: Pre-alignement | G1: Post-alignement
G2: Random correction | K2: Color classification
A3: 2_filled_cuboid/f_cub_z/Col_class | C3: #e3bb37 | D3: #e65a49 | E3: #f08a8c | F3: #ffffff | G3: #e3bb37 | H3: #e65a49 | I3: #f08a8c | J3: #ffffff | K3: #e3bb37 | L3: #e65a49 | M3: #f08a8c | N3: #ffffff
B4: 0 | C4: 38025 | D4: 0 | E4: 0 | F4: 121975 | G4: 38025 | H4: 0 | I4: 0 | J4: 121975 | K4: 38025 | L4: 0 | M4: 0 | N4: 121975
B5: 1 | C5: 37785 | D5: 0 | E5: 361 | F5: 121854 | G5: 37932 | H5: 0 | I5: 0 | J5: 122068 | K5: 37776 | L5: 0 | M5: 373 | N5: 121851
B6: 2 | C6: 37917 | D6: 0 | E6: 168 | F6: 121915 | G6: 37972 | H6: 0 | I6: 0 | J6: 122028 | K6: 37878 | L6: 0 | M6: 185 | N6: 121937
B7: 3 | C7: 37878 | D7: 0 | E7: 225 | F7: 121897 | G7: 37959 | H7: 0 | I7: 0 | J7: 122041 | K7: 37865 | L7: 0 | M7: 208 | N7: 121927
B8: 4 | C8: 37893 | D8: 0 | E8: 200 | F8: 121907 | G8: 37984 | H8: 0 | I8: 0 | J8: 122016 | K8: 37852 | L8: 0 | M8: 230 | N8: 121918
B9: 5 | C9: 37844 | D9: 0 | E9: 270 | F9: 121886 | G9: 37973 | H9: 0 | I9: 0 | J9: 122027 | K9: 37828 | L9: 0 | M9: 280 | N9: 121892
B10: 6 | C10: 37636 | D10: 0 | E10: 716 | F10: 121648 | G10: 37993 | H10: 0 | I10: 0 | J10: 122007 | K10: 37647 | L10: 0 | M10: 712 | N10: 121641
B11: 7 | C11: 37847 | D11: 0 | E11: 254 | F11: 121899 | G11: 37975 | H11: 0 | I11: 0 | J11: 122025 | K11: 37836 | L11: 0 | M11: 265 | N11: 121899
B12: 8 | C12: 37921 | D12: 0 | E12: 168 | F12: 121911 | G12: 37951 | H12: 0 | I12: 0 | J12: 122049 | K12: 37877 | L12: 0 | M12: 189 | N12: 121934
B13: 9 | C13: 37880 | D13: 0 | E13: 221 | F13: 121899 | G13: 37977 | H13: 0 | I13: 0 | J13: 122023 | K13: 37853 | L13: 0 | M13: 246 | N13: 121901
B14: 10 | C14: 37905 | D14: 0 | E14: 180 | F14: 121915 | G14: 37981 | H14: 0 | I14: 0 | J14: 122019 | K14: 37878 | L14: 0 | M14: 182 | N14: 121940
B15: 11 | C15: 37845 | D15: 0 | E15: 263 | F15: 121892 | G15: 37915 | H15: 0 | I15: 0 | J15: 122085 | K15: 37821 | L15: 0 | M15: 288 | N15: 121891
... B201: 197 | C201: 37830 | D201: 0 | E201: 388 | F201: 121782 | G201: 38023 | H201: 0 | I201: 0 | J201: 121977 | K201: 37833 | L201: 0 | M201: 386 | N201: 121781
B202: Total | C202: =SUM(C4:C201) -> 7211308 | D202: =SUM(D4:D201) -> 213361 | E202: =SUM(E4:E201) -> 118974 | F202: =SUM(F4:F201) -> 24136357 | G202: =SUM(G4:G201) -> 7410970 | H202: =SUM(H4:H201) -> 706 | I202: =SUM(I4:I201) -> 103980 | J202: =SUM(J4:J201) -> 24164344 | ... N202: =SUM(N4:N201) -> 24138763
B207: image | C207: Absolute Error | K207: SMAPE
C208: Random correction | G208: Color classification | K208: Random correction | P208: Color classification
A209: 2_filled_cuboid/f_cub_x/Col_clust | C209: #e3bb37 | D209: #e65a49 | E209: #f08a8c | F209: #ffffff | G209: #e3bb37 | H209: #e65a49 | I209: #f08a8c | J209: #ffffff | K209: #e3bb37 | L209: #e65a49 | M209: #f08a8c | N209: #ffffff | P209: #e3bb37 | Q209: #e65a49 | R209: #f08a8c | S209: #ffffff
B210: 0 | C210: =ABS(G4-C4) -> 0 | D210: =ABS(H4-D4) -> 0 | E210: =ABS(I4-E4) -> 0 | F210: =ABS(J4-F4) -> 0 | G210: =ABS(K4-C4) -> 0 | H210: =ABS(L4-D4) -> 0 | I210: =ABS(M4-E4) -> 0 | J210: =ABS(N4-F4) -> 0 | K210: =IF(AND(C4=0, G4=0), 0, ABS(C4-G4)/((ABS(C4)+ABS(G4))/2)) -> 0 | L210: =IF(AND(D4=0, H4=0), 0, ABS(D4-H4)/((ABS(D4)+ABS(H4))/2)) -> 0 | M210: =IF(AND(E4=0, I4=0), 0, ABS(E4-I4)/((ABS(E4)+ABS(I4))/2)) -> 0 | N210: =IF(AND(F4=0, J4=0), 0, ABS(F4-J4)/((ABS(F4)+ABS(J4))/2)) -> 0 | P210: =IF(AND(C4=0, K4=0), 0, ABS(C4-K4)/((ABS(C4)+ABS(K4))/2)) -> 0 | Q210: =IF(AND(D4=0, L4=0), 0, ABS(D4-L4)/((ABS(D4)+ABS(L4))/2)) -> 0 | R210: =IF(AND(E4=0, M4=0), 0, ABS(E4-M4)/((ABS(E4)+ABS(M4))/2)) -> 0 | S210: =IF(AND(F4=0, N4=0), 0, ABS(F4-N4)/((ABS(F4)+ABS(N4))/2)) -> 0
B211: 1 | C211: =ABS(G5-C5) -> 147 | D211: =ABS(H5-D5) -> 0 | E211: =ABS(I5-E5) -> 361 | F211: =ABS(J5-F5) -> 214 | G211: =ABS(K5-C5) -> 9 | H211: =ABS(L5-D5) -> 0 | I211: =ABS(M5-E5) -> 12 | J211: =ABS(N5-F5) -> 3 | K211: =IF(AND(C5=0, G5=0), 0, ABS(C5-G5)/((ABS(C5)+ABS(G5))/2)) -> 0.0038828797 | L211: =IF(AND(D5=0, H5=0), 0, ABS(D5-H5)/((ABS(D5)+ABS(H5))/2)) -> 0 | M211: =IF(AND(E5=0, I5=0), 0, ABS(E5-I5)/((ABS(E5)+ABS(I5))/2)) -> 2 | N211: =IF(AND(F5=0, J5=0), 0, ABS(F5-J5)/((ABS(F5)+ABS(J5))/2)) -> 0.0017546593 | P211: =IF(AND(C5=0, K5=0), 0, ABS(C5-K5)/((ABS(C5)+ABS(K5))/2)) -> 0.00023821813 | Q211: =IF(AND(D5=0, L5=0), 0, ABS(D5-L5)/((ABS(D5)+ABS(L5))/2)) -> 0 | R211: =IF(AND(E5=0, M5=0), 0, ABS(E5-M5)/((ABS(E5)+ABS(M5))/2)) -> 0.032697548 | S211: =IF(AND(F5=0, N5=0), 0, ABS(F5-N5)/((ABS(F5)+ABS(N5))/2)) -> 2.461993e-05
B212: 2 | C212: =ABS(G6-C6) -> 55 | D212: =ABS(H6-D6) -> 0 | E212: =ABS(I6-E6) -> 168 | F212: =ABS(J6-F6) -> 113 | G212: =ABS(K6-C6) -> 39 | H212: =ABS(L6-D6) -> 0 | I212: =ABS(M6-E6) -> 17 | J212: =ABS(N6-F6) -> 22 | K212: =IF(AND(C6=0, G6=0), 0, ABS(C6-G6)/((ABS(C6)+ABS(G6))/2)) -> 0.0014494854 | L212: =IF(AND(D6=0, H6=0), 0, ABS(D6-H6)/((ABS(D6)+ABS(H6))/2)) -> 0 | M212: =IF(AND(E6=0, I6=0), 0, ABS(E6-I6)/((ABS(E6)+ABS(I6))/2)) -> 2 | N212: =IF(AND(F6=0, J6=0), 0, ABS(F6-J6)/((ABS(F6)+ABS(J6))/2)) -> 0.00092644593 | P212: =IF(AND(C6=0, K6=0), 0, ABS(C6-K6)/((ABS(C6)+ABS(K6))/2)) -> 0.0010290916 | Q212: =IF(AND(D6=0, L6=0), 0, ABS(D6-L6)/((ABS(D6)+ABS(L6))/2)) -> 0 | R212: =IF(AND(E6=0, M6=0), 0, ABS(E6-M6)/((ABS(E6)+ABS(M6))/2)) -> 0.09631728 | S212: =IF(AND(F6=0, N6=0), 0, ABS(F6-N6)/((ABS(F6)+ABS(N6))/2)) -> 0.00018043731
B213: 3 | C213: =ABS(G7-C7) -> 81 | D213: =ABS(H7-D7) -> 0 | E213: =ABS(I7-E7) -> 225 | F213: =ABS(J7-F7) -> 144 | G213: =ABS(K7-C7) -> 13 | H213: =ABS(L7-D7) -> 0 | I213: =ABS(M7-E7) -> 17 | J213: =ABS(N7-F7) -> 30 | K213: =IF(AND(C7=0, G7=0), 0, ABS(C7-G7)/((ABS(C7)+ABS(G7))/2)) -> 0.0021361604 | L213: =IF(AND(D7=0, H7=0), 0, ABS(D7-H7)/((ABS(D7)+ABS(H7))/2)) -> 0 | M213: =IF(AND(E7=0, I7=0), 0, ABS(E7-I7)/((ABS(E7)+ABS(I7))/2)) -> 2 | N213: =IF(AND(F7=0, J7=0), 0, ABS(F7-J7)/((ABS(F7)+ABS(J7))/2)) -> 0.0011806279 | P213: =IF(AND(C7=0, K7=0), 0, ABS(C7-K7)/((ABS(C7)+ABS(K7))/2)) -> 0.00034326604 | Q213: =IF(AND(D7=0, L7=0), 0, ABS(D7-L7)/((ABS(D7)+ABS(L7))/2)) -> 0 | R213: =IF(AND(E7=0, M7=0), 0, ABS(E7-M7)/((ABS(E7)+ABS(M7))/2)) -> 0.07852194 | S213: =IF(AND(F7=0, N7=0), 0, ABS(F7-N7)/((ABS(F7)+ABS(N7))/2)) -> 0.00024607914
B214: 4 | C214: =ABS(G8-C8) -> 91 | D214: =ABS(H8-D8) -> 0 | E214: =ABS(I8-E8) -> 200 | F214: =ABS(J8-F8) -> 109 | G214: =ABS(K8-C8) -> 41 | H214: =ABS(L8-D8) -> 0 | I214: =ABS(M8-E8) -> 30 | J214: =ABS(N8-F8) -> 11 | K214: =IF(AND(C8=0, G8=0), 0, ABS(C8-G8)/((ABS(C8)+ABS(G8))/2)) -> 0.0023986188 | L214: =IF(AND(D8=0, H8=0), 0, ABS(D8-H8)/((ABS(D8)+ABS(H8))/2)) -> 0 | M214: =IF(AND(E8=0, I8=0), 0, ABS(E8-I8)/((ABS(E8)+ABS(I8))/2)) -> 2 | N214: =IF(AND(F8=0, J8=0), 0, ABS(F8-J8)/((ABS(F8)+ABS(J8))/2)) -> 0.00089372466 | P214: =IF(AND(C8=0, K8=0), 0, ABS(C8-K8)/((ABS(C8)+ABS(K8))/2)) -> 0.0010825797 | Q214: =IF(AND(D8=0, L8=0), 0, ABS(D8-L8)/((ABS(D8)+ABS(L8))/2)) -> 0 | R214: =IF(AND(E8=0, M8=0), 0, ABS(E8-M8)/((ABS(E8)+ABS(M8))/2)) -> 0.13953488 | S214: =IF(AND(F8=0, N8=0), 0, ABS(F8-N8)/((ABS(F8)+ABS(N8))/2)) -> 9.0228648e-05
B215: 5 | C215: =ABS(G9-C9) -> 129 | D215: =ABS(H9-D9) -> 0 | E215: =ABS(I9-E9) -> 270 | F215: =ABS(J9-F9) -> 141 | G215: =ABS(K9-C9) -> 16 | H215: =ABS(L9-D9) -> 0 | I215: =ABS(M9-E9) -> 10 | J215: =ABS(N9-F9) -> 6 | K215: =IF(AND(C9=0, G9=0), 0, ABS(C9-G9)/((ABS(C9)+ABS(G9))/2)) -> 0.0034029307 | L215: =IF(AND(D9=0, H9=0), 0, ABS(D9-H9)/((ABS(D9)+ABS(H9))/2)) -> 0 | M215: =IF(AND(E9=0, I9=0), 0, ABS(E9-I9)/((ABS(E9)+ABS(I9))/2)) -> 2 | N215: =IF(AND(F9=0, J9=0), 0, ABS(F9-J9)/((ABS(F9)+ABS(J9))/2)) -> 0.0011561499 | P215: =IF(AND(C9=0, K9=0), 0, ABS(C9-K9)/((ABS(C9)+ABS(K9))/2)) -> 0.00042287768 | Q215: =IF(AND(D9=0, L9=0), 0, ABS(D9-L9)/((ABS(D9)+ABS(L9))/2)) -> 0 | R215: =IF(AND(E9=0, M9=0), 0, ABS(E9-M9)/((ABS(E9)+ABS(M9))/2)) -> 0.036363636 | S215: =IF(AND(F9=0, N9=0), 0, ABS(F9-N9)/((ABS(F9)+ABS(N9))/2)) -> 4.9225115e-05
B216: 6 | C216: =ABS(G10-C10) -> 357 | D216: =ABS(H10-D10) -> 0 | E216: =ABS(I10-E10) -> 716 | F216: =ABS(J10-F10) -> 359 | G216: =ABS(K10-C10) -> 11 | H216: =ABS(L10-D10) -> 0 | I216: =ABS(M10-E10) -> 4 | J216: =ABS(N10-F10) -> 7 | K216: =IF(AND(C10=0, G10=0), 0, ABS(C10-G10)/((ABS(C10)+ABS(G10))/2)) -> 0.009440823 | L216: =IF(AND(D10=0, H10=0), 0, ABS(D10-H10)/((ABS(D10)+ABS(H10))/2)) -> 0 | M216: =IF(AND(E10=0, I10=0), 0, ABS(E10-I10)/((ABS(E10)+ABS(I10))/2)) -> 2 | N216: =IF(AND(F10=0, J10=0), 0, ABS(F10-J10)/((ABS(F10)+ABS(J10))/2)) -> 0.0029467895 | P216: =IF(AND(C10=0, K10=0), 0, ABS(C10-K10)/((ABS(C10)+ABS(K10))/2)) -> 0.00029223065 | Q216: =IF(AND(D10=0, L10=0), 0, ABS(D10-L10)/((ABS(D10)+ABS(L10))/2)) -> 0 | R216: =IF(AND(E10=0, M10=0), 0, ABS(E10-M10)/((ABS(E10)+ABS(M10))/2)) -> 0.0056022409 | S216: =IF(AND(F10=0, N10=0), 0, ABS(F10-N10)/((ABS(F10)+ABS(N10))/2)) -> 5.7544731e-05
B217: 7 | C217: =ABS(G11-C11) -> 128 | D217: =ABS(H11-D11) -> 0 | E217: =ABS(I11-E11) -> 254 | F217: =ABS(J11-F11) -> 126 | G217: =ABS(K11-C11) -> 11 | H217: =ABS(L11-D11) -> 0 | I217: =ABS(M11-E11) -> 11 | J217: =ABS(N11-F11) -> 0 | K217: =IF(AND(C11=0, G11=0), 0, ABS(C11-G11)/((ABS(C11)+ABS(G11))/2)) -> 0.0033763288 | L217: =IF(AND(D11=0, H11=0), 0, ABS(D11-H11)/((ABS(D11)+ABS(H11))/2)) -> 0 | M217: =IF(AND(E11=0, I11=0), 0, ABS(E11-I11)/((ABS(E11)+ABS(I11))/2)) -> 2 | N217: =IF(AND(F11=0, J11=0), 0, ABS(F11-J11)/((ABS(F11)+ABS(J11))/2)) -> 0.0010331087 | P217: =IF(AND(C11=0, K11=0), 0, ABS(C11-K11)/((ABS(C11)+ABS(K11))/2)) -> 0.00029068615 | Q217: =IF(AND(D11=0, L11=0), 0, ABS(D11-L11)/((ABS(D11)+ABS(L11))/2)) -> 0 | R217: =IF(AND(E11=0, M11=0), 0, ABS(E11-M11)/((ABS(E11)+ABS(M11))/2)) -> 0.04238921 | S217: =IF(AND(F11=0, N11=0), 0, ABS(F11-N11)/((ABS(F11)+ABS(N11))/2)) -> 0
B218: 8 | C218: =ABS(G12-C12) -> 30 | D218: =ABS(H12-D12) -> 0 | E218: =ABS(I12-E12) -> 168 | F218: =ABS(J12-F12) -> 138 | G218: =ABS(K12-C12) -> 44 | H218: =ABS(L12-D12) -> 0 | I218: =ABS(M12-E12) -> 21 | J218: =ABS(N12-F12) -> 23 | K218: =IF(AND(C12=0, G12=0), 0, ABS(C12-G12)/((ABS(C12)+ABS(G12))/2)) -> 0.00079080557 | L218: =IF(AND(D12=0, H12=0), 0, ABS(D12-H12)/((ABS(D12)+ABS(H12))/2)) -> 0 | M218: =IF(AND(E12=0, I12=0), 0, ABS(E12-I12)/((ABS(E12)+ABS(I12))/2)) -> 2 | N218: =IF(AND(F12=0, J12=0), 0, ABS(F12-J12)/((ABS(F12)+ABS(J12))/2)) -> 0.001131333 | P218: =IF(AND(C12=0, K12=0), 0, ABS(C12-K12)/((ABS(C12)+ABS(K12))/2)) -> 0.0011609805 | Q218: =IF(AND(D12=0, L12=0), 0, ABS(D12-L12)/((ABS(D12)+ABS(L12))/2)) -> 0 | R218: =IF(AND(E12=0, M12=0), 0, ABS(E12-M12)/((ABS(E12)+ABS(M12))/2)) -> 0.11764706 | S218: =IF(AND(F12=0, N12=0), 0, ABS(F12-N12)/((ABS(F12)+ABS(N12))/2)) -> 0.00018864443
B219: 9 | C219: =ABS(G13-C13) -> 97 | D219: =ABS(H13-D13) -> 0 | E219: =ABS(I13-E13) -> 221 | F219: =ABS(J13-F13) -> 124 | G219: =ABS(K13-C13) -> 27 | H219: =ABS(L13-D13) -> 0 | I219: =ABS(M13-E13) -> 25 | J219: =ABS(N13-F13) -> 2 | K219: =IF(AND(C13=0, G13=0), 0, ABS(C13-G13)/((ABS(C13)+ABS(G13))/2)) -> 0.0025574436 | L219: =IF(AND(D13=0, H13=0), 0, ABS(D13-H13)/((ABS(D13)+ABS(H13))/2)) -> 0 | M219: =IF(AND(E13=0, I13=0), 0, ABS(E13-I13)/((ABS(E13)+ABS(I13))/2)) -> 2 | N219: =IF(AND(F13=0, J13=0), 0, ABS(F13-J13)/((ABS(F13)+ABS(J13))/2)) -> 0.0010167185 | P219: =IF(AND(C13=0, K13=0), 0, ABS(C13-K13)/((ABS(C13)+ABS(K13))/2)) -> 0.00071303131 | Q219: =IF(AND(D13=0, L13=0), 0, ABS(D13-L13)/((ABS(D13)+ABS(L13))/2)) -> 0 | R219: =IF(AND(E13=0, M13=0), 0, ABS(E13-M13)/((ABS(E13)+ABS(M13))/2)) -> 0.10706638 | S219: =IF(AND(F13=0, N13=0), 0, ABS(F13-N13)/((ABS(F13)+ABS(N13))/2)) -> 1.6406891e-05
B220: 10 | C220: =ABS(G14-C14) -> 76 | D220: =ABS(H14-D14) -> 0 | E220: =ABS(I14-E14) -> 180 | F220: =ABS(J14-F14) -> 104 | G220: =ABS(K14-C14) -> 27 | H220: =ABS(L14-D14) -> 0 | I220: =ABS(M14-E14) -> 2 | J220: =ABS(N14-F14) -> 25 | K220: =IF(AND(C14=0, G14=0), 0, ABS(C14-G14)/((ABS(C14)+ABS(G14))/2)) -> 0.0020030045 | L220: =IF(AND(D14=0, H14=0), 0, ABS(D14-H14)/((ABS(D14)+ABS(H14))/2)) -> 0 | M220: =IF(AND(E14=0, I14=0), 0, ABS(E14-I14)/((ABS(E14)+ABS(I14))/2)) -> 2 | N220: =IF(AND(F14=0, J14=0), 0, ABS(F14-J14)/((ABS(F14)+ABS(J14))/2)) -> 0.00085268966 | P220: =IF(AND(C14=0, K14=0), 0, ABS(C14-K14)/((ABS(C14)+ABS(K14))/2)) -> 0.00071256086 | Q220: =IF(AND(D14=0, L14=0), 0, ABS(D14-L14)/((ABS(D14)+ABS(L14))/2)) -> 0 | R220: =IF(AND(E14=0, M14=0), 0, ABS(E14-M14)/((ABS(E14)+ABS(M14))/2)) -> 0.011049724 | S220: =IF(AND(F14=0, N14=0), 0, ABS(F14-N14)/((ABS(F14)+ABS(N14))/2)) -> 0.00020503988
B221: 11 | C221: =ABS(G15-C15) -> 70 | D221: =ABS(H15-D15) -> 0 | E221: =ABS(I15-E15) -> 263 | F221: =ABS(J15-F15) -> 193 | G221: =ABS(K15-C15) -> 24 | H221: =ABS(L15-D15) -> 0 | I221: =ABS(M15-E15) -> 25 | J221: =ABS(N15-F15) -> 1 | K221: =IF(AND(C15=0, G15=0), 0, ABS(C15-G15)/((ABS(C15)+ABS(G15))/2)) -> 0.0018479409 | L221: =IF(AND(D15=0, H15=0), 0, ABS(D15-H15)/((ABS(D15)+ABS(H15))/2)) -> 0 | M221: =IF(AND(E15=0, I15=0), 0, ABS(E15-I15)/((ABS(E15)+ABS(I15))/2)) -> 2 | N221: =IF(AND(F15=0, J15=0), 0, ABS(F15-J15)/((ABS(F15)+ABS(J15))/2)) -> 0.0015821163 | P221: =IF(AND(C15=0, K15=0), 0, ABS(C15-K15)/((ABS(C15)+ABS(K15))/2)) -> 0.00063436682 | Q221: =IF(AND(D15=0, L15=0), 0, ABS(D15-L15)/((ABS(D15)+ABS(L15))/2)) -> 0 | R221: =IF(AND(E15=0, M15=0), 0, ABS(E15-M15)/((ABS(E15)+ABS(M15))/2)) -> 0.090744102 | S221: =IF(AND(F15=0, N15=0), 0, ABS(F15-N15)/((ABS(F15)+ABS(N15))/2)) -> 8.2040175e-06
... B406: 196 | C406: =ABS(G200-C200) -> 134 | D406: =ABS(H200-D200) -> 0 | E406: =ABS(I200-E200) -> 276 | F406: =ABS(J200-F200) -> 142 | G406: =ABS(K200-C200) -> 27 | H406: =ABS(L200-D200) -> 0 | I406: =ABS(M200-E200) -> 30 | J406: =ABS(N200-F200) -> 3 | K406: =IF(AND(C200=0, G200=0), 0, ABS(C200-G200)/((ABS(C200)+ABS(G200))/2)) -> 0.0035346874 | L406: =IF(AND(D200=0, H200=0), 0, ABS(D200-H200)/((ABS(D200)+ABS(H200))/2)) -> 0 | M406: =IF(AND(E200=0, I200=0), 0, ABS(E200-I200)/((ABS(E200)+ABS(I200))/2)) -> 2 | N406: =IF(AND(F200=0, J200=0), 0, ABS(F200-J200)/((ABS(F200)+ABS(J200))/2)) -> 0.0011643925 | P406: =IF(AND(C200=0, K200=0), 0, ABS(C200-K200)/((ABS(C200)+ABS(K200))/2)) -> 0.0007137287 | Q406: =IF(AND(D200=0, L200=0), 0, ABS(D200-L200)/((ABS(D200)+ABS(L200))/2)) -> 0 | R406: =IF(AND(E200=0, M200=0), 0, ABS(E200-M200)/((ABS(E200)+ABS(M200))/2)) -> 0.10309278 | S406: =IF(AND(F200=0, N200=0), 0, ABS(F200-N200)/((ABS(F200)+ABS(N200))/2)) -> 2.4614476e-05
B407: 197 | C407: =ABS(G201-C201) -> 193 | D407: =ABS(H201-D201) -> 0 | E407: =ABS(I201-E201) -> 388 | F407: =ABS(J201-F201) -> 195 | G407: =ABS(K201-C201) -> 3 | H407: =ABS(L201-D201) -> 0 | I407: =ABS(M201-E201) -> 2 | J407: =ABS(N201-F201) -> 1 | K407: =IF(AND(C201=0, G201=0), 0, ABS(C201-G201)/((ABS(C201)+ABS(G201))/2)) -> 0.0050887902 | L407: =IF(AND(D201=0, H201=0), 0, ABS(D201-H201)/((ABS(D201)+ABS(H201))/2)) -> 0 | M407: =IF(AND(E201=0, I201=0), 0, ABS(E201-I201)/((ABS(E201)+ABS(I201))/2)) -> 2 | N407: =IF(AND(F201=0, J201=0), 0, ABS(F201-J201)/((ABS(F201)+ABS(J201))/2)) -> 0.0015999409 | O407: Total | P407: =IF(AND(C201=0, K201=0), 0, ABS(C201-K201)/((ABS(C201)+ABS(K201))/2)) -> 7.9298997e-05 | Q407: =IF(AND(D201=0, L201=0), 0, ABS(D201-L201)/((ABS(D201)+ABS(L201))/2)) -> 0 | R407: =IF(AND(E201=0, M201=0), 0, ABS(E201-M201)/((ABS(E201)+ABS(M201))/2)) -> 0.0051679587 | S407: =IF(AND(F201=0, N201=0), 0, ABS(F201-N201)/((ABS(F201)+ABS(N201))/2)) -> 8.2114278e-06 | T407: Total
B408: Total | C408: =SUM(C210:C407)/198 -> 1008.9798 | D408: =SUM(D210:D407)/198 -> 1074.0152 | E408: =SUM(E210:E407)/198 -> 325.85859 | F408: =SUM(F210:F407)/198 -> 142.04545 | G408: =SUM(G210:G407)/198 -> 25.111111 | H408: =SUM(H210:H407)/198 -> 0.51010101 | I408: =SUM(I210:I407)/198 -> 19.338384 | J408: =SUM(J210:J407)/198 -> 12.868687 | K408: =SUM(K210:K407)/COUNT(K210:K407) -> 0.028480597 | L408: =SUM(L210:L407)/COUNT(L210:L407) -> 0.61160271 | M408: =SUM(M210:M407)/COUNT(M210:M407) -> 1.152906 | N408: =SUM(N210:N407)/COUNT(N210:N407) -> 0.0011645804 | O408: =SUM(K210:N407)/COUNT(K210:N407) -> 0.44853847 | P408: =SUM(P210:P407)/COUNT(P210:P407) -> 0.00069185724 | Q408: =SUM(Q210:Q407)/COUNT(Q210:Q407) -> 0.00014760332 | R408: =SUM(R210:R407)/COUNT(R210:R407) -> 0.052586499 | S408: =SUM(S210:S407)/COUNT(S210:S407) -> 0.00010555669 | T408: =SUM(P210:S407)/COUNT(P210:S407) -> 0.013382879

Sheet Comparison with original
B1: image | C1: Original | G1: Clustering | O1: Classification
G2: Random correction | K2: Color classification | O2: Random correction | S2: Color classification
A3: 2_filled_cuboid/f_cub_z | C3: #e3bb37 | D3: #e65a49 | E3: #f08a8c | F3: #ffffff | G3: #e3bb38 | H3: #e65a49 | I3: #efaa8d | J3: #fefefe | K3: #e3bb38 | L3: #e65a49 | M3: #efaa8d | N3: #fefefe | O3: #e3bb37 | P3: #e65a49 | Q3: #f08a8c | R3: #ffffff | S3: #e3bb37 | T3: #e65a49 | U3: #f08a8c | V3: #ffffff
B4: 0 | C4: 38025 | D4: 0 | E4: 0 | F4: 121975 | G4: ='Color clustering'!G4 -> 38025 | H4: ='Color clustering'!H4 -> 0 | I4: ='Color clustering'!I4 -> 0 | J4: ='Color clustering'!J4 -> 121975 | K4: ='Color clustering'!K4 -> 38025 | L4: ='Color clustering'!L4 -> 0 | M4: ='Color clustering'!M4 -> 0 | N4: ='Color clustering'!N4 -> 121975 | O4: ='Color classification'!G4 -> 38025 | P4: ='Color classification'!H4 -> 0 | Q4: ='Color classification'!I4 -> 0 | R4: ='Color classification'!J4 -> 121975 | S4: ='Color classification'!K4 -> 38025 | T4: ='Color classification'!L4 -> 0 | U4: ='Color classification'!M4 -> 0 | V4: ='Color classification'!N4 -> 121975
B5: 1 | C5: 38025 | D5: 0 | E5: 0 | F5: 121975 | G5: ='Color clustering'!G5 -> 37862 | H5: ='Color clustering'!H5 -> 0 | I5: ='Color clustering'!I5 -> 9 | J5: ='Color clustering'!J5 -> 122129 | K5: ='Color clustering'!K5 -> 37623 | L5: ='Color clustering'!L5 -> 0 | M5: ='Color clustering'!M5 -> 676 | N5: ='Color clustering'!N5 -> 121701 | O5: ='Color classification'!G5 -> 37932 | P5: ='Color classification'!H5 -> 0 | Q5: ='Color classification'!I5 -> 0 | R5: ='Color classification'!J5 -> 122068 | S5: ='Color classification'!K5 -> 37776 | T5: ='Color classification'!L5 -> 0 | U5: ='Color classification'!M5 -> 373 | V5: ='Color classification'!N5 -> 121851
B6: 2 | C6: 38025 | D6: 0 | E6: 0 | F6: 121975 | G6: ='Color clustering'!G6 -> 37917 | H6: ='Color clustering'!H6 -> 0 | I6: ='Color clustering'!I6 -> 0 | J6: ='Color clustering'!J6 -> 122083 | K6: ='Color clustering'!K6 -> 37748 | L6: ='Color clustering'!L6 -> 0 | M6: ='Color clustering'!M6 -> 405 | N6: ='Color clustering'!N6 -> 121847 | O6: ='Color classification'!G6 -> 37972 | P6: ='Color classification'!H6 -> 0 | Q6: ='Color classification'!I6 -> 0 | R6: ='Color classification'!J6 -> 122028 | S6: ='Color classification'!K6 -> 37878 | T6: ='Color classification'!L6 -> 0 | U6: ='Color classification'!M6 -> 185 | V6: ='Color classification'!N6 -> 121937
B7: 3 | C7: 38025 | D7: 0 | E7: 0 | F7: 121975 | G7: ='Color clustering'!G7 -> 37896 | H7: ='Color clustering'!H7 -> 0 | I7: ='Color clustering'!I7 -> 0 | J7: ='Color clustering'!J7 -> 122104 | K7: ='Color clustering'!K7 -> 37716 | L7: ='Color clustering'!L7 -> 0 | M7: ='Color clustering'!M7 -> 461 | N7: ='Color clustering'!N7 -> 121823 | O7: ='Color classification'!G7 -> 37959 | P7: ='Color classification'!H7 -> 0 | Q7: ='Color classification'!I7 -> 0 | R7: ='Color classification'!J7 -> 122041 | S7: ='Color classification'!K7 -> 37865 | T7: ='Color classification'!L7 -> 0 | U7: ='Color classification'!M7 -> 208 | V7: ='Color classification'!N7 -> 121927
B8: 4 | C8: 38025 | D8: 0 | E8: 0 | F8: 121975 | G8: ='Color clustering'!G8 -> 37950 | H8: ='Color clustering'!H8 -> 0 | I8: ='Color clustering'!I8 -> 0 | J8: ='Color clustering'!J8 -> 122050 | K8: ='Color clustering'!K8 -> 37726 | L8: ='Color clustering'!L8 -> 0 | M8: ='Color clustering'!M8 -> 453 | N8: ='Color clustering'!N8 -> 121821 | O8: ='Color classification'!G8 -> 37984 | P8: ='Color classification'!H8 -> 0 | Q8: ='Color classification'!I8 -> 0 | R8: ='Color classification'!J8 -> 122016 | S8: ='Color classification'!K8 -> 37852 | T8: ='Color classification'!L8 -> 0 | U8: ='Color classification'!M8 -> 230 | V8: ='Color classification'!N8 -> 121918
B9: 5 | C9: 38025 | D9: 0 | E9: 0 | F9: 121975 | G9: ='Color clustering'!G9 -> 37916 | H9: ='Color clustering'!H9 -> 0 | I9: ='Color clustering'!I9 -> 7 | J9: ='Color clustering'!J9 -> 122077 | K9: ='Color clustering'!K9 -> 37654 | L9: ='Color clustering'!L9 -> 0 | M9: ='Color clustering'!M9 -> 584 | N9: ='Color clustering'!N9 -> 121762 | O9: ='Color classification'!G9 -> 37973 | P9: ='Color classification'!H9 -> 0 | Q9: ='Color classification'!I9 -> 0 | R9: ='Color classification'!J9 -> 122027 | S9: ='Color classification'!K9 -> 37828 | T9: ='Color classification'!L9 -> 0 | U9: ='Color classification'!M9 -> 280 | V9: ='Color classification'!N9 -> 121892
B10: 6 | C10: 38025 | D10: 0 | E10: 0 | F10: 121975 | G10: ='Color clustering'!G10 -> 38037 | H10: ='Color clustering'!H10 -> 0 | I10: ='Color clustering'!I10 -> 0 | J10: ='Color clustering'!J10 -> 121963 | K10: ='Color clustering'!K10 -> 37715 | L10: ='Color clustering'!L10 -> 0 | M10: ='Color clustering'!M10 -> 756 | N10: ='Color clustering'!N10 -> 121529 | O10: ='Color classification'!G10 -> 37993 | P10: ='Color classification'!H10 -> 0 | Q10: ='Color classification'!I10 -> 0 | R10: ='Color classification'!J10 -> 122007 | S10: ='Color classification'!K10 -> 37647 | T10: ='Color classification'!L10 -> 0 | U10: ='Color classification'!M10 -> 712 | V10: ='Color classification'!N10 -> 121641
B11: 7 | C11: 38025 | D11: 0 | E11: 0 | F11: 121975 | G11: ='Color clustering'!G11 -> 37895 | H11: ='Color clustering'!H11 -> 0 | I11: ='Color clustering'!I11 -> 13 | J11: ='Color clustering'!J11 -> 122092 | K11: ='Color clustering'!K11 -> 37596 | L11: ='Color clustering'!L11 -> 0 | M11: ='Color clustering'!M11 -> 647 | N11: ='Color clustering'!N11 -> 121757 | O11: ='Color classification'!G11 -> 37975 | P11: ='Color classification'!H11 -> 0 | Q11: ='Color classification'!I11 -> 0 | R11: ='Color classification'!J11 -> 122025 | S11: ='Color classification'!K11 -> 37836 | T11: ='Color classification'!L11 -> 0 | U11: ='Color classification'!M11 -> 265 | V11: ='Color classification'!N11 -> 121899
B12: 8 | C12: 38025 | D12: 0 | E12: 0 | F12: 121975 | G12: ='Color clustering'!G12 -> 37940 | H12: ='Color clustering'!H12 -> 0 | I12: ='Color clustering'!I12 -> 0 | J12: ='Color clustering'!J12 -> 122060 | K12: ='Color clustering'!K12 -> 37754 | L12: ='Color clustering'!L12 -> 0 | M12: ='Color clustering'!M12 -> 386 | N12: ='Color clustering'!N12 -> 121860 | O12: ='Color classification'!G12 -> 37951 | P12: ='Color classification'!H12 -> 0 | Q12: ='Color classification'!I12 -> 0 | R12: ='Color classification'!J12 -> 122049 | S12: ='Color classification'!K12 -> 37877 | T12: ='Color classification'!L12 -> 0 | U12: ='Color classification'!M12 -> 189 | V12: ='Color classification'!N12 -> 121934
B13: 9 | C13: 38025 | D13: 0 | E13: 0 | F13: 121975 | G13: ='Color clustering'!G13 -> 37879 | H13: ='Color clustering'!H13 -> 0 | I13: ='Color clustering'!I13 -> 4 | J13: ='Color clustering'!J13 -> 122117 | K13: ='Color clustering'!K13 -> 37681 | L13: ='Color clustering'!L13 -> 0 | M13: ='Color clustering'!M13 -> 506 | N13: ='Color clustering'!N13 -> 121813 | O13: ='Color classification'!G13 -> 37977 | P13: ='Color classification'!H13 -> 0 | Q13: ='Color classification'!I13 -> 0 | R13: ='Color classification'!J13 -> 122023 | S13: ='Color classification'!K13 -> 37853 | T13: ='Color classification'!L13 -> 0 | U13: ='Color classification'!M13 -> 246 | V13: ='Color classification'!N13 -> 121901
B14: 10 | C14: 38025 | D14: 0 | E14: 0 | F14: 121975 | G14: ='Color clustering'!G14 -> 37977 | H14: ='Color clustering'!H14 -> 0 | I14: ='Color clustering'!I14 -> 0 | J14: ='Color clustering'!J14 -> 122023 | K14: ='Color clustering'!K14 -> 37739 | L14: ='Color clustering'!L14 -> 0 | M14: ='Color clustering'!M14 -> 399 | N14: ='Color clustering'!N14 -> 121862 | O14: ='Color classification'!G14 -> 37981 | P14: ='Color classification'!H14 -> 0 | Q14: ='Color classification'!I14 -> 0 | R14: ='Color classification'!J14 -> 122019 | S14: ='Color classification'!K14 -> 37878 | T14: ='Color classification'!L14 -> 0 | U14: ='Color classification'!M14 -> 182 | V14: ='Color classification'!N14 -> 121940
B15: 11 | C15: 38025 | D15: 0 | E15: 0 | F15: 121975 | G15: ='Color clustering'!G15 -> 37917 | H15: ='Color clustering'!H15 -> 0 | I15: ='Color clustering'!I15 -> 12 | J15: ='Color clustering'!J15 -> 122071 | K15: ='Color clustering'!K15 -> 37658 | L15: ='Color clustering'!L15 -> 0 | M15: ='Color clustering'!M15 -> 578 | N15: ='Color clustering'!N15 -> 121764 | O15: ='Color classification'!G15 -> 37915 | P15: ='Color classification'!H15 -> 0 | Q15: ='Color classification'!I15 -> 0 | R15: ='Color classification'!J15 -> 122085 | S15: ='Color classification'!K15 -> 37821 | T15: ='Color classification'!L15 -> 0 | U15: ='Color classification'!M15 -> 288 | V15: ='Color classification'!N15 -> 121891
... B201: 197 | C201: 38025 | D201: 0 | E201: 0 | F201: 121975 | G201: ='Color clustering'!G201 -> 38081 | H201: ='Color clustering'!H201 -> 0 | I201: ='Color clustering'!I201 -> 0 | J201: ='Color clustering'!J201 -> 121919 | K201: ='Color clustering'!K201 -> 37786 | L201: ='Color clustering'!L201 -> 0 | M201: ='Color clustering'!M201 -> 434 | N201: ='Color clustering'!N201 -> 121780 | O201: ='Color classification'!G201 -> 38023 | P201: ='Color classification'!H201 -> 0 | Q201: ='Color classification'!I201 -> 0 | R201: ='Color classification'!J201 -> 121977 | S201: ='Color classification'!K201 -> 37833 | T201: ='Color classification'!L201 -> 0 | U201: ='Color classification'!M201 -> 386 | V201: ='Color classification'!N201 -> 121781
B202: Total | C202: =SUM(C4:C201) -> 7240362 | D202: =SUM(D4:D201) -> 213205 | E202: =SUM(E4:E201) -> 75383 | F202: =SUM(F4:F201) -> 24151050 | G202: =SUM(G4:G201) -> 7407877 | H202: =SUM(H4:H201) -> 1930 | I202: =SUM(I4:I201) -> 102161 | J202: =SUM(J4:J201) -> 24168032 | ... V202: =SUM(V4:V201) -> 24138763
B207: image | C207: Abolute Error Clustering | K207: Abolute Error Classification | S207: SMAPE Clustering | AC207: SMAPE Classification
C208: Random correction | G208: Color classification | K208: Random correction | O208: Color classification | S208: Random correction | X208: Color classification | AC208: Random correction | AH208: Color classification
A209: 2_filled_cuboid/f_cub_x/Col_clust | C209: #e2bb37 | D209: #e55a49 | E209: #efaa8d | F209: #fefefe | G209: #e2bb37 | H209: #e55a49 | I209: #efaa8d | J209: #fefefe | K209: #e3bb37 | L209: #e65a49 | M209: #f08a8c | N209: #ffffff | O209: #e3bb37 | P209: #e65a49 | Q209: #f08a8c | R209: #ffffff | S209: #e2bb37 | T209: #e55a49 | U209: #efaa8d | V209: #fefefe | X209: #e2bb37 | Y209: #e55a49 | Z209: #efaa8d | AA209: #fefefe | AC209: #e3bb37 | AD209: #e65a49 | AE209: #f08a8c | AF209: #ffffff | AH209: #e3bb37 | AI209: #e65a49 | AJ209: #f08a8c | AK209: #ffffff
B210: 0 | C210: =ABS(G4-C4) -> 0 | D210: =ABS(H4-D4) -> 0 | E210: =ABS(I4-E4) -> 0 | F210: =ABS(J4-F4) -> 0 | G210: =ABS(K4-C4) -> 0 | H210: =ABS(L4-D4) -> 0 | I210: =ABS(M4-E4) -> 0 | J210: =ABS(N4-F4) -> 0 | K210: =ABS(O4-C4) -> 0 | L210: =ABS(P4-D4) -> 0 | M210: =ABS(Q4-E4) -> 0 | N210: =ABS(R4-F4) -> 0 | O210: =ABS(S4-C4) -> 0 | P210: =ABS(T4-D4) -> 0 | Q210: =ABS(U4-E4) -> 0 | R210: =ABS(V4-F4) -> 0 | S210: =IF(AND(C4=0, G4=0), 0, ABS(C4-G4)/((ABS(C4)+ABS(G4))/2)) -> 0 | T210: =IF(AND(D4=0, H4=0), 0, ABS(D4-H4)/((ABS(D4)+ABS(H4))/2)) -> 0 | U210: =IF(AND(E4=0, I4=0), 0, ABS(E4-I4)/((ABS(E4)+ABS(I4))/2)) -> 0 | V210: =IF(AND(F4=0, J4=0), 0, ABS(F4-J4)/((ABS(F4)+ABS(J4))/2)) -> 0 | X210: =IF(AND(C4=0, K4=0), 0, ABS(C4-K4)/((ABS(C4)+ABS(K4))/2)) -> 0 | Y210: =IF(AND(D4=0, L4=0), 0, ABS(D4-L4)/((ABS(D4)+ABS(L4))/2)) -> 0 | Z210: =IF(AND(E4=0, M4=0), 0, ABS(E4-M4)/((ABS(E4)+ABS(M4))/2)) -> 0 | AA210: =IF(AND(F4=0, N4=0), 0, ABS(F4-N4)/((ABS(F4)+ABS(N4))/2)) -> 0 | AC210: =IF(AND(C4=0, O4=0), 0, ABS(C4-O4)/((ABS(C4)+ABS(O4))/2)) -> 0 | AD210: =IF(AND(D4=0, P4=0), 0, ABS(D4-P4)/((ABS(D4)+ABS(P4))/2)) -> 0 | AE210: =IF(AND(E4=0, Q4=0), 0, ABS(E4-Q4)/((ABS(E4)+ABS(Q4))/2)) -> 0 | AF210: =IF(AND(F4=0, R4=0), 0, ABS(F4-R4)/((ABS(F4)+ABS(R4))/2)) -> 0 | AH210: =IF(AND(C4=0, S4=0), 0, ABS(C4-S4)/((ABS(C4)+ABS(S4))/2)) -> 0 | AI210: =IF(AND(D4=0, T4=0), 0, ABS(D4-T4)/((ABS(D4)+ABS(T4))/2)) -> 0 | AJ210: =IF(AND(E4=0, U4=0), 0, ABS(E4-U4)/((ABS(E4)+ABS(U4))/2)) -> 0 | AK210: =IF(AND(F4=0, V4=0), 0, ABS(F4-V4)/((ABS(F4)+ABS(V4))/2)) -> 0
B211: 1 | C211: =ABS(G5-C5) -> 163 | D211: =ABS(H5-D5) -> 0 | E211: =ABS(I5-E5) -> 9 | F211: =ABS(J5-F5) -> 154 | G211: =ABS(K5-C5) -> 402 | H211: =ABS(L5-D5) -> 0 | I211: =ABS(M5-E5) -> 676 | J211: =ABS(N5-F5) -> 274 | K211: =ABS(O5-C5) -> 93 | L211: =ABS(P5-D5) -> 0 | M211: =ABS(Q5-E5) -> 0 | N211: =ABS(R5-F5) -> 93 | O211: =ABS(S5-C5) -> 249 | P211: =ABS(T5-D5) -> 0 | Q211: =ABS(U5-E5) -> 373 | R211: =ABS(V5-F5) -> 124 | S211: =IF(AND(C5=0, G5=0), 0, ABS(C5-G5)/((ABS(C5)+ABS(G5))/2)) -> 0.004295861 | T211: =IF(AND(D5=0, H5=0), 0, ABS(D5-H5)/((ABS(D5)+ABS(H5))/2)) -> 0 | U211: =IF(AND(E5=0, I5=0), 0, ABS(E5-I5)/((ABS(E5)+ABS(I5))/2)) -> 2 | V211: =IF(AND(F5=0, J5=0), 0, ABS(F5-J5)/((ABS(F5)+ABS(J5))/2)) -> 0.0012617573 | X211: =IF(AND(C5=0, K5=0), 0, ABS(C5-K5)/((ABS(C5)+ABS(K5))/2)) -> 0.010628173 | Y211: =IF(AND(D5=0, L5=0), 0, ABS(D5-L5)/((ABS(D5)+ABS(L5))/2)) -> 0 | Z211: =IF(AND(E5=0, M5=0), 0, ABS(E5-M5)/((ABS(E5)+ABS(M5))/2)) -> 2 | AA211: =IF(AND(F5=0, N5=0), 0, ABS(F5-N5)/((ABS(F5)+ABS(N5))/2)) -> 0.0022488879 | AC211: =IF(AND(C5=0, O5=0), 0, ABS(C5-O5)/((ABS(C5)+ABS(O5))/2)) -> 0.0024487539 | AD211: =IF(AND(D5=0, P5=0), 0, ABS(D5-P5)/((ABS(D5)+ABS(P5))/2)) -> 0 | AE211: =IF(AND(E5=0, Q5=0), 0, ABS(E5-Q5)/((ABS(E5)+ABS(Q5))/2)) -> 0 | AF211: =IF(AND(F5=0, R5=0), 0, ABS(F5-R5)/((ABS(F5)+ABS(R5))/2)) -> 0.00076216077 | AH211: =IF(AND(C5=0, S5=0), 0, ABS(C5-S5)/((ABS(C5)+ABS(S5))/2)) -> 0.0065698342 | AI211: =IF(AND(D5=0, T5=0), 0, ABS(D5-T5)/((ABS(D5)+ABS(T5))/2)) -> 0 | AJ211: =IF(AND(E5=0, U5=0), 0, ABS(E5-U5)/((ABS(E5)+ABS(U5))/2)) -> 2 | AK211: =IF(AND(F5=0, V5=0), 0, ABS(F5-V5)/((ABS(F5)+ABS(V5))/2)) -> 0.0010171188
B212: 2 | C212: =ABS(G6-C6) -> 108 | D212: =ABS(H6-D6) -> 0 | E212: =ABS(I6-E6) -> 0 | F212: =ABS(J6-F6) -> 108 | G212: =ABS(K6-C6) -> 277 | H212: =ABS(L6-D6) -> 0 | I212: =ABS(M6-E6) -> 405 | J212: =ABS(N6-F6) -> 128 | K212: =ABS(O6-C6) -> 53 | L212: =ABS(P6-D6) -> 0 | M212: =ABS(Q6-E6) -> 0 | N212: =ABS(R6-F6) -> 53 | O212: =ABS(S6-C6) -> 147 | P212: =ABS(T6-D6) -> 0 | Q212: =ABS(U6-E6) -> 185 | R212: =ABS(V6-F6) -> 38 | S212: =IF(AND(C6=0, G6=0), 0, ABS(C6-G6)/((ABS(C6)+ABS(G6))/2)) -> 0.0028442759 | T212: =IF(AND(D6=0, H6=0), 0, ABS(D6-H6)/((ABS(D6)+ABS(H6))/2)) -> 0 | U212: =IF(AND(E6=0, I6=0), 0, ABS(E6-I6)/((ABS(E6)+ABS(I6))/2)) -> 0 | V212: =IF(AND(F6=0, J6=0), 0, ABS(F6-J6)/((ABS(F6)+ABS(J6))/2)) -> 0.00088503552 | X212: =IF(AND(C6=0, K6=0), 0, ABS(C6-K6)/((ABS(C6)+ABS(K6))/2)) -> 0.0073113114 | Y212: =IF(AND(D6=0, L6=0), 0, ABS(D6-L6)/((ABS(D6)+ABS(L6))/2)) -> 0 | Z212: =IF(AND(E6=0, M6=0), 0, ABS(E6-M6)/((ABS(E6)+ABS(M6))/2)) -> 2 | AA212: =IF(AND(F6=0, N6=0), 0, ABS(F6-N6)/((ABS(F6)+ABS(N6))/2)) -> 0.0010499463 | AC212: =IF(AND(C6=0, O6=0), 0, ABS(C6-O6)/((ABS(C6)+ABS(O6))/2)) -> 0.0013947919 | AD212: =IF(AND(D6=0, P6=0), 0, ABS(D6-P6)/((ABS(D6)+ABS(P6))/2)) -> 0 | AE212: =IF(AND(E6=0, Q6=0), 0, ABS(E6-Q6)/((ABS(E6)+ABS(Q6))/2)) -> 0 | AF212: =IF(AND(F6=0, R6=0), 0, ABS(F6-R6)/((ABS(F6)+ABS(R6))/2)) -> 0.00043442089 | AH212: =IF(AND(C6=0, S6=0), 0, ABS(C6-S6)/((ABS(C6)+ABS(S6))/2)) -> 0.0038733647 | AI212: =IF(AND(D6=0, T6=0), 0, ABS(D6-T6)/((ABS(D6)+ABS(T6))/2)) -> 0 | AJ212: =IF(AND(E6=0, U6=0), 0, ABS(E6-U6)/((ABS(E6)+ABS(U6))/2)) -> 2 | AK212: =IF(AND(F6=0, V6=0), 0, ABS(F6-V6)/((ABS(F6)+ABS(V6))/2)) -> 0.00031158779
B213: 3 | C213: =ABS(G7-C7) -> 129 | D213: =ABS(H7-D7) -> 0 | E213: =ABS(I7-E7) -> 0 | F213: =ABS(J7-F7) -> 129 | G213: =ABS(K7-C7) -> 309 | H213: =ABS(L7-D7) -> 0 | I213: =ABS(M7-E7) -> 461 | J213: =ABS(N7-F7) -> 152 | K213: =ABS(O7-C7) -> 66 | L213: =ABS(P7-D7) -> 0 | M213: =ABS(Q7-E7) -> 0 | N213: =ABS(R7-F7) -> 66 | O213: =ABS(S7-C7) -> 160 | P213: =ABS(T7-D7) -> 0 | Q213: =ABS(U7-E7) -> 208 | R213: =ABS(V7-F7) -> 48 | S213: =IF(AND(C7=0, G7=0), 0, ABS(C7-G7)/((ABS(C7)+ABS(G7))/2)) -> 0.0033982693 | T213: =IF(AND(D7=0, H7=0), 0, ABS(D7-H7)/((ABS(D7)+ABS(H7))/2)) -> 0 | U213: =IF(AND(E7=0, I7=0), 0, ABS(E7-I7)/((ABS(E7)+ABS(I7))/2)) -> 0 | V213: =IF(AND(F7=0, J7=0), 0, ABS(F7-J7)/((ABS(F7)+ABS(J7))/2)) -> 0.0010570348 | X213: =IF(AND(C7=0, K7=0), 0, ABS(C7-K7)/((ABS(C7)+ABS(K7))/2)) -> 0.0081593853 | Y213: =IF(AND(D7=0, L7=0), 0, ABS(D7-L7)/((ABS(D7)+ABS(L7))/2)) -> 0 | Z213: =IF(AND(E7=0, M7=0), 0, ABS(E7-M7)/((ABS(E7)+ABS(M7))/2)) -> 2 | AA213: =IF(AND(F7=0, N7=0), 0, ABS(F7-N7)/((ABS(F7)+ABS(N7))/2)) -> 0.0012469339 | AC213: =IF(AND(C7=0, O7=0), 0, ABS(C7-O7)/((ABS(C7)+ABS(O7))/2)) -> 0.0017372078 | AD213: =IF(AND(D7=0, P7=0), 0, ABS(D7-P7)/((ABS(D7)+ABS(P7))/2)) -> 0 | AE213: =IF(AND(E7=0, Q7=0), 0, ABS(E7-Q7)/((ABS(E7)+ABS(Q7))/2)) -> 0 | AF213: =IF(AND(F7=0, R7=0), 0, ABS(F7-R7)/((ABS(F7)+ABS(R7))/2)) -> 0.00054094813 | AH213: =IF(AND(C7=0, S7=0), 0, ABS(C7-S7)/((ABS(C7)+ABS(S7))/2)) -> 0.0042166293 | AI213: =IF(AND(D7=0, T7=0), 0, ABS(D7-T7)/((ABS(D7)+ABS(T7))/2)) -> 0 | AJ213: =IF(AND(E7=0, U7=0), 0, ABS(E7-U7)/((ABS(E7)+ABS(U7))/2)) -> 2 | AK213: =IF(AND(F7=0, V7=0), 0, ABS(F7-V7)/((ABS(F7)+ABS(V7))/2)) -> 0.00039360071
B214: 4 | C214: =ABS(G8-C8) -> 75 | D214: =ABS(H8-D8) -> 0 | E214: =ABS(I8-E8) -> 0 | F214: =ABS(J8-F8) -> 75 | G214: =ABS(K8-C8) -> 299 | H214: =ABS(L8-D8) -> 0 | I214: =ABS(M8-E8) -> 453 | J214: =ABS(N8-F8) -> 154 | K214: =ABS(O8-C8) -> 41 | L214: =ABS(P8-D8) -> 0 | M214: =ABS(Q8-E8) -> 0 | N214: =ABS(R8-F8) -> 41 | O214: =ABS(S8-C8) -> 173 | P214: =ABS(T8-D8) -> 0 | Q214: =ABS(U8-E8) -> 230 | R214: =ABS(V8-F8) -> 57 | S214: =IF(AND(C8=0, G8=0), 0, ABS(C8-G8)/((ABS(C8)+ABS(G8))/2)) -> 0.0019743337 | T214: =IF(AND(D8=0, H8=0), 0, ABS(D8-H8)/((ABS(D8)+ABS(H8))/2)) -> 0 | U214: =IF(AND(E8=0, I8=0), 0, ABS(E8-I8)/((ABS(E8)+ABS(I8))/2)) -> 0 | V214: =IF(AND(F8=0, J8=0), 0, ABS(F8-J8)/((ABS(F8)+ABS(J8))/2)) -> 0.00061469112 | X214: =IF(AND(C8=0, K8=0), 0, ABS(C8-K8)/((ABS(C8)+ABS(K8))/2)) -> 0.0078942852 | Y214: =IF(AND(D8=0, L8=0), 0, ABS(D8-L8)/((ABS(D8)+ABS(L8))/2)) -> 0 | Z214: =IF(AND(E8=0, M8=0), 0, ABS(E8-M8)/((ABS(E8)+ABS(M8))/2)) -> 2 | AA214: =IF(AND(F8=0, N8=0), 0, ABS(F8-N8)/((ABS(F8)+ABS(N8))/2)) -> 0.0012633513 | AC214: =IF(AND(C8=0, O8=0), 0, ABS(C8-O8)/((ABS(C8)+ABS(O8))/2)) -> 0.0010788196 | AD214: =IF(AND(D8=0, P8=0), 0, ABS(D8-P8)/((ABS(D8)+ABS(P8))/2)) -> 0 | AE214: =IF(AND(E8=0, Q8=0), 0, ABS(E8-Q8)/((ABS(E8)+ABS(Q8))/2)) -> 0 | AF214: =IF(AND(F8=0, R8=0), 0, ABS(F8-R8)/((ABS(F8)+ABS(R8))/2)) -> 0.00033607797 | AH214: =IF(AND(C8=0, S8=0), 0, ABS(C8-S8)/((ABS(C8)+ABS(S8))/2)) -> 0.0045600116 | AI214: =IF(AND(D8=0, T8=0), 0, ABS(D8-T8)/((ABS(D8)+ABS(T8))/2)) -> 0 | AJ214: =IF(AND(E8=0, U8=0), 0, ABS(E8-U8)/((ABS(E8)+ABS(U8))/2)) -> 2 | AK214: =IF(AND(F8=0, V8=0), 0, ABS(F8-V8)/((ABS(F8)+ABS(V8))/2)) -> 0.00046741809
B215: 5 | C215: =ABS(G9-C9) -> 109 | D215: =ABS(H9-D9) -> 0 | E215: =ABS(I9-E9) -> 7 | F215: =ABS(J9-F9) -> 102 | G215: =ABS(K9-C9) -> 371 | H215: =ABS(L9-D9) -> 0 | I215: =ABS(M9-E9) -> 584 | J215: =ABS(N9-F9) -> 213 | K215: =ABS(O9-C9) -> 52 | L215: =ABS(P9-D9) -> 0 | M215: =ABS(Q9-E9) -> 0 | N215: =ABS(R9-F9) -> 52 | O215: =ABS(S9-C9) -> 197 | P215: =ABS(T9-D9) -> 0 | Q215: =ABS(U9-E9) -> 280 | R215: =ABS(V9-F9) -> 83 | S215: =IF(AND(C9=0, G9=0), 0, ABS(C9-G9)/((ABS(C9)+ABS(G9))/2)) -> 0.0028706496 | T215: =IF(AND(D9=0, H9=0), 0, ABS(D9-H9)/((ABS(D9)+ABS(H9))/2)) -> 0 | U215: =IF(AND(E9=0, I9=0), 0, ABS(E9-I9)/((ABS(E9)+ABS(I9))/2)) -> 2 | V215: =IF(AND(F9=0, J9=0), 0, ABS(F9-J9)/((ABS(F9)+ABS(J9))/2)) -> 0.00083588743 | X215: =IF(AND(C9=0, K9=0), 0, ABS(C9-K9)/((ABS(C9)+ABS(K9))/2)) -> 0.0098045693 | Y215: =IF(AND(D9=0, L9=0), 0, ABS(D9-L9)/((ABS(D9)+ABS(L9))/2)) -> 0 | Z215: =IF(AND(E9=0, M9=0), 0, ABS(E9-M9)/((ABS(E9)+ABS(M9))/2)) -> 2 | AA215: =IF(AND(F9=0, N9=0), 0, ABS(F9-N9)/((ABS(F9)+ABS(N9))/2)) -> 0.0017477855 | AC215: =IF(AND(C9=0, O9=0), 0, ABS(C9-O9)/((ABS(C9)+ABS(O9))/2)) -> 0.0013684571 | AD215: =IF(AND(D9=0, P9=0), 0, ABS(D9-P9)/((ABS(D9)+ABS(P9))/2)) -> 0 | AE215: =IF(AND(E9=0, Q9=0), 0, ABS(E9-Q9)/((ABS(E9)+ABS(Q9))/2)) -> 0 | AF215: =IF(AND(F9=0, R9=0), 0, ABS(F9-R9)/((ABS(F9)+ABS(R9))/2)) -> 0.00042622601 | AH215: =IF(AND(C9=0, S9=0), 0, ABS(C9-S9)/((ABS(C9)+ABS(S9))/2)) -> 0.0051942573 | AI215: =IF(AND(D9=0, T9=0), 0, ABS(D9-T9)/((ABS(D9)+ABS(T9))/2)) -> 0 | AJ215: =IF(AND(E9=0, U9=0), 0, ABS(E9-U9)/((ABS(E9)+ABS(U9))/2)) -> 2 | AK215: =IF(AND(F9=0, V9=0), 0, ABS(F9-V9)/((ABS(F9)+ABS(V9))/2)) -> 0.00068069891
B216: 6 | C216: =ABS(G10-C10) -> 12 | D216: =ABS(H10-D10) -> 0 | E216: =ABS(I10-E10) -> 0 | F216: =ABS(J10-F10) -> 12 | G216: =ABS(K10-C10) -> 310 | H216: =ABS(L10-D10) -> 0 | I216: =ABS(M10-E10) -> 756 | J216: =ABS(N10-F10) -> 446 | K216: =ABS(O10-C10) -> 32 | L216: =ABS(P10-D10) -> 0 | M216: =ABS(Q10-E10) -> 0 | N216: =ABS(R10-F10) -> 32 | O216: =ABS(S10-C10) -> 378 | P216: =ABS(T10-D10) -> 0 | Q216: =ABS(U10-E10) -> 712 | R216: =ABS(V10-F10) -> 334 | S216: =IF(AND(C10=0, G10=0), 0, ABS(C10-G10)/((ABS(C10)+ABS(G10))/2)) -> 0.00031553207 | T216: =IF(AND(D10=0, H10=0), 0, ABS(D10-H10)/((ABS(D10)+ABS(H10))/2)) -> 0 | U216: =IF(AND(E10=0, I10=0), 0, ABS(E10-I10)/((ABS(E10)+ABS(I10))/2)) -> 0 | V216: =IF(AND(F10=0, J10=0), 0, ABS(F10-J10)/((ABS(F10)+ABS(J10))/2)) -> 9.8385655e-05 | X216: =IF(AND(C10=0, K10=0), 0, ABS(C10-K10)/((ABS(C10)+ABS(K10))/2)) -> 0.0081858991 | Y216: =IF(AND(D10=0, L10=0), 0, ABS(D10-L10)/((ABS(D10)+ABS(L10))/2)) -> 0 | Z216: =IF(AND(E10=0, M10=0), 0, ABS(E10-M10)/((ABS(E10)+ABS(M10))/2)) -> 2 | AA216: =IF(AND(F10=0, N10=0), 0, ABS(F10-N10)/((ABS(F10)+ABS(N10))/2)) -> 0.0036631842 | AC216: =IF(AND(C10=0, O10=0), 0, ABS(C10-O10)/((ABS(C10)+ABS(O10))/2)) -> 0.00084190586 | AD216: =IF(AND(D10=0, P10=0), 0, ABS(D10-P10)/((ABS(D10)+ABS(P10))/2)) -> 0 | AE216: =IF(AND(E10=0, Q10=0), 0, ABS(E10-Q10)/((ABS(E10)+ABS(Q10))/2)) -> 0 | AF216: =IF(AND(F10=0, R10=0), 0, ABS(F10-R10)/((ABS(F10)+ABS(R10))/2)) -> 0.00026231443 | AH216: =IF(AND(C10=0, S10=0), 0, ABS(C10-S10)/((ABS(C10)+ABS(S10))/2)) -> 0.0099904853 | AI216: =IF(AND(D10=0, T10=0), 0, ABS(D10-T10)/((ABS(D10)+ABS(T10))/2)) -> 0 | AJ216: =IF(AND(E10=0, U10=0), 0, ABS(E10-U10)/((ABS(E10)+ABS(U10))/2)) -> 2 | AK216: =IF(AND(F10=0, V10=0), 0, ABS(F10-V10)/((ABS(F10)+ABS(V10))/2)) -> 0.0027420202
B217: 7 | C217: =ABS(G11-C11) -> 130 | D217: =ABS(H11-D11) -> 0 | E217: =ABS(I11-E11) -> 13 | F217: =ABS(J11-F11) -> 117 | G217: =ABS(K11-C11) -> 429 | H217: =ABS(L11-D11) -> 0 | I217: =ABS(M11-E11) -> 647 | J217: =ABS(N11-F11) -> 218 | K217: =ABS(O11-C11) -> 50 | L217: =ABS(P11-D11) -> 0 | M217: =ABS(Q11-E11) -> 0 | N217: =ABS(R11-F11) -> 50 | O217: =ABS(S11-C11) -> 189 | P217: =ABS(T11-D11) -> 0 | Q217: =ABS(U11-E11) -> 265 | R217: =ABS(V11-F11) -> 76 | S217: =IF(AND(C11=0, G11=0), 0, ABS(C11-G11)/((ABS(C11)+ABS(G11))/2)) -> 0.0034246575 | T217: =IF(AND(D11=0, H11=0), 0, ABS(D11-H11)/((ABS(D11)+ABS(H11))/2)) -> 0 | U217: =IF(AND(E11=0, I11=0), 0, ABS(E11-I11)/((ABS(E11)+ABS(I11))/2)) -> 2 | V217: =IF(AND(F11=0, J11=0), 0, ABS(F11-J11)/((ABS(F11)+ABS(J11))/2)) -> 0.00095875313 | X217: =IF(AND(C11=0, K11=0), 0, ABS(C11-K11)/((ABS(C11)+ABS(K11))/2)) -> 0.011346055 | Y217: =IF(AND(D11=0, L11=0), 0, ABS(D11-L11)/((ABS(D11)+ABS(L11))/2)) -> 0 | Z217: =IF(AND(E11=0, M11=0), 0, ABS(E11-M11)/((ABS(E11)+ABS(M11))/2)) -> 2 | AA217: =IF(AND(F11=0, N11=0), 0, ABS(F11-N11)/((ABS(F11)+ABS(N11))/2)) -> 0.00178885 | AC217: =IF(AND(C11=0, O11=0), 0, ABS(C11-O11)/((ABS(C11)+ABS(O11))/2)) -> 0.0013157895 | AD217: =IF(AND(D11=0, P11=0), 0, ABS(D11-P11)/((ABS(D11)+ABS(P11))/2)) -> 0 | AE217: =IF(AND(E11=0, Q11=0), 0, ABS(E11-Q11)/((ABS(E11)+ABS(Q11))/2)) -> 0 | AF217: =IF(AND(F11=0, R11=0), 0, ABS(F11-R11)/((ABS(F11)+ABS(R11))/2)) -> 0.00040983607 | AH217: =IF(AND(C11=0, S11=0), 0, ABS(C11-S11)/((ABS(C11)+ABS(S11))/2)) -> 0.0049827975 | AI217: =IF(AND(D11=0, T11=0), 0, ABS(D11-T11)/((ABS(D11)+ABS(T11))/2)) -> 0 | AJ217: =IF(AND(E11=0, U11=0), 0, ABS(E11-U11)/((ABS(E11)+ABS(U11))/2)) -> 2 | AK217: =IF(AND(F11=0, V11=0), 0, ABS(F11-V11)/((ABS(F11)+ABS(V11))/2)) -> 0.00062327267
B218: 8 | C218: =ABS(G12-C12) -> 85 | D218: =ABS(H12-D12) -> 0 | E218: =ABS(I12-E12) -> 0 | F218: =ABS(J12-F12) -> 85 | G218: =ABS(K12-C12) -> 271 | H218: =ABS(L12-D12) -> 0 | I218: =ABS(M12-E12) -> 386 | J218: =ABS(N12-F12) -> 115 | K218: =ABS(O12-C12) -> 74 | L218: =ABS(P12-D12) -> 0 | M218: =ABS(Q12-E12) -> 0 | N218: =ABS(R12-F12) -> 74 | O218: =ABS(S12-C12) -> 148 | P218: =ABS(T12-D12) -> 0 | Q218: =ABS(U12-E12) -> 189 | R218: =ABS(V12-F12) -> 41 | S218: =IF(AND(C12=0, G12=0), 0, ABS(C12-G12)/((ABS(C12)+ABS(G12))/2)) -> 0.0022378727 | T218: =IF(AND(D12=0, H12=0), 0, ABS(D12-H12)/((ABS(D12)+ABS(H12))/2)) -> 0 | U218: =IF(AND(E12=0, I12=0), 0, ABS(E12-I12)/((ABS(E12)+ABS(I12))/2)) -> 0 | V218: =IF(AND(F12=0, J12=0), 0, ABS(F12-J12)/((ABS(F12)+ABS(J12))/2)) -> 0.00069662139 | X218: =IF(AND(C12=0, K12=0), 0, ABS(C12-K12)/((ABS(C12)+ABS(K12))/2)) -> 0.0071523773 | Y218: =IF(AND(D12=0, L12=0), 0, ABS(D12-L12)/((ABS(D12)+ABS(L12))/2)) -> 0 | Z218: =IF(AND(E12=0, M12=0), 0, ABS(E12-M12)/((ABS(E12)+ABS(M12))/2)) -> 2 | AA218: =IF(AND(F12=0, N12=0), 0, ABS(F12-N12)/((ABS(F12)+ABS(N12))/2)) -> 0.00094326081 | AC218: =IF(AND(C12=0, O12=0), 0, ABS(C12-O12)/((ABS(C12)+ABS(O12))/2)) -> 0.0019479836 | AD218: =IF(AND(D12=0, P12=0), 0, ABS(D12-P12)/((ABS(D12)+ABS(P12))/2)) -> 0 | AE218: =IF(AND(E12=0, Q12=0), 0, ABS(E12-Q12)/((ABS(E12)+ABS(Q12))/2)) -> 0 | AF218: =IF(AND(F12=0, R12=0), 0, ABS(F12-R12)/((ABS(F12)+ABS(R12))/2)) -> 0.00060649772 | AH218: =IF(AND(C12=0, S12=0), 0, ABS(C12-S12)/((ABS(C12)+ABS(S12))/2)) -> 0.0038997655 | AI218: =IF(AND(D12=0, T12=0), 0, ABS(D12-T12)/((ABS(D12)+ABS(T12))/2)) -> 0 | AJ218: =IF(AND(E12=0, U12=0), 0, ABS(E12-U12)/((ABS(E12)+ABS(U12))/2)) -> 2 | AK218: =IF(AND(F12=0, V12=0), 0, ABS(F12-V12)/((ABS(F12)+ABS(V12))/2)) -> 0.00033619096
