Workbook

Sheet Color clustering
B1: image | C1: Pre-alignement | I1: Post-alignement
I2: Random correction | O2: Color classification
A3: 4_filled_cylinder/f_cyl_z/Col_clust | C3: #c88637 | D3: #e3bb37 | E3: #e65a49 | F3: #e98d78 | G3: #f1de9e | H3: #ffffff | I3: #c88637 | J3: #e3bb37 | K3: #e65a49 | L3: #e98d78 | M3: #f1de9e | N3: #ffffff | O3: #c88637 | P3: #e3bb37 | Q3: #e65a49 | R3: #e98d78 | S3: #f1de9e | T3: #ffffff
B4: 0 | C4: 0 | D4: 30149 | E4: 0 | F4: 0 | G4: 0 | H4: 129851 | I4: 0 | J4: 30149 | L4: 0 | M4: 0 | N4: 129851 | O4: 0 | P4: 30149 | Q4: 0 | R4: 0 | S4: 0 | T4: 129851
B5: 1 | C5: 0 | D5: 29952 | E5: 0 | F5: 0 | G5: 394 | H5: 129654 | I5: 0 | J5: 30152 | L5: 0 | M5: 22 | N5: 129826 | O5: 0 | P5: 29912 | Q5: 0 | R5: 0 | S5: 482 | T5: 129606
B6: 2 | C6: 0 | D6: 30149 | E6: 0 | F6: 0 | G6: 0 | H6: 129851 | I6: 0 | J6: 30112 | L6: 0 | M6: 6 | N6: 129882 | O6: 0 | P6: 29989 | Q6: 0 | R6: 0 | S6: 338 | T6: 129673
B7: 3 | C7: 0 | D7: 30149 | E7: 0 | F7: 0 | G7: 0 | H7: 129851 | I7: 0 | J7: 30102 | L7: 0 | M7: 10 | N7: 129888 | O7: 0 | P7: 29991 | Q7: 0 | R7: 0 | S7: 331 | T7: 129678
B8: 4 | C8: 0 | D8: 30149 | E8: 0 | F8: 0 | G8: 0 | H8: 129851 | I8: 0 | J8: 30175 | L8: 0 | M8: 0 | N8: 129825 | O8: 0 | P8: 30149 | Q8: 0 | R8: 0 | S8: 0 | T8: 129851
B9: 5 | C9: 0 | D9: 29952 | E9: 0 | F9: 0 | G9: 394 | H9: 129654 | I9: 0 | J9: 30229 | L9: 0 | M9: 2 | N9: 129769 | O9: 0 | P9: 29962 | Q9: 0 | R9: 0 | S9: 398 | T9: 129640
B10: 6 | C10: 0 | D10: 29872 | E10: 0 | F10: 0 | G10: 554 | H10: 129574 | I10: 0 | J10: 30106 | L10: 0 | M10: 0 | N10: 129894 | O10: 0 | P10: 29881 | Q10: 0 | R10: 0 | S10: 554 | T10: 129565
B11: 7 | C11: 0 | D11: 29872 | E11: 0 | F11: 0 | G11: 554 | H11: 129574 | I11: 0 | J11: 30126 | L11: 0 | M11: 0 | N11: 129874 | O11: 0 | P11: 29904 | Q11: 0 | R11: 0 | S11: 555 | T11: 129541
B12: 8 | C12: 0 | D12: 29952 | E12: 0 | F12: 0 | G12: 394 | H12: 129654 | I12: 0 | J12: 30106 | L12: 0 | M12: 0 | N12: 129894 | O12: 0 | P12: 29927 | Q12: 0 | R12: 0 | S12: 459 | T12: 129614
B13: 9 | C13: 0 | D13: 29952 | E13: 0 | F13: 0 | G13: 394 | H13: 129654 | I13: 0 | J13: 30148 | L13: 0 | M13: 0 | N13: 129852 | O13: 0 | P13: 29923 | Q13: 0 | R13: 0 | S13: 464 | T13: 129613
B14: 10 | C14: 0 | D14: 30149 | E14: 0 | F14: 0 | G14: 0 | H14: 129851 | I14: 0 | J14: 30117 | L14: 0 | M14: 8 | N14: 129875 | O14: 0 | P14: 29985 | Q14: 0 | R14: 0 | S14: 341 | T14: 129674
B15: 11 | C15: 0 | D15: 29952 | E15: 0 | F15: 0 | G15: 394 | H15: 129654 | I15: 0 | J15: 30103 | L15: 0 | M15: 0 | N15: 129897 | O15: 0 | P15: 29923 | Q15: 0 | R15: 0 | S15: 467 | T15: 129610
... B203: 199 | C203: 0 | D203: 30090 | E203: 0 | F203: 0 | G203: 197 | H203: 129713 | I203: 0 | J203: 30197 | L203: 0 | M203: 0 | N203: 129803 | O203: 0 | P203: 30090 | Q203: 0 | R203: 0 | S203: 198 | T203: 129712
B204: Total | C204: =SUM(C4:C203) -> 252678 | D204: =SUM(D4:D203) -> 5372930 | E204: =SUM(E4:E203) -> 103536 | F204: =SUM(F4:F203) -> 274593 | G204: =SUM(G4:G203) -> 55654 | H204: =SUM(H4:H203) -> 25940609 | I204: =SUM(I4:I203) -> 249913 | J204: =SUM(J4:J203) -> 5506546 | L204: =SUM(L4:L203) -> 272706 | M204: =SUM(M4:M203) -> 791 | N204: =SUM(N4:N203) -> 25970044 | O204: =SUM(O4:O203) -> 253611 | P204: =SUM(P4:P203) -> 5365902 | Q204: =SUM(Q4:Q203) -> 103214 | R204: =SUM(R4:R203) -> 274490 | S204: =SUM(S4:S203) -> 71335 | T204: =SUM(T4:T203) -> 25931448
B209: image | C209: Absolute Error | O209: SMAPE
C210: Random correction | I210: Color classification | O210: Random correction | V210: Color classification
A211: 4_filled_cylinder/f_cyl_x/Col_clust | C211: #c88637 | D211: #e3bb37 | E211: #e65a49 | F211: #e98d78 | G211: #f1de9e | H211: #ffffff | I211: #c88637 | J211: #e3bb37 | K211: #e65a49 | L211: #e98d78 | M211: #f1de9e | N211: #ffffff | O211: #c88637 | P211: #e3bb37 | Q211: #e65a49 | R211: #e98d78 | S211: #f1de9e | T211: #ffffff | V211: #c88637 | W211: #e3bb37 | X211: #e65a49 | Y211: #e98d78 | Z211: #f1de9e | AA211: #ffffff
B212: 0 | C212: =ABS(I4-C4) -> 0 | D212: =ABS(J4-D4) -> 0 | E212: =ABS(K4-E4) -> 0 | F212: =ABS(L4-F4) -> 0 | G212: =ABS(M4-G4) -> 0 | H212: =ABS(N4-H4) -> 0 | I212: =ABS(O4-C4) -> 0 | J212: =ABS(P4-D4) -> 0 | K212: =ABS(Q4-E4) -> 0 | L212: =ABS(R4-F4) -> 0 | M212: =ABS(S4-G4) -> 0 | N212: =ABS(T4-H4) -> 0 | O212: =IF(AND(C4=0,I4=0), 0, ABS(C4-I4)/((ABS(C4)+ABS(I4))/2)) -> 0 | P212: =IF(AND(D4=0,J4=0), 0, ABS(D4-J4)/((ABS(D4)+ABS(J4))/2)) -> 0 | Q212: =IF(AND(E4=0,K4=0), 0, ABS(E4-K4)/((ABS(E4)+ABS(K4))/2)) -> 0 | R212: =IF(AND(F4=0,L4=0), 0, ABS(F4-L4)/((ABS(F4)+ABS(L4))/2)) -> 0 | S212: =IF(AND(G4=0,M4=0), 0, ABS(G4-M4)/((ABS(G4)+ABS(M4))/2)) -> 0 | T212: =IF(AND(H4=0,N4=0), 0, ABS(H4-N4)/((ABS(H4)+ABS(N4))/2)) -> 0 | V212: =IF(AND(C4=0,O4=0), 0, ABS(C4-O4)/((ABS(C4)+ABS(O4))/2)) -> 0 | W212: =IF(AND(D4=0,P4=0), 0, ABS(D4-P4)/((ABS(D4)+ABS(P4))/2)) -> 0 | X212: =IF(AND(E4=0,Q4=0), 0, ABS(E4-Q4)/((ABS(E4)+ABS(Q4))/2)) -> 0 | Y212: =IF(AND(F4=0,R4=0), 0, ABS(F4-R4)/((ABS(F4)+ABS(R4))/2)) -> 0 | Z212: =IF(AND(G4=0,S4=0), 0, ABS(G4-S4)/((ABS(G4)+ABS(S4))/2)) -> 0 | AA212: =IF(AND(H4=0,T4=0), 0, ABS(H4-T4)/((ABS(H4)+ABS(T4))/2)) -> 0
B213: 1 | C213: =ABS(I5-C5) -> 0 | D213: =ABS(J5-D5) -> 200 | E213: =ABS(K5-E5) -> 0 | F213: =ABS(L5-F5) -> 0 | G213: =ABS(M5-G5) -> 372 | H213: =ABS(N5-H5) -> 172 | I213: =ABS(O5-C5) -> 0 | J213: =ABS(P5-D5) -> 40 | K213: =ABS(Q5-E5) -> 0 | L213: =ABS(R5-F5) -> 0 | M213: =ABS(S5-G5) -> 88 | N213: =ABS(T5-H5) -> 48 | O213: =IF(AND(C5=0,I5=0), 0, ABS(C5-I5)/((ABS(C5)+ABS(I5))/2)) -> 0 | P213: =IF(AND(D5=0,J5=0), 0, ABS(D5-J5)/((ABS(D5)+ABS(J5))/2)) -> 0.0066551311 | Q213: =IF(AND(E5=0,K5=0), 0, ABS(E5-K5)/((ABS(E5)+ABS(K5))/2)) -> 0 | R213: =IF(AND(F5=0,L5=0), 0, ABS(F5-L5)/((ABS(F5)+ABS(L5))/2)) -> 0 | S213: =IF(AND(G5=0,M5=0), 0, ABS(G5-M5)/((ABS(G5)+ABS(M5))/2)) -> 1.7884615 | T213: =IF(AND(H5=0,N5=0), 0, ABS(H5-N5)/((ABS(H5)+ABS(N5))/2)) -> 0.0013257284 | V213: =IF(AND(C5=0,O5=0), 0, ABS(C5-O5)/((ABS(C5)+ABS(O5))/2)) -> 0 | W213: =IF(AND(D5=0,P5=0), 0, ABS(D5-P5)/((ABS(D5)+ABS(P5))/2)) -> 0.0013363624 | X213: =IF(AND(E5=0,Q5=0), 0, ABS(E5-Q5)/((ABS(E5)+ABS(Q5))/2)) -> 0 | Y213: =IF(AND(F5=0,R5=0), 0, ABS(F5-R5)/((ABS(F5)+ABS(R5))/2)) -> 0 | Z213: =IF(AND(G5=0,S5=0), 0, ABS(G5-S5)/((ABS(G5)+ABS(S5))/2)) -> 0.20091324 | AA213: =IF(AND(H5=0,T5=0), 0, ABS(H5-T5)/((ABS(H5)+ABS(T5))/2)) -> 0.00037028466
B214: 2 | C214: =ABS(I6-C6) -> 0 | D214: =ABS(J6-D6) -> 37 | E214: =ABS(K6-E6) -> 0 | F214: =ABS(L6-F6) -> 0 | G214: =ABS(M6-G6) -> 6 | H214: =ABS(N6-H6) -> 31 | I214: =ABS(O6-C6) -> 0 | J214: =ABS(P6-D6) -> 160 | K214: =ABS(Q6-E6) -> 0 | L214: =ABS(R6-F6) -> 0 | M214: =ABS(S6-G6) -> 338 | N214: =ABS(T6-H6) -> 178 | O214: =IF(AND(C6=0,I6=0), 0, ABS(C6-I6)/((ABS(C6)+ABS(I6))/2)) -> 0 | P214: =IF(AND(D6=0,J6=0), 0, ABS(D6-J6)/((ABS(D6)+ABS(J6))/2)) -> 0.0012279916 | Q214: =IF(AND(E6=0,K6=0), 0, ABS(E6-K6)/((ABS(E6)+ABS(K6))/2)) -> 0 | R214: =IF(AND(F6=0,L6=0), 0, ABS(F6-L6)/((ABS(F6)+ABS(L6))/2)) -> 0 | S214: =IF(AND(G6=0,M6=0), 0, ABS(G6-M6)/((ABS(G6)+ABS(M6))/2)) -> 2 | T214: =IF(AND(H6=0,N6=0), 0, ABS(H6-N6)/((ABS(H6)+ABS(N6))/2)) -> 0.00023870667 | V214: =IF(AND(C6=0,O6=0), 0, ABS(C6-O6)/((ABS(C6)+ABS(O6))/2)) -> 0 | W214: =IF(AND(D6=0,P6=0), 0, ABS(D6-P6)/((ABS(D6)+ABS(P6))/2)) -> 0.0053210948 | X214: =IF(AND(E6=0,Q6=0), 0, ABS(E6-Q6)/((ABS(E6)+ABS(Q6))/2)) -> 0 | Y214: =IF(AND(F6=0,R6=0), 0, ABS(F6-R6)/((ABS(F6)+ABS(R6))/2)) -> 0 | Z214: =IF(AND(G6=0,S6=0), 0, ABS(G6-S6)/((ABS(G6)+ABS(S6))/2)) -> 2 | AA214: =IF(AND(H6=0,T6=0), 0, ABS(H6-T6)/((ABS(H6)+ABS(T6))/2)) -> 0.0013717421
B215: 3 | C215: =ABS(I7-C7) -> 0 | D215: =ABS(J7-D7) -> 47 | E215: =ABS(K7-E7) -> 0 | F215: =ABS(L7-F7) -> 0 | G215: =ABS(M7-G7) -> 10 | H215: =ABS(N7-H7) -> 37 | I215: =ABS(O7-C7) -> 0 | J215: =ABS(P7-D7) -> 158 | K215: =ABS(Q7-E7) -> 0 | L215: =ABS(R7-F7) -> 0 | M215: =ABS(S7-G7) -> 331 | N215: =ABS(T7-H7) -> 173 | O215: =IF(AND(C7=0,I7=0), 0, ABS(C7-I7)/((ABS(C7)+ABS(I7))/2)) -> 0 | P215: =IF(AND(D7=0,J7=0), 0, ABS(D7-J7)/((ABS(D7)+ABS(J7))/2)) -> 0.0015601401 | Q215: =IF(AND(E7=0,K7=0), 0, ABS(E7-K7)/((ABS(E7)+ABS(K7))/2)) -> 0 | R215: =IF(AND(F7=0,L7=0), 0, ABS(F7-L7)/((ABS(F7)+ABS(L7))/2)) -> 0 | S215: =IF(AND(G7=0,M7=0), 0, ABS(G7-M7)/((ABS(G7)+ABS(M7))/2)) -> 2 | T215: =IF(AND(H7=0,N7=0), 0, ABS(H7-N7)/((ABS(H7)+ABS(N7))/2)) -> 0.00028490138 | V215: =IF(AND(C7=0,O7=0), 0, ABS(C7-O7)/((ABS(C7)+ABS(O7))/2)) -> 0 | W215: =IF(AND(D7=0,P7=0), 0, ABS(D7-P7)/((ABS(D7)+ABS(P7))/2)) -> 0.0052544064 | X215: =IF(AND(E7=0,Q7=0), 0, ABS(E7-Q7)/((ABS(E7)+ABS(Q7))/2)) -> 0 | Y215: =IF(AND(F7=0,R7=0), 0, ABS(F7-R7)/((ABS(F7)+ABS(R7))/2)) -> 0 | Z215: =IF(AND(G7=0,S7=0), 0, ABS(G7-S7)/((ABS(G7)+ABS(S7))/2)) -> 2 | AA215: =IF(AND(H7=0,T7=0), 0, ABS(H7-T7)/((ABS(H7)+ABS(T7))/2)) -> 0.0013331843
B216: 4 | C216: =ABS(I8-C8) -> 0 | D216: =ABS(J8-D8) -> 26 | E216: =ABS(K8-E8) -> 0 | F216: =ABS(L8-F8) -> 0 | G216: =ABS(M8-G8) -> 0 | H216: =ABS(N8-H8) -> 26 | I216: =ABS(O8-C8) -> 0 | J216: =ABS(P8-D8) -> 0 | K216: =ABS(Q8-E8) -> 0 | L216: =ABS(R8-F8) -> 0 | M216: =ABS(S8-G8) -> 0 | N216: =ABS(T8-H8) -> 0 | O216: =IF(AND(C8=0,I8=0), 0, ABS(C8-I8)/((ABS(C8)+ABS(I8))/2)) -> 0 | P216: =IF(AND(D8=0,J8=0), 0, ABS(D8-J8)/((ABS(D8)+ABS(J8))/2)) -> 0.0008620118 | Q216: =IF(AND(E8=0,K8=0), 0, ABS(E8-K8)/((ABS(E8)+ABS(K8))/2)) -> 0 | R216: =IF(AND(F8=0,L8=0), 0, ABS(F8-L8)/((ABS(F8)+ABS(L8))/2)) -> 0 | S216: =IF(AND(G8=0,M8=0), 0, ABS(G8-M8)/((ABS(G8)+ABS(M8))/2)) -> 0 | T216: =IF(AND(H8=0,N8=0), 0, ABS(H8-N8)/((ABS(H8)+ABS(N8))/2)) -> 0.00020024954 | V216: =IF(AND(C8=0,O8=0), 0, ABS(C8-O8)/((ABS(C8)+ABS(O8))/2)) -> 0 | W216: =IF(AND(D8=0,P8=0), 0, ABS(D8-P8)/((ABS(D8)+ABS(P8))/2)) -> 0 | X216: =IF(AND(E8=0,Q8=0), 0, ABS(E8-Q8)/((ABS(E8)+ABS(Q8))/2)) -> 0 | Y216: =IF(AND(F8=0,R8=0), 0, ABS(F8-R8)/((ABS(F8)+ABS(R8))/2)) -> 0 | Z216: =IF(AND(G8=0,S8=0), 0, ABS(G8-S8)/((ABS(G8)+ABS(S8))/2)) -> 0 | AA216: =IF(AND(H8=0,T8=0), 0, ABS(H8-T8)/((ABS(H8)+ABS(T8))/2)) -> 0
B217: 5 | C217: =ABS(I9-C9) -> 0 | D217: =ABS(J9-D9) -> 277 | E217: =ABS(K9-E9) -> 0 | F217: =ABS(L9-F9) -> 0 | G217: =ABS(M9-G9) -> 392 | H217: =ABS(N9-H9) -> 115 | I217: =ABS(O9-C9) -> 0 | J217: =ABS(P9-D9) -> 10 | K217: =ABS(Q9-E9) -> 0 | L217: =ABS(R9-F9) -> 0 | M217: =ABS(S9-G9) -> 4 | N217: =ABS(T9-H9) -> 14 | O217: =IF(AND(C9=0,I9=0), 0, ABS(C9-I9)/((ABS(C9)+ABS(I9))/2)) -> 0 | P217: =IF(AND(D9=0,J9=0), 0, ABS(D9-J9)/((ABS(D9)+ABS(J9))/2)) -> 0.0092055632 | Q217: =IF(AND(E9=0,K9=0), 0, ABS(E9-K9)/((ABS(E9)+ABS(K9))/2)) -> 0 | R217: =IF(AND(F9=0,L9=0), 0, ABS(F9-L9)/((ABS(F9)+ABS(L9))/2)) -> 0 | S217: =IF(AND(G9=0,M9=0), 0, ABS(G9-M9)/((ABS(G9)+ABS(M9))/2)) -> 1.979798 | T217: =IF(AND(H9=0,N9=0), 0, ABS(H9-N9)/((ABS(H9)+ABS(N9))/2)) -> 0.00088658292 | V217: =IF(AND(C9=0,O9=0), 0, ABS(C9-O9)/((ABS(C9)+ABS(O9))/2)) -> 0 | W217: =IF(AND(D9=0,P9=0), 0, ABS(D9-P9)/((ABS(D9)+ABS(P9))/2)) -> 0.0003338118 | X217: =IF(AND(E9=0,Q9=0), 0, ABS(E9-Q9)/((ABS(E9)+ABS(Q9))/2)) -> 0 | Y217: =IF(AND(F9=0,R9=0), 0, ABS(F9-R9)/((ABS(F9)+ABS(R9))/2)) -> 0 | Z217: =IF(AND(G9=0,S9=0), 0, ABS(G9-S9)/((ABS(G9)+ABS(S9))/2)) -> 0.01010101 | AA217: =IF(AND(H9=0,T9=0), 0, ABS(H9-T9)/((ABS(H9)+ABS(T9))/2)) -> 0.00010798553
B218: 6 | C218: =ABS(I10-C10) -> 0 | D218: =ABS(J10-D10) -> 234 | E218: =ABS(K10-E10) -> 0 | F218: =ABS(L10-F10) -> 0 | G218: =ABS(M10-G10) -> 554 | H218: =ABS(N10-H10) -> 320 | I218: =ABS(O10-C10) -> 0 | J218: =ABS(P10-D10) -> 9 | K218: =ABS(Q10-E10) -> 0 | L218: =ABS(R10-F10) -> 0 | M218: =ABS(S10-G10) -> 0 | N218: =ABS(T10-H10) -> 9 | O218: =IF(AND(C10=0,I10=0), 0, ABS(C10-I10)/((ABS(C10)+ABS(I10))/2)) -> 0 | P218: =IF(AND(D10=0,J10=0), 0, ABS(D10-J10)/((ABS(D10)+ABS(J10))/2)) -> 0.007802861 | Q218: =IF(AND(E10=0,K10=0), 0, ABS(E10-K10)/((ABS(E10)+ABS(K10))/2)) -> 0 | R218: =IF(AND(F10=0,L10=0), 0, ABS(F10-L10)/((ABS(F10)+ABS(L10))/2)) -> 0 | S218: =IF(AND(G10=0,M10=0), 0, ABS(G10-M10)/((ABS(G10)+ABS(M10))/2)) -> 2 | T218: =IF(AND(H10=0,N10=0), 0, ABS(H10-N10)/((ABS(H10)+ABS(N10))/2)) -> 0.0024665855 | V218: =IF(AND(C10=0,O10=0), 0, ABS(C10-O10)/((ABS(C10)+ABS(O10))/2)) -> 0 | W218: =IF(AND(D10=0,P10=0), 0, ABS(D10-P10)/((ABS(D10)+ABS(P10))/2)) -> 0.00030124011 | X218: =IF(AND(E10=0,Q10=0), 0, ABS(E10-Q10)/((ABS(E10)+ABS(Q10))/2)) -> 0 | Y218: =IF(AND(F10=0,R10=0), 0, ABS(F10-R10)/((ABS(F10)+ABS(R10))/2)) -> 0 | Z218: =IF(AND(G10=0,S10=0), 0, ABS(G10-S10)/((ABS(G10)+ABS(S10))/2)) -> 0 | AA218: =IF(AND(H10=0,T10=0), 0, ABS(H10-T10)/((ABS(H10)+ABS(T10))/2)) -> 6.9460791e-05
B219: 7 | C219: =ABS(I11-C11) -> 0 | D219: =ABS(J11-D11) -> 254 | E219: =ABS(K11-E11) -> 0 | F219: =ABS(L11-F11) -> 0 | G219: =ABS(M11-G11) -> 554 | H219: =ABS(N11-H11) -> 300 | I219: =ABS(O11-C11) -> 0 | J219: =ABS(P11-D11) -> 32 | K219: =ABS(Q11-E11) -> 0 | L219: =ABS(R11-F11) -> 0 | M219: =ABS(S11-G11) -> 1 | N219: =ABS(T11-H11) -> 33 | O219: =IF(AND(C11=0,I11=0), 0, ABS(C11-I11)/((ABS(C11)+ABS(I11))/2)) -> 0 | P219: =IF(AND(D11=0,J11=0), 0, ABS(D11-J11)/((ABS(D11)+ABS(J11))/2)) -> 0.0084669489 | Q219: =IF(AND(E11=0,K11=0), 0, ABS(E11-K11)/((ABS(E11)+ABS(K11))/2)) -> 0 | R219: =IF(AND(F11=0,L11=0), 0, ABS(F11-L11)/((ABS(F11)+ABS(L11))/2)) -> 0 | S219: =IF(AND(G11=0,M11=0), 0, ABS(G11-M11)/((ABS(G11)+ABS(M11))/2)) -> 2 | T219: =IF(AND(H11=0,N11=0), 0, ABS(H11-N11)/((ABS(H11)+ABS(N11))/2)) -> 0.0023126021 | V219: =IF(AND(C11=0,O11=0), 0, ABS(C11-O11)/((ABS(C11)+ABS(O11))/2)) -> 0 | W219: =IF(AND(D11=0,P11=0), 0, ABS(D11-P11)/((ABS(D11)+ABS(P11))/2)) -> 0.0010706638 | X219: =IF(AND(E11=0,Q11=0), 0, ABS(E11-Q11)/((ABS(E11)+ABS(Q11))/2)) -> 0 | Y219: =IF(AND(F11=0,R11=0), 0, ABS(F11-R11)/((ABS(F11)+ABS(R11))/2)) -> 0 | Z219: =IF(AND(G11=0,S11=0), 0, ABS(G11-S11)/((ABS(G11)+ABS(S11))/2)) -> 0.0018034265 | AA219: =IF(AND(H11=0,T11=0), 0, ABS(H11-T11)/((ABS(H11)+ABS(T11))/2)) -> 0.00025471316
B220: 8 | C220: =ABS(I12-C12) -> 0 | D220: =ABS(J12-D12) -> 154 | E220: =ABS(K12-E12) -> 0 | F220: =ABS(L12-F12) -> 0 | G220: =ABS(M12-G12) -> 394 | H220: =ABS(N12-H12) -> 240 | I220: =ABS(O12-C12) -> 0 | J220: =ABS(P12-D12) -> 25 | K220: =ABS(Q12-E12) -> 0 | L220: =ABS(R12-F12) -> 0 | M220: =ABS(S12-G12) -> 65 | N220: =ABS(T12-H12) -> 40 | O220: =IF(AND(C12=0,I12=0), 0, ABS(C12-I12)/((ABS(C12)+ABS(I12))/2)) -> 0 | P220: =IF(AND(D12=0,J12=0), 0, ABS(D12-J12)/((ABS(D12)+ABS(J12))/2)) -> 0.0051283759 | Q220: =IF(AND(E12=0,K12=0), 0, ABS(E12-K12)/((ABS(E12)+ABS(K12))/2)) -> 0 | R220: =IF(AND(F12=0,L12=0), 0, ABS(F12-L12)/((ABS(F12)+ABS(L12))/2)) -> 0 | S220: =IF(AND(G12=0,M12=0), 0, ABS(G12-M12)/((ABS(G12)+ABS(M12))/2)) -> 2 | T220: =IF(AND(H12=0,N12=0), 0, ABS(H12-N12)/((ABS(H12)+ABS(N12))/2)) -> 0.0018493689 | V220: =IF(AND(C12=0,O12=0), 0, ABS(C12-O12)/((ABS(C12)+ABS(O12))/2)) -> 0 | W220: =IF(AND(D12=0,P12=0), 0, ABS(D12-P12)/((ABS(D12)+ABS(P12))/2)) -> 0.00083501728 | X220: =IF(AND(E12=0,Q12=0), 0, ABS(E12-Q12)/((ABS(E12)+ABS(Q12))/2)) -> 0 | Y220: =IF(AND(F12=0,R12=0), 0, ABS(F12-R12)/((ABS(F12)+ABS(R12))/2)) -> 0 | Z220: =IF(AND(G12=0,S12=0), 0, ABS(G12-S12)/((ABS(G12)+ABS(S12))/2)) -> 0.15240328 | AA220: =IF(AND(H12=0,T12=0), 0, ABS(H12-T12)/((ABS(H12)+ABS(T12))/2)) -> 0.00030856103
B221: 9 | C221: =ABS(I13-C13) -> 0 | D221: =ABS(J13-D13) -> 196 | E221: =ABS(K13-E13) -> 0 | F221: =ABS(L13-F13) -> 0 | G221: =ABS(M13-G13) -> 394 | H221: =ABS(N13-H13) -> 198 | I221: =ABS(O13-C13) -> 0 | J221: =ABS(P13-D13) -> 29 | K221: =ABS(Q13-E13) -> 0 | L221: =ABS(R13-F13) -> 0 | M221: =ABS(S13-G13) -> 70 | N221: =ABS(T13-H13) -> 41 | O221: =IF(AND(C13=0,I13=0), 0, ABS(C13-I13)/((ABS(C13)+ABS(I13))/2)) -> 0 | P221: =IF(AND(D13=0,J13=0), 0, ABS(D13-J13)/((ABS(D13)+ABS(J13))/2)) -> 0.0065224626 | Q221: =IF(AND(E13=0,K13=0), 0, ABS(E13-K13)/((ABS(E13)+ABS(K13))/2)) -> 0 | R221: =IF(AND(F13=0,L13=0), 0, ABS(F13-L13)/((ABS(F13)+ABS(L13))/2)) -> 0 | S221: =IF(AND(G13=0,M13=0), 0, ABS(G13-M13)/((ABS(G13)+ABS(M13))/2)) -> 2 | T221: =IF(AND(H13=0,N13=0), 0, ABS(H13-N13)/((ABS(H13)+ABS(N13))/2)) -> 0.0015259763 | V221: =IF(AND(C13=0,O13=0), 0, ABS(C13-O13)/((ABS(C13)+ABS(O13))/2)) -> 0 | W221: =IF(AND(D13=0,P13=0), 0, ABS(D13-P13)/((ABS(D13)+ABS(P13))/2)) -> 0.00096868476 | X221: =IF(AND(E13=0,Q13=0), 0, ABS(E13-Q13)/((ABS(E13)+ABS(Q13))/2)) -> 0 | Y221: =IF(AND(F13=0,R13=0), 0, ABS(F13-R13)/((ABS(F13)+ABS(R13))/2)) -> 0 | Z221: =IF(AND(G13=0,S13=0), 0, ABS(G13-S13)/((ABS(G13)+ABS(S13))/2)) -> 0.16317016 | AA221: =IF(AND(H13=0,T13=0), 0, ABS(H13-T13)/((ABS(H13)+ABS(T13))/2)) -> 0.00031627627
B222: 10 | C222: =ABS(I14-C14) -> 0 | D222: =ABS(J14-D14) -> 32 | E222: =ABS(K14-E14) -> 0 | F222: =ABS(L14-F14) -> 0 | G222: =ABS(M14-G14) -> 8 | H222: =ABS(N14-H14) -> 24 | I222: =ABS(O14-C14) -> 0 | J222: =ABS(P14-D14) -> 164 | K222: =ABS(Q14-E14) -> 0 | L222: =ABS(R14-F14) -> 0 | M222: =ABS(S14-G14) -> 341 | N222: =ABS(T14-H14) -> 177 | O222: =IF(AND(C14=0,I14=0), 0, ABS(C14-I14)/((ABS(C14)+ABS(I14))/2)) -> 0 | P222: =IF(AND(D14=0,J14=0), 0, ABS(D14-J14)/((ABS(D14)+ABS(J14))/2)) -> 0.0010619586 | Q222: =IF(AND(E14=0,K14=0), 0, ABS(E14-K14)/((ABS(E14)+ABS(K14))/2)) -> 0 | R222: =IF(AND(F14=0,L14=0), 0, ABS(F14-L14)/((ABS(F14)+ABS(L14))/2)) -> 0 | S222: =IF(AND(G14=0,M14=0), 0, ABS(G14-M14)/((ABS(G14)+ABS(M14))/2)) -> 2 | T222: =IF(AND(H14=0,N14=0), 0, ABS(H14-N14)/((ABS(H14)+ABS(N14))/2)) -> 0.00018481015 | V222: =IF(AND(C14=0,O14=0), 0, ABS(C14-O14)/((ABS(C14)+ABS(O14))/2)) -> 0 | W222: =IF(AND(D14=0,P14=0), 0, ABS(D14-P14)/((ABS(D14)+ABS(P14))/2)) -> 0.005454485 | X222: =IF(AND(E14=0,Q14=0), 0, ABS(E14-Q14)/((ABS(E14)+ABS(Q14))/2)) -> 0 | Y222: =IF(AND(F14=0,R14=0), 0, ABS(F14-R14)/((ABS(F14)+ABS(R14))/2)) -> 0 | Z222: =IF(AND(G14=0,S14=0), 0, ABS(G14-S14)/((ABS(G14)+ABS(S14))/2)) -> 2 | AA222: =IF(AND(H14=0,T14=0), 0, ABS(H14-T14)/((ABS(H14)+ABS(T14))/2)) -> 0.0013640304
B223: 11 | C223: =ABS(I15-C15) -> 0 | D223: =ABS(J15-D15) -> 151 | E223: =ABS(K15-E15) -> 0 | F223: =ABS(L15-F15) -> 0 | G223: =ABS(M15-G15) -> 394 | H223: =ABS(N15-H15) -> 243 | I223: =ABS(O15-C15) -> 0 | J223: =ABS(P15-D15) -> 29 | K223: =ABS(Q15-E15) -> 0 | L223: =ABS(R15-F15) -> 0 | M223: =ABS(S15-G15) -> 73 | N223: =ABS(T15-H15) -> 44 | O223: =IF(AND(C15=0,I15=0), 0, ABS(C15-I15)/((ABS(C15)+ABS(I15))/2)) -> 0 | P223: =IF(AND(D15=0,J15=0), 0, ABS(D15-J15)/((ABS(D15)+ABS(J15))/2)) -> 0.0050287237 | Q223: =IF(AND(E15=0,K15=0), 0, ABS(E15-K15)/((ABS(E15)+ABS(K15))/2)) -> 0 | R223: =IF(AND(F15=0,L15=0), 0, ABS(F15-L15)/((ABS(F15)+ABS(L15))/2)) -> 0 | S223: =IF(AND(G15=0,M15=0), 0, ABS(G15-M15)/((ABS(G15)+ABS(M15))/2)) -> 2 | T223: =IF(AND(H15=0,N15=0), 0, ABS(H15-N15)/((ABS(H15)+ABS(N15))/2)) -> 0.0018724644 | V223: =IF(AND(C15=0,O15=0), 0, ABS(C15-O15)/((ABS(C15)+ABS(O15))/2)) -> 0 | W223: =IF(AND(D15=0,P15=0), 0, ABS(D15-P15)/((ABS(D15)+ABS(P15))/2)) -> 0.00096868476 | X223: =IF(AND(E15=0,Q15=0), 0, ABS(E15-Q15)/((ABS(E15)+ABS(Q15))/2)) -> 0 | Y223: =IF(AND(F15=0,R15=0), 0, ABS(F15-R15)/((ABS(F15)+ABS(R15))/2)) -> 0 | Z223: =IF(AND(G15=0,S15=0), 0, ABS(G15-S15)/((ABS(G15)+ABS(S15))/2)) -> 0.16957027 | AA223: =IF(AND(H15=0,T15=0), 0, ABS(H15-T15)/((ABS(H15)+ABS(T15))/2)) -> 0.00033942236
... B410: 198 | C410: =ABS(I202-C202) -> 0 | D410: =ABS(J202-D202) -> 72 | E410: =ABS(K202-E202) -> 0 | F410: =ABS(L202-F202) -> 0 | G410: =ABS(M202-G202) -> 58 | H410: =ABS(N202-H202) -> 14 | I410: =ABS(O202-C202) -> 0 | J410: =ABS(P202-D202) -> 0 | K410: =ABS(Q202-E202) -> 0 | L410: =ABS(R202-F202) -> 0 | M410: =ABS(S202-G202) -> 0 | N410: =ABS(T202-H202) -> 0 | O410: =IF(AND(C202=0,I202=0), 0, ABS(C202-I202)/((ABS(C202)+ABS(I202))/2)) -> 0 | P410: =IF(AND(D202=0,J202=0), 0, ABS(D202-J202)/((ABS(D202)+ABS(J202))/2)) -> 0.0023852907 | Q410: =IF(AND(E202=0,K202=0), 0, ABS(E202-K202)/((ABS(E202)+ABS(K202))/2)) -> 0 | R410: =IF(AND(F202=0,L202=0), 0, ABS(F202-L202)/((ABS(F202)+ABS(L202))/2)) -> 0 | S410: =IF(AND(G202=0,M202=0), 0, ABS(G202-M202)/((ABS(G202)+ABS(M202))/2)) -> 2 | T410: =IF(AND(H202=0,N202=0), 0, ABS(H202-N202)/((ABS(H202)+ABS(N202))/2)) -> 0.00010786988 | V410: =IF(AND(C202=0,O202=0), 0, ABS(C202-O202)/((ABS(C202)+ABS(O202))/2)) -> 0 | W410: =IF(AND(D202=0,P202=0), 0, ABS(D202-P202)/((ABS(D202)+ABS(P202))/2)) -> 0 | X410: =IF(AND(E202=0,Q202=0), 0, ABS(E202-Q202)/((ABS(E202)+ABS(Q202))/2)) -> 0 | Y410: =IF(AND(F202=0,R202=0), 0, ABS(F202-R202)/((ABS(F202)+ABS(R202))/2)) -> 0 | Z410: =IF(AND(G202=0,S202=0), 0, ABS(G202-S202)/((ABS(G202)+ABS(S202))/2)) -> 0 | AA410: =IF(AND(H202=0,T202=0), 0, ABS(H202-T202)/((ABS(H202)+ABS(T202))/2)) -> 0
B411: 199 | C411: =ABS(I203-C203) -> 0 | D411: =ABS(J203-D203) -> 107 | E411: =ABS(K203-E203) -> 0 | F411: =ABS(L203-F203) -> 0 | G411: =ABS(M203-G203) -> 197 | H411: =ABS(N203-H203) -> 90 | I411: =ABS(O203-C203) -> 0 | J411: =ABS(P203-D203) -> 0 | K411: =ABS(Q203-E203) -> 0 | L411: =ABS(R203-F203) -> 0 | M411: =ABS(S203-G203) -> 1 | N411: =ABS(T203-H203) -> 1 | O411: =IF(AND(C203=0,I203=0), 0, ABS(C203-I203)/((ABS(C203)+ABS(I203))/2)) -> 0 | P411: =IF(AND(D203=0,J203=0), 0, ABS(D203-J203)/((ABS(D203)+ABS(J203))/2)) -> 0.0035496873 | Q411: =IF(AND(E203=0,K203=0), 0, ABS(E203-K203)/((ABS(E203)+ABS(K203))/2)) -> 0 | R411: =IF(AND(F203=0,L203=0), 0, ABS(F203-L203)/((ABS(F203)+ABS(L203))/2)) -> 0 | S411: =IF(AND(G203=0,M203=0), 0, ABS(G203-M203)/((ABS(G203)+ABS(M203))/2)) -> 2 | T411: =IF(AND(H203=0,N203=0), 0, ABS(H203-N203)/((ABS(H203)+ABS(N203))/2)) -> 0.00069359885 | U411: Total | V411: =IF(AND(C203=0,O203=0), 0, ABS(C203-O203)/((ABS(C203)+ABS(O203))/2)) -> 0 | W411: =IF(AND(D203=0,P203=0), 0, ABS(D203-P203)/((ABS(D203)+ABS(P203))/2)) -> 0 | X411: =IF(AND(E203=0,Q203=0), 0, ABS(E203-Q203)/((ABS(E203)+ABS(Q203))/2)) -> 0 | Y411: =IF(AND(F203=0,R203=0), 0, ABS(F203-R203)/((ABS(F203)+ABS(R203))/2)) -> 0 | Z411: =IF(AND(G203=0,S203=0), 0, ABS(G203-S203)/((ABS(G203)+ABS(S203))/2)) -> 0.0050632911 | AA411: =IF(AND(H203=0,T203=0), 0, ABS(H203-T203)/((ABS(H203)+ABS(T203))/2)) -> 7.7093572e-06 | AB411: Total
B412: Total | C412: =SUM(C212:C411)/200 -> 23.855 | D412: =SUM(D212:D411)/200 -> 675.23 | E412: =SUM(E212:E411)/200 -> 517.68 | F412: =SUM(F212:F411)/200 -> 10.265 | G412: =SUM(G212:G411)/200 -> 275.525 | H412: =SUM(H212:H411)/200 -> 155.895 | I412: =SUM(I212:I411)/200 -> 5.035 | J412: =SUM(J212:J411)/200 -> 36.28 | ... N412: =SUM(N212:N411)/200 -> 45.825 | O412: =SUM(O212:O411)/COUNT(O212:O411) -> 0.24712764 | P412: =SUM(P212:P411)/COUNT(P212:P411) -> 0.0251464 | Q412: =SUM(Q212:Q411)/COUNT(Q212:Q411) -> 0.8 | R412: =SUM(R212:R411)/COUNT(R212:R411) -> 0.0042992417 | S412: =SUM(S212:S411)/COUNT(S212:S411) -> 1.5457279 | T412: =SUM(T212:T411)/COUNT(T212:T411) -> 0.001201586 | U412: =SUM(O212:T411)/COUNT(O212:T411) -> 0.43725047 | V412: =SUM(V212:V411)/COUNT(V212:V411) -> 0.064928675 | W412: =SUM(W212:W411)/COUNT(W212:W411) -> 0.0013618198 | X412: =SUM(X212:X411)/COUNT(X212:X411) -> 0.001624265 | Y412: =SUM(Y212:Y411)/COUNT(Y212:Y411) -> 0.00035586724 | Z412: =SUM(Z212:Z411)/COUNT(Z212:Z411) -> 0.43986252 | AA412: =SUM(AA212:AA411)/COUNT(AA212:AA411) -> 0.00035330481 | AB412: =SUM(V212:AA411)/COUNT(V212:AA411) -> 0.084747742

Sheet Color classification
B1: image | C1: Pre-alignement | I1: Post-alignement
I2: Random correction | O2: Color classification
A3: 4_filled_cylinder/f_cyl_z/Col_class | C3: #c78637 | D3: #e3bb37 | E3: #e65a49 | F3: #e88d76 | G3: #f08a8c | H3: #ffffff | I3: #c78637 | J3: #e3bb37 | K3: #e65a49 | L3: #e88d76 | M3: #f08a8c | N3: #ffffff | O3: #c78637 | P3: #e3bb37 | Q3: #e65a49 | R3: #e88d76 | S3: #f08a8c | T3: #ffffff
B4: 0 | C4: 0 | D4: 30149 | E4: 0 | F4: 0 | G4: 0 | H4: 129851 | I4: 0 | J4: 30149 | K4: =0 -> 0 | L4: 0 | M4: 0 | N4: 129851 | O4: 0 | P4: 30149 | Q4: 0 | R4: 0 | S4: 0 | T4: 129851
B5: 1 | C5: 0 | D5: 30010 | E5: 0 | F5: 139 | G5: 0 | H5: 129851 | I5: 0 | J5: 30028 | K5: =0 -> 0 | L5: 0 | M5: 0 | N5: 129972 | O5: 0 | P5: 29921 | Q5: 0 | R5: 128 | S5: 144 | T5: 129807
B6: 2 | C6: 0 | D6: 30149 | E6: 0 | F6: 0 | G6: 0 | H6: 129851 | I6: 0 | J6: 30121 | K6: =0 -> 0 | L6: 0 | M6: 0 | N6: 129879 | O6: 0 | P6: 30032 | Q6: 0 | R6: 66 | S6: 97 | T6: 129805
B7: 3 | C7: 0 | D7: 30149 | E7: 0 | F7: 0 | G7: 0 | H7: 129851 | I7: 0 | J7: 30144 | K7: =0 -> 0 | L7: 0 | M7: 0 | N7: 129856 | O7: 0 | P7: 30025 | Q7: 0 | R7: 69 | S7: 105 | T7: 129801
B8: 4 | C8: 0 | D8: 30149 | E8: 0 | F8: 0 | G8: 0 | H8: 129851 | I8: 0 | J8: 30121 | K8: =0 -> 0 | L8: 0 | M8: 0 | N8: 129879 | O8: 0 | P8: 30149 | Q8: 0 | R8: 0 | S8: 0 | T8: 129851
B9: 5 | C9: 0 | D9: 29952 | E9: 0 | F9: 138 | G9: 117 | H9: 129793 | I9: 0 | J9: 29947 | K9: =0 -> 0 | L9: 6 | M9: 0 | N9: 130047 | O9: 0 | P9: 29952 | Q9: 0 | R9: 131 | S9: 124 | T9: 129793
B10: 6 | C10: 0 | D10: 29930 | E10: 0 | F10: 138 | G10: 160 | H10: 129772 | I10: 0 | J10: 30034 | K10: =0 -> 0 | L10: 0 | M10: 0 | N10: 129966 | O10: 0 | P10: 29785 | Q10: 0 | R10: 293 | S10: 204 | T10: 129718
B11: 7 | C11: 0 | D11: 29930 | E11: 0 | F11: 138 | G11: 160 | H11: 129772 | I11: 0 | J11: 30039 | K11: =0 -> 0 | L11: 0 | M11: 0 | N11: 129961 | O11: 0 | P11: 29823 | Q11: 0 | R11: 239 | S11: 165 | T11: 129773
B12: 8 | C12: 0 | D12: 30010 | E12: 0 | F12: 80 | G12: 117 | H12: 129793 | I12: 0 | J12: 30093 | K12: =0 -> 0 | L12: 0 | M12: 0 | N12: 129907 | O12: 0 | P12: 29961 | Q12: 0 | R12: 160 | S12: 91 | T12: 129788
B13: 9 | C13: 0 | D13: 30010 | E13: 0 | F13: 80 | G13: 117 | H13: 129793 | I13: 0 | J13: 30090 | K13: =0 -> 0 | L13: 0 | M13: 0 | N13: 129910 | O13: 0 | P13: 29979 | Q13: 0 | R13: 147 | S13: 84 | T13: 129790
B14: 10 | C14: 0 | D14: 30149 | E14: 0 | F14: 0 | G14: 0 | H14: 129851 | I14: 0 | J14: 30143 | K14: =0 -> 0 | L14: 0 | M14: 0 | N14: 129857 | O14: 0 | P14: 30032 | Q14: 0 | R14: 68 | S14: 96 | T14: 129804
B15: 11 | C15: 0 | D15: 29952 | E15: 0 | F15: 0 | G15: 394 | H15: 129654 | I15: 0 | J15: 30104 | K15: =0 -> 0 | L15: 0 | M15: 0 | N15: 129896 | O15: 0 | P15: 29853 | Q15: 0 | R15: 287 | S15: 212 | T15: 129648
... B203: 199 | C203: 0 | D203: 30090 | E203: 0 | F203: 59 | G203: 0 | H203: 129851 | I203: 0 | J203: 30088 | K203: =0 -> 0 | L203: 0 | M203: 0 | N203: 129912 | O203: 0 | P203: 30090 | Q203: 0 | R203: 59 | S203: 0 | T203: 129851
B204: Total | C204: =SUM(C4:C203) -> 252565 | D204: =SUM(D4:D203) -> 5378748 | E204: =SUM(E4:E203) -> 103622 | F204: =SUM(F4:F203) -> 249588 | G204: =SUM(G4:G203) -> 52788 | H204: =SUM(H4:H203) -> 25962689 | I204: =SUM(I4:I203) -> 250283 | J204: =SUM(J4:J203) -> 5496223 | ... T204: =SUM(T4:T203) -> 25959046
B209: image | C209: Absolute Error | O209: SMAPE
C210: Random correction | I210: Color classification | O210: Random correction | V210: Color classification
A211: 4_filled_cylinder/f_cyl_x/Col_clust | C211: #c78637 | D211: #e3bb37 | E211: #e65a49 | F211: #e88d76 | G211: #f08a8c | H211: #ffffff | I211: #c78637 | J211: #e3bb37 | K211: #e65a49 | L211: #e88d76 | M211: #f08a8c | N211: #ffffff | O211: #c78637 | P211: #e3bb37 | Q211: #e65a49 | R211: #e88d76 | S211: #f08a8c | T211: #ffffff | V211: #c78637 | W211: #e3bb37 | X211: #e65a49 | Y211: #e88d76 | Z211: #f08a8c | AA211: #ffffff
B212: 0 | C212: =ABS(I4-C4) -> 0 | D212: =ABS(J4-D4) -> 0 | E212: =ABS(K4-E4) -> 0 | F212: =ABS(L4-F4) -> 0 | G212: =ABS(M4-G4) -> 0 | H212: =ABS(N4-H4) -> 0 | I212: =ABS(O4-C4) -> 0 | J212: =ABS(P4-D4) -> 0 | K212: =ABS(Q4-E4) -> 0 | L212: =ABS(R4-F4) -> 0 | M212: =ABS(S4-G4) -> 0 | N212: =ABS(T4-H4) -> 0 | O212: =IF(AND(C4=0,I4=0), 0, ABS(C4-I4)/((ABS(C4)+ABS(I4))/2)) -> 0 | P212: =IF(AND(D4=0,J4=0), 0, ABS(D4-J4)/((ABS(D4)+ABS(J4))/2)) -> 0 | Q212: =IF(AND(E4=0,K4=0), 0, ABS(E4-K4)/((ABS(E4)+ABS(K4))/2)) -> 0 | R212: =IF(AND(F4=0,L4=0), 0, ABS(F4-L4)/((ABS(F4)+ABS(L4))/2)) -> 0 | S212: =IF(AND(G4=0,M4=0), 0, ABS(G4-M4)/((ABS(G4)+ABS(M4))/2)) -> 0 | T212: =IF(AND(H4=0,N4=0), 0, ABS(H4-N4)/((ABS(H4)+ABS(N4))/2)) -> 0 | V212: =IF(AND(C4=0,O4=0), 0, ABS(C4-O4)/((ABS(C4)+ABS(O4))/2)) -> 0 | W212: =IF(AND(D4=0,P4=0), 0, ABS(D4-P4)/((ABS(D4)+ABS(P4))/2)) -> 0 | X212: =IF(AND(E4=0,Q4=0), 0, ABS(E4-Q4)/((ABS(E4)+ABS(Q4))/2)) -> 0 | Y212: =IF(AND(F4=0,R4=0), 0, ABS(F4-R4)/((ABS(F4)+ABS(R4))/2)) -> 0 | Z212: =IF(AND(G4=0,S4=0), 0, ABS(G4-S4)/((ABS(G4)+ABS(S4))/2)) -> 0 | AA212: =IF(AND(H4=0,T4=0), 0, ABS(H4-T4)/((ABS(H4)+ABS(T4))/2)) -> 0
B213: 1 | C213: =ABS(I5-C5) -> 0 | D213: =ABS(J5-D5) -> 18 | E213: =ABS(K5-E5) -> 0 | F213: =ABS(L5-F5) -> 139 | G213: =ABS(M5-G5) -> 0 | H213: =ABS(N5-H5) -> 121 | I213: =ABS(O5-C5) -> 0 | J213: =ABS(P5-D5) -> 89 | K213: =ABS(Q5-E5) -> 0 | L213: =ABS(R5-F5) -> 11 | M213: =ABS(S5-G5) -> 144 | N213: =ABS(T5-H5) -> 44 | O213: =IF(AND(C5=0,I5=0), 0, ABS(C5-I5)/((ABS(C5)+ABS(I5))/2)) -> 0 | P213: =IF(AND(D5=0,J5=0), 0, ABS(D5-J5)/((ABS(D5)+ABS(J5))/2)) -> 0.00059962024 | Q213: =IF(AND(E5=0,K5=0), 0, ABS(E5-K5)/((ABS(E5)+ABS(K5))/2)) -> 0 | R213: =IF(AND(F5=0,L5=0), 0, ABS(F5-L5)/((ABS(F5)+ABS(L5))/2)) -> 2 | S213: =IF(AND(G5=0,M5=0), 0, ABS(G5-M5)/((ABS(G5)+ABS(M5))/2)) -> 0 | T213: =IF(AND(H5=0,N5=0), 0, ABS(H5-N5)/((ABS(H5)+ABS(N5))/2)) -> 0.0009314033 | V213: =IF(AND(C5=0,O5=0), 0, ABS(C5-O5)/((ABS(C5)+ABS(O5))/2)) -> 0 | W213: =IF(AND(D5=0,P5=0), 0, ABS(D5-P5)/((ABS(D5)+ABS(P5))/2)) -> 0.0029700823 | X213: =IF(AND(E5=0,Q5=0), 0, ABS(E5-Q5)/((ABS(E5)+ABS(Q5))/2)) -> 0 | Y213: =IF(AND(F5=0,R5=0), 0, ABS(F5-R5)/((ABS(F5)+ABS(R5))/2)) -> 0.082397004 | Z213: =IF(AND(G5=0,S5=0), 0, ABS(G5-S5)/((ABS(G5)+ABS(S5))/2)) -> 2 | AA213: =IF(AND(H5=0,T5=0), 0, ABS(H5-T5)/((ABS(H5)+ABS(T5))/2)) -> 0.00033890733
B214: 2 | C214: =ABS(I6-C6) -> 0 | D214: =ABS(J6-D6) -> 28 | E214: =ABS(K6-E6) -> 0 | F214: =ABS(L6-F6) -> 0 | G214: =ABS(M6-G6) -> 0 | H214: =ABS(N6-H6) -> 28 | I214: =ABS(O6-C6) -> 0 | J214: =ABS(P6-D6) -> 117 | K214: =ABS(Q6-E6) -> 0 | L214: =ABS(R6-F6) -> 66 | M214: =ABS(S6-G6) -> 97 | N214: =ABS(T6-H6) -> 46 | O214: =IF(AND(C6=0,I6=0), 0, ABS(C6-I6)/((ABS(C6)+ABS(I6))/2)) -> 0 | P214: =IF(AND(D6=0,J6=0), 0, ABS(D6-J6)/((ABS(D6)+ABS(J6))/2)) -> 0.00092915215 | Q214: =IF(AND(E6=0,K6=0), 0, ABS(E6-K6)/((ABS(E6)+ABS(K6))/2)) -> 0 | R214: =IF(AND(F6=0,L6=0), 0, ABS(F6-L6)/((ABS(F6)+ABS(L6))/2)) -> 0 | S214: =IF(AND(G6=0,M6=0), 0, ABS(G6-M6)/((ABS(G6)+ABS(M6))/2)) -> 0 | T214: =IF(AND(H6=0,N6=0), 0, ABS(H6-N6)/((ABS(H6)+ABS(N6))/2)) -> 0.00021560852 | V214: =IF(AND(C6=0,O6=0), 0, ABS(C6-O6)/((ABS(C6)+ABS(O6))/2)) -> 0 | W214: =IF(AND(D6=0,P6=0), 0, ABS(D6-P6)/((ABS(D6)+ABS(P6))/2)) -> 0.0038882704 | X214: =IF(AND(E6=0,Q6=0), 0, ABS(E6-Q6)/((ABS(E6)+ABS(Q6))/2)) -> 0 | Y214: =IF(AND(F6=0,R6=0), 0, ABS(F6-R6)/((ABS(F6)+ABS(R6))/2)) -> 2 | Z214: =IF(AND(G6=0,S6=0), 0, ABS(G6-S6)/((ABS(G6)+ABS(S6))/2)) -> 2 | AA214: =IF(AND(H6=0,T6=0), 0, ABS(H6-T6)/((ABS(H6)+ABS(T6))/2)) -> 0.00035431494
B215: 3 | C215: =ABS(I7-C7) -> 0 | D215: =ABS(J7-D7) -> 5 | E215: =ABS(K7-E7) -> 0 | F215: =ABS(L7-F7) -> 0 | G215: =ABS(M7-G7) -> 0 | H215: =ABS(N7-H7) -> 5 | I215: =ABS(O7-C7) -> 0 | J215: =ABS(P7-D7) -> 124 | K215: =ABS(Q7-E7) -> 0 | L215: =ABS(R7-F7) -> 69 | M215: =ABS(S7-G7) -> 105 | N215: =ABS(T7-H7) -> 50 | O215: =IF(AND(C7=0,I7=0), 0, ABS(C7-I7)/((ABS(C7)+ABS(I7))/2)) -> 0 | P215: =IF(AND(D7=0,J7=0), 0, ABS(D7-J7)/((ABS(D7)+ABS(J7))/2)) -> 0.00016585673 | Q215: =IF(AND(E7=0,K7=0), 0, ABS(E7-K7)/((ABS(E7)+ABS(K7))/2)) -> 0 | R215: =IF(AND(F7=0,L7=0), 0, ABS(F7-L7)/((ABS(F7)+ABS(L7))/2)) -> 0 | S215: =IF(AND(G7=0,M7=0), 0, ABS(G7-M7)/((ABS(G7)+ABS(M7))/2)) -> 0 | T215: =IF(AND(H7=0,N7=0), 0, ABS(H7-N7)/((ABS(H7)+ABS(N7))/2)) -> 3.8504931e-05 | V215: =IF(AND(C7=0,O7=0), 0, ABS(C7-O7)/((ABS(C7)+ABS(O7))/2)) -> 0 | W215: =IF(AND(D7=0,P7=0), 0, ABS(D7-P7)/((ABS(D7)+ABS(P7))/2)) -> 0.0041213813 | X215: =IF(AND(E7=0,Q7=0), 0, ABS(E7-Q7)/((ABS(E7)+ABS(Q7))/2)) -> 0 | Y215: =IF(AND(F7=0,R7=0), 0, ABS(F7-R7)/((ABS(F7)+ABS(R7))/2)) -> 2 | Z215: =IF(AND(G7=0,S7=0), 0, ABS(G7-S7)/((ABS(G7)+ABS(S7))/2)) -> 2 | AA215: =IF(AND(H7=0,T7=0), 0, ABS(H7-T7)/((ABS(H7)+ABS(T7))/2)) -> 0.00038513087
B216: 4 | C216: =ABS(I8-C8) -> 0 | D216: =ABS(J8-D8) -> 28 | E216: =ABS(K8-E8) -> 0 | F216: =ABS(L8-F8) -> 0 | G216: =ABS(M8-G8) -> 0 | H216: =ABS(N8-H8) -> 28 | I216: =ABS(O8-C8) -> 0 | J216: =ABS(P8-D8) -> 0 | K216: =ABS(Q8-E8) -> 0 | L216: =ABS(R8-F8) -> 0 | M216: =ABS(S8-G8) -> 0 | N216: =ABS(T8-H8) -> 0 | O216: =IF(AND(C8=0,I8=0), 0, ABS(C8-I8)/((ABS(C8)+ABS(I8))/2)) -> 0 | P216: =IF(AND(D8=0,J8=0), 0, ABS(D8-J8)/((ABS(D8)+ABS(J8))/2)) -> 0.00092915215 | Q216: =IF(AND(E8=0,K8=0), 0, ABS(E8-K8)/((ABS(E8)+ABS(K8))/2)) -> 0 | R216: =IF(AND(F8=0,L8=0), 0, ABS(F8-L8)/((ABS(F8)+ABS(L8))/2)) -> 0 | S216: =IF(AND(G8=0,M8=0), 0, ABS(G8-M8)/((ABS(G8)+ABS(M8))/2)) -> 0 | T216: =IF(AND(H8=0,N8=0), 0, ABS(H8-N8)/((ABS(H8)+ABS(N8))/2)) -> 0.00021560852 | V216: =IF(AND(C8=0,O8=0), 0, ABS(C8-O8)/((ABS(C8)+ABS(O8))/2)) -> 0 | W216: =IF(AND(D8=0,P8=0), 0, ABS(D8-P8)/((ABS(D8)+ABS(P8))/2)) -> 0 | X216: =IF(AND(E8=0,Q8=0), 0, ABS(E8-Q8)/((ABS(E8)+ABS(Q8))/2)) -> 0 | Y216: =IF(AND(F8=0,R8=0), 0, ABS(F8-R8)/((ABS(F8)+ABS(R8))/2)) -> 0 | Z216: =IF(AND(G8=0,S8=0), 0, ABS(G8-S8)/((ABS(G8)+ABS(S8))/2)) -> 0 | AA216: =IF(AND(H8=0,T8=0), 0, ABS(H8-T8)/((ABS(H8)+ABS(T8))/2)) -> 0
B217: 5 | C217: =ABS(I9-C9) -> 0 | D217: =ABS(J9-D9) -> 5 | E217: =ABS(K9-E9) -> 0 | F217: =ABS(L9-F9) -> 132 | G217: =ABS(M9-G9) -> 117 | H217: =ABS(N9-H9) -> 254 | I217: =ABS(O9-C9) -> 0 | J217: =ABS(P9-D9) -> 0 | K217: =ABS(Q9-E9) -> 0 | L217: =ABS(R9-F9) -> 7 | M217: =ABS(S9-G9) -> 7 | N217: =ABS(T9-H9) -> 0 | O217: =IF(AND(C9=0,I9=0), 0, ABS(C9-I9)/((ABS(C9)+ABS(I9))/2)) -> 0 | P217: =IF(AND(D9=0,J9=0), 0, ABS(D9-J9)/((ABS(D9)+ABS(J9))/2)) -> 0.0001669477 | Q217: =IF(AND(E9=0,K9=0), 0, ABS(E9-K9)/((ABS(E9)+ABS(K9))/2)) -> 0 | R217: =IF(AND(F9=0,L9=0), 0, ABS(F9-L9)/((ABS(F9)+ABS(L9))/2)) -> 1.8333333 | S217: =IF(AND(G9=0,M9=0), 0, ABS(G9-M9)/((ABS(G9)+ABS(M9))/2)) -> 2 | T217: =IF(AND(H9=0,N9=0), 0, ABS(H9-N9)/((ABS(H9)+ABS(N9))/2)) -> 0.0019550493 | V217: =IF(AND(C9=0,O9=0), 0, ABS(C9-O9)/((ABS(C9)+ABS(O9))/2)) -> 0 | W217: =IF(AND(D9=0,P9=0), 0, ABS(D9-P9)/((ABS(D9)+ABS(P9))/2)) -> 0 | X217: =IF(AND(E9=0,Q9=0), 0, ABS(E9-Q9)/((ABS(E9)+ABS(Q9))/2)) -> 0 | Y217: =IF(AND(F9=0,R9=0), 0, ABS(F9-R9)/((ABS(F9)+ABS(R9))/2)) -> 0.05204461 | Z217: =IF(AND(G9=0,S9=0), 0, ABS(G9-S9)/((ABS(G9)+ABS(S9))/2)) -> 0.058091286 | AA217: =IF(AND(H9=0,T9=0), 0, ABS(H9-T9)/((ABS(H9)+ABS(T9))/2)) -> 0
B218: 6 | C218: =ABS(I10-C10) -> 0 | D218: =ABS(J10-D10) -> 104 | E218: =ABS(K10-E10) -> 0 | F218: =ABS(L10-F10) -> 138 | G218: =ABS(M10-G10) -> 160 | H218: =ABS(N10-H10) -> 194 | I218: =ABS(O10-C10) -> 0 | J218: =ABS(P10-D10) -> 145 | K218: =ABS(Q10-E10) -> 0 | L218: =ABS(R10-F10) -> 155 | M218: =ABS(S10-G10) -> 44 | N218: =ABS(T10-H10) -> 54 | O218: =IF(AND(C10=0,I10=0), 0, ABS(C10-I10)/((ABS(C10)+ABS(I10))/2)) -> 0 | P218: =IF(AND(D10=0,J10=0), 0, ABS(D10-J10)/((ABS(D10)+ABS(J10))/2)) -> 0.0034687479 | Q218: =IF(AND(E10=0,K10=0), 0, ABS(E10-K10)/((ABS(E10)+ABS(K10))/2)) -> 0 | R218: =IF(AND(F10=0,L10=0), 0, ABS(F10-L10)/((ABS(F10)+ABS(L10))/2)) -> 2 | S218: =IF(AND(G10=0,M10=0), 0, ABS(G10-M10)/((ABS(G10)+ABS(M10))/2)) -> 2 | T218: =IF(AND(H10=0,N10=0), 0, ABS(H10-N10)/((ABS(H10)+ABS(N10))/2)) -> 0.001493813 | V218: =IF(AND(C10=0,O10=0), 0, ABS(C10-O10)/((ABS(C10)+ABS(O10))/2)) -> 0 | W218: =IF(AND(D10=0,P10=0), 0, ABS(D10-P10)/((ABS(D10)+ABS(P10))/2)) -> 0.0048564012 | X218: =IF(AND(E10=0,Q10=0), 0, ABS(E10-Q10)/((ABS(E10)+ABS(Q10))/2)) -> 0 | Y218: =IF(AND(F10=0,R10=0), 0, ABS(F10-R10)/((ABS(F10)+ABS(R10))/2)) -> 0.71925754 | Z218: =IF(AND(G10=0,S10=0), 0, ABS(G10-S10)/((ABS(G10)+ABS(S10))/2)) -> 0.24175824 | AA218: =IF(AND(H10=0,T10=0), 0, ABS(H10-T10)/((ABS(H10)+ABS(T10))/2)) -> 0.00041620101
B219: 7 | C219: =ABS(I11-C11) -> 0 | D219: =ABS(J11-D11) -> 109 | E219: =ABS(K11-E11) -> 0 | F219: =ABS(L11-F11) -> 138 | G219: =ABS(M11-G11) -> 160 | H219: =ABS(N11-H11) -> 189 | I219: =ABS(O11-C11) -> 0 | J219: =ABS(P11-D11) -> 107 | K219: =ABS(Q11-E11) -> 0 | L219: =ABS(R11-F11) -> 101 | M219: =ABS(S11-G11) -> 5 | N219: =ABS(T11-H11) -> 1 | O219: =IF(AND(C11=0,I11=0), 0, ABS(C11-I11)/((ABS(C11)+ABS(I11))/2)) -> 0 | P219: =IF(AND(D11=0,J11=0), 0, ABS(D11-J11)/((ABS(D11)+ABS(J11))/2)) -> 0.0036352115 | Q219: =IF(AND(E11=0,K11=0), 0, ABS(E11-K11)/((ABS(E11)+ABS(K11))/2)) -> 0 | R219: =IF(AND(F11=0,L11=0), 0, ABS(F11-L11)/((ABS(F11)+ABS(L11))/2)) -> 2 | S219: =IF(AND(G11=0,M11=0), 0, ABS(G11-M11)/((ABS(G11)+ABS(M11))/2)) -> 2 | T219: =IF(AND(H11=0,N11=0), 0, ABS(H11-N11)/((ABS(H11)+ABS(N11))/2)) -> 0.0014553407 | V219: =IF(AND(C11=0,O11=0), 0, ABS(C11-O11)/((ABS(C11)+ABS(O11))/2)) -> 0 | W219: =IF(AND(D11=0,P11=0), 0, ABS(D11-P11)/((ABS(D11)+ABS(P11))/2)) -> 0.0035814101 | X219: =IF(AND(E11=0,Q11=0), 0, ABS(E11-Q11)/((ABS(E11)+ABS(Q11))/2)) -> 0 | Y219: =IF(AND(F11=0,R11=0), 0, ABS(F11-R11)/((ABS(F11)+ABS(R11))/2)) -> 0.53580902 | Z219: =IF(AND(G11=0,S11=0), 0, ABS(G11-S11)/((ABS(G11)+ABS(S11))/2)) -> 0.030769231 | AA219: =IF(AND(H11=0,T11=0), 0, ABS(H11-T11)/((ABS(H11)+ABS(T11))/2)) -> 7.7057928e-06
B220: 8 | C220: =ABS(I12-C12) -> 0 | D220: =ABS(J12-D12) -> 83 | E220: =ABS(K12-E12) -> 0 | F220: =ABS(L12-F12) -> 80 | G220: =ABS(M12-G12) -> 117 | H220: =ABS(N12-H12) -> 114 | I220: =ABS(O12-C12) -> 0 | J220: =ABS(P12-D12) -> 49 | K220: =ABS(Q12-E12) -> 0 | L220: =ABS(R12-F12) -> 80 | M220: =ABS(S12-G12) -> 26 | N220: =ABS(T12-H12) -> 5 | O220: =IF(AND(C12=0,I12=0), 0, ABS(C12-I12)/((ABS(C12)+ABS(I12))/2)) -> 0 | P220: =IF(AND(D12=0,J12=0), 0, ABS(D12-J12)/((ABS(D12)+ABS(J12))/2)) -> 0.0027619254 | Q220: =IF(AND(E12=0,K12=0), 0, ABS(E12-K12)/((ABS(E12)+ABS(K12))/2)) -> 0 | R220: =IF(AND(F12=0,L12=0), 0, ABS(F12-L12)/((ABS(F12)+ABS(L12))/2)) -> 2 | S220: =IF(AND(G12=0,M12=0), 0, ABS(G12-M12)/((ABS(G12)+ABS(M12))/2)) -> 2 | T220: =IF(AND(H12=0,N12=0), 0, ABS(H12-N12)/((ABS(H12)+ABS(N12))/2)) -> 0.00087793608 | V220: =IF(AND(C12=0,O12=0), 0, ABS(C12-O12)/((ABS(C12)+ABS(O12))/2)) -> 0 | W220: =IF(AND(D12=0,P12=0), 0, ABS(D12-P12)/((ABS(D12)+ABS(P12))/2)) -> 0.0016341232 | X220: =IF(AND(E12=0,Q12=0), 0, ABS(E12-Q12)/((ABS(E12)+ABS(Q12))/2)) -> 0 | Y220: =IF(AND(F12=0,R12=0), 0, ABS(F12-R12)/((ABS(F12)+ABS(R12))/2)) -> 0.66666667 | Z220: =IF(AND(G12=0,S12=0), 0, ABS(G12-S12)/((ABS(G12)+ABS(S12))/2)) -> 0.25 | AA220: =IF(AND(H12=0,T12=0), 0, ABS(H12-T12)/((ABS(H12)+ABS(T12))/2)) -> 3.8523621e-05
B221: 9 | C221: =ABS(I13-C13) -> 0 | D221: =ABS(J13-D13) -> 80 | E221: =ABS(K13-E13) -> 0 | F221: =ABS(L13-F13) -> 80 | G221: =ABS(M13-G13) -> 117 | H221: =ABS(N13-H13) -> 117 | I221: =ABS(O13-C13) -> 0 | J221: =ABS(P13-D13) -> 31 | K221: =ABS(Q13-E13) -> 0 | L221: =ABS(R13-F13) -> 67 | M221: =ABS(S13-G13) -> 33 | N221: =ABS(T13-H13) -> 3 | O221: =IF(AND(C13=0,I13=0), 0, ABS(C13-I13)/((ABS(C13)+ABS(I13))/2)) -> 0 | P221: =IF(AND(D13=0,J13=0), 0, ABS(D13-J13)/((ABS(D13)+ABS(J13))/2)) -> 0.0026622296 | Q221: =IF(AND(E13=0,K13=0), 0, ABS(E13-K13)/((ABS(E13)+ABS(K13))/2)) -> 0 | R221: =IF(AND(F13=0,L13=0), 0, ABS(F13-L13)/((ABS(F13)+ABS(L13))/2)) -> 2 | S221: =IF(AND(G13=0,M13=0), 0, ABS(G13-M13)/((ABS(G13)+ABS(M13))/2)) -> 2 | T221: =IF(AND(H13=0,N13=0), 0, ABS(H13-N13)/((ABS(H13)+ABS(N13))/2)) -> 0.00090102925 | V221: =IF(AND(C13=0,O13=0), 0, ABS(C13-O13)/((ABS(C13)+ABS(O13))/2)) -> 0 | W221: =IF(AND(D13=0,P13=0), 0, ABS(D13-P13)/((ABS(D13)+ABS(P13))/2)) -> 0.0010335228 | X221: =IF(AND(E13=0,Q13=0), 0, ABS(E13-Q13)/((ABS(E13)+ABS(Q13))/2)) -> 0 | Y221: =IF(AND(F13=0,R13=0), 0, ABS(F13-R13)/((ABS(F13)+ABS(R13))/2)) -> 0.59030837 | Z221: =IF(AND(G13=0,S13=0), 0, ABS(G13-S13)/((ABS(G13)+ABS(S13))/2)) -> 0.32835821 | AA221: =IF(AND(H13=0,T13=0), 0, ABS(H13-T13)/((ABS(H13)+ABS(T13))/2)) -> 2.3113994e-05
B222: 10 | C222: =ABS(I14-C14) -> 0 | D222: =ABS(J14-D14) -> 6 | E222: =ABS(K14-E14) -> 0 | F222: =ABS(L14-F14) -> 0 | G222: =ABS(M14-G14) -> 0 | H222: =ABS(N14-H14) -> 6 | I222: =ABS(O14-C14) -> 0 | J222: =ABS(P14-D14) -> 117 | K222: =ABS(Q14-E14) -> 0 | L222: =ABS(R14-F14) -> 68 | M222: =ABS(S14-G14) -> 96 | N222: =ABS(T14-H14) -> 47 | O222: =IF(AND(C14=0,I14=0), 0, ABS(C14-I14)/((ABS(C14)+ABS(I14))/2)) -> 0 | P222: =IF(AND(D14=0,J14=0), 0, ABS(D14-J14)/((ABS(D14)+ABS(J14))/2)) -> 0.00019903138 | Q222: =IF(AND(E14=0,K14=0), 0, ABS(E14-K14)/((ABS(E14)+ABS(K14))/2)) -> 0 | R222: =IF(AND(F14=0,L14=0), 0, ABS(F14-L14)/((ABS(F14)+ABS(L14))/2)) -> 0 | S222: =IF(AND(G14=0,M14=0), 0, ABS(G14-M14)/((ABS(G14)+ABS(M14))/2)) -> 0 | T222: =IF(AND(H14=0,N14=0), 0, ABS(H14-N14)/((ABS(H14)+ABS(N14))/2)) -> 4.6205739e-05 | V222: =IF(AND(C14=0,O14=0), 0, ABS(C14-O14)/((ABS(C14)+ABS(O14))/2)) -> 0 | W222: =IF(AND(D14=0,P14=0), 0, ABS(D14-P14)/((ABS(D14)+ABS(P14))/2)) -> 0.0038882704 | X222: =IF(AND(E14=0,Q14=0), 0, ABS(E14-Q14)/((ABS(E14)+ABS(Q14))/2)) -> 0 | Y222: =IF(AND(F14=0,R14=0), 0, ABS(F14-R14)/((ABS(F14)+ABS(R14))/2)) -> 2 | Z222: =IF(AND(G14=0,S14=0), 0, ABS(G14-S14)/((ABS(G14)+ABS(S14))/2)) -> 2 | AA222: =IF(AND(H14=0,T14=0), 0, ABS(H14-T14)/((ABS(H14)+ABS(T14))/2)) -> 0.00036201883
B223: 11 | C223: =ABS(I15-C15) -> 0 | D223: =ABS(J15-D15) -> 152 | E223: =ABS(K15-E15) -> 0 | F223: =ABS(L15-F15) -> 0 | G223: =ABS(M15-G15) -> 394 | H223: =ABS(N15-H15) -> 242 | I223: =ABS(O15-C15) -> 0 | J223: =ABS(P15-D15) -> 99 | K223: =ABS(Q15-E15) -> 0 | L223: =ABS(R15-F15) -> 287 | M223: =ABS(S15-G15) -> 182 | N223: =ABS(T15-H15) -> 6 | O223: =IF(AND(C15=0,I15=0), 0, ABS(C15-I15)/((ABS(C15)+ABS(I15))/2)) -> 0 | P223: =IF(AND(D15=0,J15=0), 0, ABS(D15-J15)/((ABS(D15)+ABS(J15))/2)) -> 0.0050619422 | Q223: =IF(AND(E15=0,K15=0), 0, ABS(E15-K15)/((ABS(E15)+ABS(K15))/2)) -> 0 | R223: =IF(AND(F15=0,L15=0), 0, ABS(F15-L15)/((ABS(F15)+ABS(L15))/2)) -> 0 | S223: =IF(AND(G15=0,M15=0), 0, ABS(G15-M15)/((ABS(G15)+ABS(M15))/2)) -> 2 | T223: =IF(AND(H15=0,N15=0), 0, ABS(H15-N15)/((ABS(H15)+ABS(N15))/2)) -> 0.0018647659 | V223: =IF(AND(C15=0,O15=0), 0, ABS(C15-O15)/((ABS(C15)+ABS(O15))/2)) -> 0 | W223: =IF(AND(D15=0,P15=0), 0, ABS(D15-P15)/((ABS(D15)+ABS(P15))/2)) -> 0.00331076 | X223: =IF(AND(E15=0,Q15=0), 0, ABS(E15-Q15)/((ABS(E15)+ABS(Q15))/2)) -> 0 | Y223: =IF(AND(F15=0,R15=0), 0, ABS(F15-R15)/((ABS(F15)+ABS(R15))/2)) -> 2 | Z223: =IF(AND(G15=0,S15=0), 0, ABS(G15-S15)/((ABS(G15)+ABS(S15))/2)) -> 0.60066007 | AA223: =IF(AND(H15=0,T15=0), 0, ABS(H15-T15)/((ABS(H15)+ABS(T15))/2)) -> 4.6278085e-05
... B410: 198 | C410: =ABS(I202-C202) -> 0 | D410: =ABS(J202-D202) -> 4 | E410: =ABS(K202-E202) -> 0 | F410: =ABS(L202-F202) -> 0 | G410: =ABS(M202-G202) -> 0 | H410: =ABS(N202-H202) -> 4 | I410: =ABS(O202-C202) -> 0 | J410: =ABS(P202-D202) -> 0 | K410: =ABS(Q202-E202) -> 0 | L410: =ABS(R202-F202) -> 0 | M410: =ABS(S202-G202) -> 0 | N410: =ABS(T202-H202) -> 0 | O410: =IF(AND(C202=0,I202=0), 0, ABS(C202-I202)/((ABS(C202)+ABS(I202))/2)) -> 0 | P410: =IF(AND(D202=0,J202=0), 0, ABS(D202-J202)/((ABS(D202)+ABS(J202))/2)) -> 0.00013266558 | Q410: =IF(AND(E202=0,K202=0), 0, ABS(E202-K202)/((ABS(E202)+ABS(K202))/2)) -> 0 | R410: =IF(AND(F202=0,L202=0), 0, ABS(F202-L202)/((ABS(F202)+ABS(L202))/2)) -> 0 | S410: =IF(AND(G202=0,M202=0), 0, ABS(G202-M202)/((ABS(G202)+ABS(M202))/2)) -> 0 | T410: =IF(AND(H202=0,N202=0), 0, ABS(H202-N202)/((ABS(H202)+ABS(N202))/2)) -> 3.0805012e-05 | V410: =IF(AND(C202=0,O202=0), 0, ABS(C202-O202)/((ABS(C202)+ABS(O202))/2)) -> 0 | W410: =IF(AND(D202=0,P202=0), 0, ABS(D202-P202)/((ABS(D202)+ABS(P202))/2)) -> 0 | X410: =IF(AND(E202=0,Q202=0), 0, ABS(E202-Q202)/((ABS(E202)+ABS(Q202))/2)) -> 0 | Y410: =IF(AND(F202=0,R202=0), 0, ABS(F202-R202)/((ABS(F202)+ABS(R202))/2)) -> 0 | Z410: =IF(AND(G202=0,S202=0), 0, ABS(G202-S202)/((ABS(G202)+ABS(S202))/2)) -> 0 | AA410: =IF(AND(H202=0,T202=0), 0, ABS(H202-T202)/((ABS(H202)+ABS(T202))/2)) -> 0
B411: 199 | C411: =ABS(I203-C203) -> 0 | D411: =ABS(J203-D203) -> 2 | E411: =ABS(K203-E203) -> 0 | F411: =ABS(L203-F203) -> 59 | G411: =ABS(M203-G203) -> 0 | H411: =ABS(N203-H203) -> 61 | I411: =ABS(O203-C203) -> 0 | J411: =ABS(P203-D203) -> 0 | K411: =ABS(Q203-E203) -> 0 | L411: =ABS(R203-F203) -> 0 | M411: =ABS(S203-G203) -> 0 | N411: =ABS(T203-H203) -> 0 | O411: =IF(AND(C203=0,I203=0), 0, ABS(C203-I203)/((ABS(C203)+ABS(I203))/2)) -> 0 | P411: =IF(AND(D203=0,J203=0), 0, ABS(D203-J203)/((ABS(D203)+ABS(J203))/2)) -> 6.6469474e-05 | Q411: =IF(AND(E203=0,K203=0), 0, ABS(E203-K203)/((ABS(E203)+ABS(K203))/2)) -> 0 | R411: =IF(AND(F203=0,L203=0), 0, ABS(F203-L203)/((ABS(F203)+ABS(L203))/2)) -> 2 | S411: =IF(AND(G203=0,M203=0), 0, ABS(G203-M203)/((ABS(G203)+ABS(M203))/2)) -> 0 | T411: =IF(AND(H203=0,N203=0), 0, ABS(H203-N203)/((ABS(H203)+ABS(N203))/2)) -> 0.00046965888 | U411: Total | V411: =IF(AND(C203=0,O203=0), 0, ABS(C203-O203)/((ABS(C203)+ABS(O203))/2)) -> 0 | W411: =IF(AND(D203=0,P203=0), 0, ABS(D203-P203)/((ABS(D203)+ABS(P203))/2)) -> 0 | X411: =IF(AND(E203=0,Q203=0), 0, ABS(E203-Q203)/((ABS(E203)+ABS(Q203))/2)) -> 0 | Y411: =IF(AND(F203=0,R203=0), 0, ABS(F203-R203)/((ABS(F203)+ABS(R203))/2)) -> 0 | Z411: =IF(AND(G203=0,S203=0), 0, ABS(G203-S203)/((ABS(G203)+ABS(S203))/2)) -> 0 | AA411: =IF(AND(H203=0,T203=0), 0, ABS(H203-T203)/((ABS(H203)+ABS(T203))/2)) -> 0 | AB411: Total
B412: Total | C412: =SUM(C212:C411)/200 -> 24.31 | D412: =SUM(D212:D411)/200 -> 597.835 | E412: =SUM(E212:E411)/200 -> 518.11 | F412: =SUM(F212:F411)/200 -> 76.43 | G412: =SUM(G212:G411)/200 -> 76.36 | H412: =SUM(H212:H411)/200 -> 93.505 | I412: =SUM(I212:I411)/200 -> 2.575 | J412: =SUM(J212:J411)/200 -> 59 | ... N412: =SUM(N212:N411)/200 -> 18.225 | O412: =SUM(O212:O411)/COUNT(O212:O411) -> 0.24334859 | P412: =SUM(P212:P411)/COUNT(P212:P411) -> 0.022264887 | Q412: =SUM(Q212:Q411)/COUNT(Q212:Q411) -> 0.8 | R412: =SUM(R212:R411)/COUNT(R212:R411) -> 0.55771868 | S412: =SUM(S212:S411)/COUNT(S212:S411) -> 0.89676421 | T412: =SUM(T212:T411)/COUNT(T212:T411) -> 0.00072004784 | U412: =SUM(O212:T411)/COUNT(O212:T411) -> 0.42013607 | V412: =SUM(V212:V411)/COUNT(V212:V411) -> 0.0060096813 | W412: =SUM(W212:W411)/COUNT(W212:W411) -> 0.002269104 | X412: =SUM(X212:X411)/COUNT(X212:X411) -> 0.00077029582 | Y412: =SUM(Y212:Y411)/COUNT(Y212:Y411) -> 0.39791728 | Z412: =SUM(Z212:Z411)/COUNT(Z212:Z411) -> 0.657899 | AA412: =SUM(AA212:AA411)/COUNT(AA212:AA411) -> 0.00014041214 | AB412: =SUM(V212:AA411)/COUNT(V212:AA411) -> 0.17750096

Sheet Comparison with original
B1: image | C1: Original | I1: Clustering | U1: Classification
I2: Random correction | O2: Color classification | U2: Random correction | AA2: Color classification
A3: 4_filled_cylinder/f_cyl_z | C3: #c78637 | D3: #e3bb37 | E3: #e65a49 | F3: #e88d76 | G3: #f08a8c | H3: #ffffff | I3: #c88637 | J3: #e3bb37 | K3: #e65a49 | L3: #e98d78 | M3: #f1de9e | N3: #ffffff | O3: #c88637 | P3: #e3bb37 | Q3: #e65a49 | R3: #e98d78 | S3: #f1de9e | T3: #ffffff | U3: #c78637 | V3: #e3bb37 | W3: #e65a49 | X3: #e88d76 | Y3: #f08a8c | Z3: #ffffff | AA3: #c78637 | AB3: #e3bb37 | AC3: #e65a49 | AD3: #e88d76 | AE3: #f08a8c | AF3: #ffffff
B4: 0 | C4: 0 | D4: 30149 | E4: 0 | F4: 0 | G4: 0 | H4: 129851 | I4: ='Color clustering'!I4 -> 0 | J4: ='Color clustering'!J4 -> 30149 | K4: ='Color clustering'!K4 -> 0 | L4: ='Color clustering'!L4 -> 0 | M4: ='Color clustering'!M4 -> 0 | N4: ='Color clustering'!N4 -> 129851 | O4: ='Color clustering'!O4 -> 0 | P4: ='Color clustering'!P4 -> 30149 | ... T4: ='Color clustering'!T4 -> 129851 | U4: ='Color classification'!I4 -> 0 | V4: ='Color classification'!J4 -> 30149 | W4: ='Color classification'!K4 -> 0 | X4: ='Color classification'!L4 -> 0 | Y4: ='Color classification'!M4 -> 0 | Z4: ='Color classification'!N4 -> 129851 | AA4: ='Color classification'!O4 -> 0 | AB4: ='Color classification'!P4 -> 30149 | ... AF4: ='Color classification'!T4 -> 129851
B5: 1 | C5: 0 | D5: 30149 | E5: 0 | F5: 0 | G5: 0 | H5: 129851 | I5: ='Color clustering'!I5 -> 0 | J5: ='Color clustering'!J5 -> 30152 | K5: ='Color clustering'!K5 -> 0 | L5: ='Color clustering'!L5 -> 0 | M5: ='Color clustering'!M5 -> 22 | N5: ='Color clustering'!N5 -> 129826 | O5: ='Color clustering'!O5 -> 0 | P5: ='Color clustering'!P5 -> 29912 | ... T5: ='Color clustering'!T5 -> 129606 | U5: ='Color classification'!I5 -> 0 | V5: ='Color classification'!J5 -> 30028 | W5: ='Color classification'!K5 -> 0 | X5: ='Color classification'!L5 -> 0 | Y5: ='Color classification'!M5 -> 0 | Z5: ='Color classification'!N5 -> 129972 | AA5: ='Color classification'!O5 -> 0 | AB5: ='Color classification'!P5 -> 29921 | ... AF5: ='Color classification'!T5 -> 129807
B6: 2 | C6: 0 | D6: 30149 | E6: 0 | F6: 0 | G6: 0 | H6: 129851 | I6: ='Color clustering'!I6 -> 0 | J6: ='Color clustering'!J6 -> 30112 | K6: ='Color clustering'!K6 -> 0 | L6: ='Color clustering'!L6 -> 0 | M6: ='Color clustering'!M6 -> 6 | N6: ='Color clustering'!N6 -> 129882 | O6: ='Color clustering'!O6 -> 0 | P6: ='Color clustering'!P6 -> 29989 | ... T6: ='Color clustering'!T6 -> 129673 | U6: ='Color classification'!I6 -> 0 | V6: ='Color classification'!J6 -> 30121 | W6: ='Color classification'!K6 -> 0 | X6: ='Color classification'!L6 -> 0 | Y6: ='Color classification'!M6 -> 0 | Z6: ='Color classification'!N6 -> 129879 | AA6: ='Color classification'!O6 -> 0 | AB6: ='Color classification'!P6 -> 30032 | ... AF6: ='Color classification'!T6 -> 129805
B7: 3 | C7: 0 | D7: 30149 | E7: 0 | F7: 0 | G7: 0 | H7: 129851 | I7: ='Color clustering'!I7 -> 0 | J7: ='Color clustering'!J7 -> 30102 | K7: ='Color clustering'!K7 -> 0 | L7: ='Color clustering'!L7 -> 0 | M7: ='Color clustering'!M7 -> 10 | N7: ='Color clustering'!N7 -> 129888 | O7: ='Color clustering'!O7 -> 0 | P7: ='Color clustering'!P7 -> 29991 | ... T7: ='Color clustering'!T7 -> 129678 | U7: ='Color classification'!I7 -> 0 | V7: ='Color classification'!J7 -> 30144 | W7: ='Color classification'!K7 -> 0 | X7: ='Color classification'!L7 -> 0 | Y7: ='Color classification'!M7 -> 0 | Z7: ='Color classification'!N7 -> 129856 | AA7: ='Color classification'!O7 -> 0 | AB7: ='Color classification'!P7 -> 30025 | ... AF7: ='Color classification'!T7 -> 129801
B8: 4 | C8: 0 | D8: 30149 | E8: 0 | F8: 0 | G8: 0 | H8: 129851 | I8: ='Color clustering'!I8 -> 0 | J8: ='Color clustering'!J8 -> 30175 | K8: ='Color clustering'!K8 -> 0 | L8: ='Color clustering'!L8 -> 0 | M8: ='Color clustering'!M8 -> 0 | N8: ='Color clustering'!N8 -> 129825 | O8: ='Color clustering'!O8 -> 0 | P8: ='Color clustering'!P8 -> 30149 | ... T8: ='Color clustering'!T8 -> 129851 | U8: ='Color classification'!I8 -> 0 | V8: ='Color classification'!J8 -> 30121 | W8: ='Color classification'!K8 -> 0 | X8: ='Color classification'!L8 -> 0 | Y8: ='Color classification'!M8 -> 0 | Z8: ='Color classification'!N8 -> 129879 | AA8: ='Color classification'!O8 -> 0 | AB8: ='Color classification'!P8 -> 30149 | ... AF8: ='Color classification'!T8 -> 129851
B9: 5 | C9: 0 | D9: 30149 | E9: 0 | F9: 0 | G9: 0 | H9: 129851 | I9: ='Color clustering'!I9 -> 0 | J9: ='Color clustering'!J9 -> 30229 | K9: ='Color clustering'!K9 -> 0 | L9: ='Color clustering'!L9 -> 0 | M9: ='Color clustering'!M9 -> 2 | N9: ='Color clustering'!N9 -> 129769 | O9: ='Color clustering'!O9 -> 0 | P9: ='Color clustering'!P9 -> 29962 | ... T9: ='Color clustering'!T9 -> 129640 | U9: ='Color classification'!I9 -> 0 | V9: ='Color classification'!J9 -> 29947 | W9: ='Color classification'!K9 -> 0 | X9: ='Color classification'!L9 -> 6 | Y9: ='Color classification'!M9 -> 0 | Z9: ='Color classification'!N9 -> 130047 | AA9: ='Color classification'!O9 -> 0 | AB9: ='Color classification'!P9 -> 29952 | ... AF9: ='Color classification'!T9 -> 129793
B10: 6 | C10: 0 | D10: 30149 | E10: 0 | F10: 0 | G10: 0 | H10: 129851 | I10: ='Color clustering'!I10 -> 0 | J10: ='Color clustering'!J10 -> 30106 | K10: ='Color clustering'!K10 -> 0 | L10: ='Color clustering'!L10 -> 0 | M10: ='Color clustering'!M10 -> 0 | N10: ='Color clustering'!N10 -> 129894 | O10: ='Color clustering'!O10 -> 0 | P10: ='Color clustering'!P10 -> 29881 | ... T10: ='Color clustering'!T10 -> 129565 | U10: ='Color classification'!I10 -> 0 | V10: ='Color classification'!J10 -> 30034 | W10: ='Color classification'!K10 -> 0 | X10: ='Color classification'!L10 -> 0 | Y10: ='Color classification'!M10 -> 0 | Z10: ='Color classification'!N10 -> 129966 | AA10: ='Color classification'!O10 -> 0 | AB10: ='Color classification'!P10 -> 29785 | ... AF10: ='Color classification'!T10 -> 129718
B11: 7 | C11: 0 | D11: 30149 | E11: 0 | F11: 0 | G11: 0 | H11: 129851 | I11: ='Color clustering'!I11 -> 0 | J11: ='Color clustering'!J11 -> 30126 | K11: ='Color clustering'!K11 -> 0 | L11: ='Color clustering'!L11 -> 0 | M11: ='Color clustering'!M11 -> 0 | N11: ='Color clustering'!N11 -> 129874 | O11: ='Color clustering'!O11 -> 0 | P11: ='Color clustering'!P11 -> 29904 | ... T11: ='Color clustering'!T11 -> 129541 | U11: ='Color classification'!I11 -> 0 | V11: ='Color classification'!J11 -> 30039 | W11: ='Color classification'!K11 -> 0 | X11: ='Color classification'!L11 -> 0 | Y11: ='Color classification'!M11 -> 0 | Z11: ='Color classification'!N11 -> 129961 | AA11: ='Color classification'!O11 -> 0 | AB11: ='Color classification'!P11 -> 29823 | ... AF11: ='Color classification'!T11 -> 129773
B12: 8 | C12: 0 | D12: 30149 | E12: 0 | F12: 0 | G12: 0 | H12: 129851 | I12: ='Color clustering'!I12 -> 0 | J12: ='Color clustering'!J12 -> 30106 | K12: ='Color clustering'!K12 -> 0 | L12: ='Color clustering'!L12 -> 0 | M12: ='Color clustering'!M12 -> 0 | N12: ='Color clustering'!N12 -> 129894 | O12: ='Color clustering'!O12 -> 0 | P12: ='Color clustering'!P12 -> 29927 | ... T12: ='Color clustering'!T12 -> 129614 | U12: ='Color classification'!I12 -> 0 | V12: ='Color classification'!J12 -> 30093 | W12: ='Color classification'!K12 -> 0 | X12: ='Color classification'!L12 -> 0 | Y12: ='Color classification'!M12 -> 0 | Z12: ='Color classification'!N12 -> 129907 | AA12: ='Color classification'!O12 -> 0 | AB12: ='Color classification'!P12 -> 29961 | ... AF12: ='Color classification'!T12 -> 129788
B13: 9 | C13: 0 | D13: 30149 | E13: 0 | F13: 0 | G13: 0 | H13: 129851 | I13: ='Color clustering'!I13 -> 0 | J13: ='Color clustering'!J13 -> 30148 | K13: ='Color clustering'!K13 -> 0 | L13: ='Color clustering'!L13 -> 0 | M13: ='Color clustering'!M13 -> 0 | N13: ='Color clustering'!N13 -> 129852 | O13: ='Color clustering'!O13 -> 0 | P13: ='Color clustering'!P13 -> 29923 | ... T13: ='Color clustering'!T13 -> 129613 | U13: ='Color classification'!I13 -> 0 | V13: ='Color classification'!J13 -> 30090 | W13: ='Color classification'!K13 -> 0 | X13: ='Color classification'!L13 -> 0 | Y13: ='Color classification'!M13 -> 0 | Z13: ='Color classification'!N13 -> 129910 | AA13: ='Color classification'!O13 -> 0 | AB13: ='Color classification'!P13 -> 29979 | ... AF13: ='Color classification'!T13 -> 129790
B14: 10 | C14: 0 | D14: 30149 | E14: 0 | F14: 0 | G14: 0 | H14: 129851 | I14: ='Color clustering'!I14 -> 0 | J14: ='Color clustering'!J14 -> 30117 | K14: ='Color clustering'!K14 -> 0 | L14: ='Color clustering'!L14 -> 0 | M14: ='Color clustering'!M14 -> 8 | N14: ='Color clustering'!N14 -> 129875 | O14: ='Color clustering'!O14 -> 0 | P14: ='Color clustering'!P14 -> 29985 | ... T14: ='Color clustering'!T14 -> 129674 | U14: ='Color classification'!I14 -> 0 | V14: ='Color classification'!J14 -> 30143 | W14: ='Color classification'!K14 -> 0 | X14: ='Color classification'!L14 -> 0 | Y14: ='Color classification'!M14 -> 0 | Z14: ='Color classification'!N14 -> 129857 | AA14: ='Color classification'!O14 -> 0 | AB14: ='Color classification'!P14 -> 30032 | ... AF14: ='Color classification'!T14 -> 129804
B15: 11 | C15: 0 | D15: 30149 | E15: 0 | F15: 0 | G15: 0 | H15: 129851 | I15: ='Color clustering'!I15 -> 0 | J15: ='Color clustering'!J15 -> 30103 | K15: ='Color clustering'!K15 -> 0 | L15: ='Color clustering'!L15 -> 0 | M15: ='Color clustering'!M15 -> 0 | N15: ='Color clustering'!N15 -> 129897 | O15: ='Color clustering'!O15 -> 0 | P15: ='Color clustering'!P15 -> 29923 | ... T15: ='Color clustering'!T15 -> 129610 | U15: ='Color classification'!I15 -> 0 | V15: ='Color classification'!J15 -> 30104 | W15: ='Color classification'!K15 -> 0 | X15: ='Color classification'!L15 -> 0 | Y15: ='Color classification'!M15 -> 0 | Z15: ='Color classification'!N15 -> 129896 | AA15: ='Color classification'!O15 -> 0 | AB15: ='Color classification'!P15 -> 29853 | ... AF15: ='Color classification'!T15 -> 129648
... B203: 199 | C203: 0 | D203: 30149 | E203: 0 | F203: 0 | G203: 0 | H203: 129851 | I203: ='Color clustering'!I203 -> 0 | J203: ='Color clustering'!J203 -> 30197 | K203: ='Color clustering'!K203 -> 0 | L203: ='Color clustering'!L203 -> 0 | M203: ='Color clustering'!M203 -> 0 | N203: ='Color clustering'!N203 -> 129803 | O203: ='Color clustering'!O203 -> 0 | P203: ='Color clustering'!P203 -> 30090 | ... T203: ='Color clustering'!T203 -> 129712 | U203: ='Color classification'!I203 -> 0 | V203: ='Color classification'!J203 -> 30088 | W203: ='Color classification'!K203 -> 0 | X203: ='Color classification'!L203 -> 0 | Y203: ='Color classification'!M203 -> 0 | Z203: ='Color classification'!N203 -> 129912 | AA203: ='Color classification'!O203 -> 0 | AB203: ='Color classification'!P203 -> 30090 | ... AF203: ='Color classification'!T203 -> 129851
B204: Total | C204: =SUM(C4:C203) -> 248825 | D204: =SUM(D4:D203) -> 5400786 | E204: =SUM(E4:E203) -> 105525 | F204: =SUM(F4:F203) -> 235700 | G204: =SUM(G4:G203) -> 38964 | H204: =SUM(H4:H203) -> 25970200 | I204: =SUM(I4:I203) -> 249913 | J204: =SUM(J4:J203) -> 5506546 | ... AF204: =SUM(AF4:AF203) -> 25959046
B209: image | C209: Absolute Error Clustering | O209: Absolute Error Classification | AA209: SMAPE Clustering | AO209: SMAPE Classification
C210: Random correction | I210: Color classification | O210: Random correction | U210: Color classification | AA210: Random correction | AH210: Color classification | AO210: Random correction | AV210: Color classification
A211: 4_filled_cylinder/f_cyl_z | C211: #c88637 | D211: #e3bb37 | E211: #e65a49 | F211: #e98d78 | G211: #f1de9e | H211: #ffffff | I211: #c88637 | J211: #e3bb37 | K211: #e65a49 | L211: #e98d78 | M211: #f1de9e | N211: #ffffff | O211: #c78637 | P211: #e3bb37 | Q211: #e65a49 | R211: #e88d76 | S211: #f08a8c | T211: #ffffff | U211: #c78637 | V211: #e3bb37 | W211: #e65a49 | X211: #e88d76 | Y211: #f08a8c | Z211: #ffffff | AA211: #c88637 | AB211: #e3bb37 | AC211: #e65a49 | AD211: #e98d78 | AE211: #f1de9e | AF211: #ffffff | AH211: #c88637 | AI211: #e3bb37 | AJ211: #e65a49 | AK211: #e98d78 | AL211: #f1de9e | AM211: #ffffff | AO211: #c78637 | AP211: #e3bb37 | AQ211: #e65a49 | AR211: #e88d76 | AS211: #f08a8c | AT211: #ffffff | AV211: #c78637 | AW211: #e3bb37 | AX211: #e65a49 | AY211: #e88d76 | AZ211: #f08a8c | BA211: #ffffff
