Workbook

Sheet Color clustering
B1: image | C1: Pre-alignement | H1: Post-alignement
H2: Random correction | M2: Color classification
A3: 4_filled_cylinder/f_cyl_axis_unal/Col_clust | C3: #c88637 | D3: #e3bb37 | E3: #e65a49 | F3: #efab8c | G3: #fdfdfd | H3: #c88637 | I3: #e3bb37 | J3: #e65a49 | K3: #efab8c | L3: #fdfdfd | M3: #c88637 | N3: #e3bb37 | O3: #e65a49 | P3: #efab8c | Q3: #fdfdfd
B4: 0 | C4: 0 | D4: 60 | E4: 0 | F4: 38 | G4: 159902 | H4: 0 | I4: 60 | J4: =0 -> 0 | K4: 38 | L4: 159902 | M4: 0 | N4: 60 | O4: 0 | P4: 38 | Q4: 159902
B5: 1 | C5: 0 | D5: 272 | E5: 0 | F5: 0 | G5: 159728 | H5: 0 | I5: 259 | J5: =0 -> 0 | K5: 0 | L5: 159741 | M5: 0 | N5: 259 | O5: 0 | P5: 15 | Q5: 159726
B6: 2 | C6: 0 | D6: 489 | E6: 0 | F6: 66 | G6: 159445 | H6: 0 | I6: 492 | J6: =0 -> 0 | K6: 0 | L6: 159508 | M6: 0 | N6: 479 | O6: 0 | P6: 83 | Q6: 159438
B7: 3 | C7: 0 | D7: 829 | E7: 0 | F7: 1 | G7: 159170 | H7: 0 | I7: 803 | J7: =0 -> 0 | K7: 0 | L7: 159197 | M7: 0 | N7: 795 | O7: 0 | P7: 57 | Q7: 159148
B8: 4 | C8: 0 | D8: 1146 | E8: 0 | F8: 30 | G8: 158824 | H8: 0 | I8: 1137 | J8: =0 -> 0 | K8: 0 | L8: 158863 | M8: 0 | N8: 1117 | O8: 0 | P8: 76 | Q8: 158807
B9: 5 | C9: 0 | D9: 1559 | E9: 0 | F9: 0 | G9: 158441 | H9: 0 | I9: 1544 | J9: =0 -> 0 | K9: 0 | L9: 158456 | M9: 0 | N9: 1512 | O9: 0 | P9: 72 | Q9: 158416
B10: 6 | C10: 0 | D10: 1954 | E10: 0 | F10: 22 | G10: 158024 | H10: 0 | I10: 1936 | J10: =0 -> 0 | K10: 0 | L10: 158064 | M10: 0 | N10: 1891 | O10: 0 | P10: 127 | Q10: 157982
B11: 7 | C11: 0 | D11: 2355 | E11: 0 | F11: 64 | G11: 157581 | H11: 0 | I11: 2344 | J11: =0 -> 0 | K11: 5 | L11: 157651 | M11: 0 | N11: 2324 | O11: 0 | P11: 115 | Q11: 157561
B12: 8 | C12: 0 | D12: 2837 | E12: 0 | F12: 95 | G12: 157068 | H12: 0 | I12: 2849 | J12: =0 -> 0 | K12: 0 | L12: 157151 | M12: 0 | N12: 2809 | O12: 0 | P12: 145 | Q12: 157046
B13: 9 | C13: 0 | D13: 3385 | E13: 0 | F13: 9 | G13: 156606 | H13: 0 | I13: 3373 | J13: =0 -> 0 | K13: 0 | L13: 156627 | M13: 0 | N13: 3322 | O13: 0 | P13: 105 | Q13: 156573
B14: 10 | C14: 0 | D14: 3851 | E14: 0 | F14: 116 | G14: 156033 | H14: 0 | I14: 3866 | J14: =0 -> 0 | K14: 0 | L14: 156134 | M14: 0 | N14: 3815 | O14: 0 | P14: 162 | Q14: 156023
B15: 11 | C15: 0 | D15: 4383 | E15: 0 | F15: 101 | G15: 155516 | H15: 0 | I15: 4379 | J15: =0 -> 0 | K15: 0 | L15: 155621 | M15: 0 | N15: 4349 | O15: 0 | P15: 157 | Q15: 155494
... B186: 182 | C186: 0 | D186: 79 | E186: 0 | F186: 0 | G186: 159921 | H186: 0 | I186: 75 | J186: =0 -> 0 | K186: 0 | L186: 159925 | M186: 0 | N186: 68 | O186: 0 | P186: 18 | Q186: 159914
B187: Total | C187: =SUM(C4:C186) -> 243873 | D187: =SUM(D4:D186) -> 1866257 | E187: =SUM(E4:E186) -> 103665 | F187: =SUM(F4:F186) -> 66376 | G187: =SUM(G4:G186) -> 26999829 | H187: =SUM(H4:H186) -> 241221 | I187: =SUM(I4:I186) -> 1982369 | J187: =SUM(J4:J186) -> 0 | ... Q187: =SUM(Q4:Q186) -> 26992179
B192: image | C192: Absolute Error | M192: SMAPE
C193: Random correction | H193: Color classification | M193: Random correction | S193: Color classification
A194: 4_filled_cylinder/f_cyl_axis_unal/Col_clust | C194: #c88637 | D194: #e3bb37 | E194: #e65a49 | F194: #efab8c | G194: #fdfdfd | H194: #c88637 | I194: #e3bb37 | J194: #e65a49 | K194: #efab8c | L194: #fdfdfd | M194: #c88637 | N194: #e3bb37 | O194: #e65a49 | P194: #efab8c | Q194: #fdfdfd | S194: #c88637 | T194: #e3bb37 | U194: #e65a49 | V194: #efab8c | W194: #fdfdfd
B195: 0 | C195: =ABS(H4-C4) -> 0 | D195: =ABS(I4-D4) -> 0 | E195: =ABS(J4-E4) -> 0 | F195: =ABS(K4-F4) -> 0 | G195: =ABS(L4-G4) -> 0 | H195: =ABS(M4-C4) -> 0 | I195: =ABS(N4-D4) -> 0 | J195: =ABS(O4-E4) -> 0 | K195: =ABS(P4-F4) -> 0 | L195: =ABS(Q4-G4) -> 0 | M195: =IF(AND(C4=0,H4=0), 0, ABS(C4-H4)/((ABS(C4)+ABS(H4))/2)) -> 0 | N195: =IF(AND(D4=0,I4=0), 0, ABS(D4-I4)/((ABS(D4)+ABS(I4))/2)) -> 0 | O195: =IF(AND(E4=0,J4=0), 0, ABS(E4-J4)/((ABS(E4)+ABS(J4))/2)) -> 0 | P195: =IF(AND(F4=0,K4=0), 0, ABS(F4-K4)/((ABS(F4)+ABS(K4))/2)) -> 0 | Q195: =IF(AND(G4=0,L4=0), 0, ABS(G4-L4)/((ABS(G4)+ABS(L4))/2)) -> 0 | S195: =IF(AND(C4=0,M4=0), 0, ABS(C4-M4)/((ABS(C4)+ABS(M4))/2)) -> 0 | T195: =IF(AND(D4=0,N4=0), 0, ABS(D4-N4)/((ABS(D4)+ABS(N4))/2)) -> 0 | U195: =IF(AND(E4=0,O4=0), 0, ABS(E4-O4)/((ABS(E4)+ABS(O4))/2)) -> 0 | V195: =IF(AND(F4=0,P4=0), 0, ABS(F4-P4)/((ABS(F4)+ABS(P4))/2)) -> 0 | W195: =IF(AND(G4=0,Q4=0), 0, ABS(G4-Q4)/((ABS(G4)+ABS(Q4))/2)) -> 0
B196: 1 | C196: =ABS(H5-C5) -> 0 | D196: =ABS(I5-D5) -> 13 | E196: =ABS(J5-E5) -> 0 | F196: =ABS(K5-F5) -> 0 | G196: =ABS(L5-G5) -> 13 | H196: =ABS(M5-C5) -> 0 | I196: =ABS(N5-D5) -> 13 | J196: =ABS(O5-E5) -> 0 | K196: =ABS(P5-F5) -> 15 | L196: =ABS(Q5-G5) -> 2 | M196: =IF(AND(C5=0,H5=0), 0, ABS(C5-H5)/((ABS(C5)+ABS(H5))/2)) -> 0 | N196: =IF(AND(D5=0,I5=0), 0, ABS(D5-I5)/((ABS(D5)+ABS(I5))/2)) -> 0.048964218 | O196: =IF(AND(E5=0,J5=0), 0, ABS(E5-J5)/((ABS(E5)+ABS(J5))/2)) -> 0 | P196: =IF(AND(F5=0,K5=0), 0, ABS(F5-K5)/((ABS(F5)+ABS(K5))/2)) -> 0 | Q196: =IF(AND(G5=0,L5=0), 0, ABS(G5-L5)/((ABS(G5)+ABS(L5))/2)) -> 8.1385048e-05 | S196: =IF(AND(C5=0,M5=0), 0, ABS(C5-M5)/((ABS(C5)+ABS(M5))/2)) -> 0 | T196: =IF(AND(D5=0,N5=0), 0, ABS(D5-N5)/((ABS(D5)+ABS(N5))/2)) -> 0.048964218 | U196: =IF(AND(E5=0,O5=0), 0, ABS(E5-O5)/((ABS(E5)+ABS(O5))/2)) -> 0 | V196: =IF(AND(F5=0,P5=0), 0, ABS(F5-P5)/((ABS(F5)+ABS(P5))/2)) -> 2 | W196: =IF(AND(G5=0,Q5=0), 0, ABS(G5-Q5)/((ABS(G5)+ABS(Q5))/2)) -> 1.2521365e-05
B197: 2 | C197: =ABS(H6-C6) -> 0 | D197: =ABS(I6-D6) -> 3 | E197: =ABS(J6-E6) -> 0 | F197: =ABS(K6-F6) -> 66 | G197: =ABS(L6-G6) -> 63 | H197: =ABS(M6-C6) -> 0 | I197: =ABS(N6-D6) -> 10 | J197: =ABS(O6-E6) -> 0 | K197: =ABS(P6-F6) -> 17 | L197: =ABS(Q6-G6) -> 7 | M197: =IF(AND(C6=0,H6=0), 0, ABS(C6-H6)/((ABS(C6)+ABS(H6))/2)) -> 0 | N197: =IF(AND(D6=0,I6=0), 0, ABS(D6-I6)/((ABS(D6)+ABS(I6))/2)) -> 0.006116208 | O197: =IF(AND(E6=0,J6=0), 0, ABS(E6-J6)/((ABS(E6)+ABS(J6))/2)) -> 0 | P197: =IF(AND(F6=0,K6=0), 0, ABS(F6-K6)/((ABS(F6)+ABS(K6))/2)) -> 2 | Q197: =IF(AND(G6=0,L6=0), 0, ABS(G6-L6)/((ABS(G6)+ABS(L6))/2)) -> 0.00039504253 | S197: =IF(AND(C6=0,M6=0), 0, ABS(C6-M6)/((ABS(C6)+ABS(M6))/2)) -> 0 | T197: =IF(AND(D6=0,N6=0), 0, ABS(D6-N6)/((ABS(D6)+ABS(N6))/2)) -> 0.020661157 | U197: =IF(AND(E6=0,O6=0), 0, ABS(E6-O6)/((ABS(E6)+ABS(O6))/2)) -> 0 | V197: =IF(AND(F6=0,P6=0), 0, ABS(F6-P6)/((ABS(F6)+ABS(P6))/2)) -> 0.22818792 | W197: =IF(AND(G6=0,Q6=0), 0, ABS(G6-Q6)/((ABS(G6)+ABS(Q6))/2)) -> 4.390325e-05
B198: 3 | C198: =ABS(H7-C7) -> 0 | D198: =ABS(I7-D7) -> 26 | E198: =ABS(J7-E7) -> 0 | F198: =ABS(K7-F7) -> 1 | G198: =ABS(L7-G7) -> 27 | H198: =ABS(M7-C7) -> 0 | I198: =ABS(N7-D7) -> 34 | J198: =ABS(O7-E7) -> 0 | K198: =ABS(P7-F7) -> 56 | L198: =ABS(Q7-G7) -> 22 | M198: =IF(AND(C7=0,H7=0), 0, ABS(C7-H7)/((ABS(C7)+ABS(H7))/2)) -> 0 | N198: =IF(AND(D7=0,I7=0), 0, ABS(D7-I7)/((ABS(D7)+ABS(I7))/2)) -> 0.031862745 | O198: =IF(AND(E7=0,J7=0), 0, ABS(E7-J7)/((ABS(E7)+ABS(J7))/2)) -> 0 | P198: =IF(AND(F7=0,K7=0), 0, ABS(F7-K7)/((ABS(F7)+ABS(K7))/2)) -> 2 | Q198: =IF(AND(G7=0,L7=0), 0, ABS(G7-L7)/((ABS(G7)+ABS(L7))/2)) -> 0.00016961557 | S198: =IF(AND(C7=0,M7=0), 0, ABS(C7-M7)/((ABS(C7)+ABS(M7))/2)) -> 0 | T198: =IF(AND(D7=0,N7=0), 0, ABS(D7-N7)/((ABS(D7)+ABS(N7))/2)) -> 0.041871921 | U198: =IF(AND(E7=0,O7=0), 0, ABS(E7-O7)/((ABS(E7)+ABS(O7))/2)) -> 0 | V198: =IF(AND(F7=0,P7=0), 0, ABS(F7-P7)/((ABS(F7)+ABS(P7))/2)) -> 1.9310345 | W198: =IF(AND(G7=0,Q7=0), 0, ABS(G7-Q7)/((ABS(G7)+ABS(Q7))/2)) -> 0.00013822655
B199: 4 | C199: =ABS(H8-C8) -> 0 | D199: =ABS(I8-D8) -> 9 | E199: =ABS(J8-E8) -> 0 | F199: =ABS(K8-F8) -> 30 | G199: =ABS(L8-G8) -> 39 | H199: =ABS(M8-C8) -> 0 | I199: =ABS(N8-D8) -> 29 | J199: =ABS(O8-E8) -> 0 | K199: =ABS(P8-F8) -> 46 | L199: =ABS(Q8-G8) -> 17 | M199: =IF(AND(C8=0,H8=0), 0, ABS(C8-H8)/((ABS(C8)+ABS(H8))/2)) -> 0 | N199: =IF(AND(D8=0,I8=0), 0, ABS(D8-I8)/((ABS(D8)+ABS(I8))/2)) -> 0.0078843627 | O199: =IF(AND(E8=0,J8=0), 0, ABS(E8-J8)/((ABS(E8)+ABS(J8))/2)) -> 0 | P199: =IF(AND(F8=0,K8=0), 0, ABS(F8-K8)/((ABS(F8)+ABS(K8))/2)) -> 2 | Q199: =IF(AND(G8=0,L8=0), 0, ABS(G8-L8)/((ABS(G8)+ABS(L8))/2)) -> 0.00024552468 | S199: =IF(AND(C8=0,M8=0), 0, ABS(C8-M8)/((ABS(C8)+ABS(M8))/2)) -> 0 | T199: =IF(AND(D8=0,N8=0), 0, ABS(D8-N8)/((ABS(D8)+ABS(N8))/2)) -> 0.025629695 | U199: =IF(AND(E8=0,O8=0), 0, ABS(E8-O8)/((ABS(E8)+ABS(O8))/2)) -> 0 | V199: =IF(AND(F8=0,P8=0), 0, ABS(F8-P8)/((ABS(F8)+ABS(P8))/2)) -> 0.86792453 | W199: =IF(AND(G8=0,Q8=0), 0, ABS(G8-Q8)/((ABS(G8)+ABS(Q8))/2)) -> 0.00010704245
B200: 5 | C200: =ABS(H9-C9) -> 0 | D200: =ABS(I9-D9) -> 15 | E200: =ABS(J9-E9) -> 0 | F200: =ABS(K9-F9) -> 0 | G200: =ABS(L9-G9) -> 15 | H200: =ABS(M9-C9) -> 0 | I200: =ABS(N9-D9) -> 47 | J200: =ABS(O9-E9) -> 0 | K200: =ABS(P9-F9) -> 72 | L200: =ABS(Q9-G9) -> 25 | M200: =IF(AND(C9=0,H9=0), 0, ABS(C9-H9)/((ABS(C9)+ABS(H9))/2)) -> 0 | N200: =IF(AND(D9=0,I9=0), 0, ABS(D9-I9)/((ABS(D9)+ABS(I9))/2)) -> 0.0096680632 | O200: =IF(AND(E9=0,J9=0), 0, ABS(E9-J9)/((ABS(E9)+ABS(J9))/2)) -> 0 | P200: =IF(AND(F9=0,K9=0), 0, ABS(F9-K9)/((ABS(F9)+ABS(K9))/2)) -> 0 | Q200: =IF(AND(G9=0,L9=0), 0, ABS(G9-L9)/((ABS(G9)+ABS(L9))/2)) -> 9.4667984e-05 | S200: =IF(AND(C9=0,M9=0), 0, ABS(C9-M9)/((ABS(C9)+ABS(M9))/2)) -> 0 | T200: =IF(AND(D9=0,N9=0), 0, ABS(D9-N9)/((ABS(D9)+ABS(N9))/2)) -> 0.030608922 | U200: =IF(AND(E9=0,O9=0), 0, ABS(E9-O9)/((ABS(E9)+ABS(O9))/2)) -> 0 | V200: =IF(AND(F9=0,P9=0), 0, ABS(F9-P9)/((ABS(F9)+ABS(P9))/2)) -> 2 | W200: =IF(AND(G9=0,Q9=0), 0, ABS(G9-Q9)/((ABS(G9)+ABS(Q9))/2)) -> 0.00015779989
B201: 6 | C201: =ABS(H10-C10) -> 0 | D201: =ABS(I10-D10) -> 18 | E201: =ABS(J10-E10) -> 0 | F201: =ABS(K10-F10) -> 22 | G201: =ABS(L10-G10) -> 40 | H201: =ABS(M10-C10) -> 0 | I201: =ABS(N10-D10) -> 63 | J201: =ABS(O10-E10) -> 0 | K201: =ABS(P10-F10) -> 105 | L201: =ABS(Q10-G10) -> 42 | M201: =IF(AND(C10=0,H10=0), 0, ABS(C10-H10)/((ABS(C10)+ABS(H10))/2)) -> 0 | N201: =IF(AND(D10=0,I10=0), 0, ABS(D10-I10)/((ABS(D10)+ABS(I10))/2)) -> 0.0092544987 | O201: =IF(AND(E10=0,J10=0), 0, ABS(E10-J10)/((ABS(E10)+ABS(J10))/2)) -> 0 | P201: =IF(AND(F10=0,K10=0), 0, ABS(F10-K10)/((ABS(F10)+ABS(K10))/2)) -> 2 | Q201: =IF(AND(G10=0,L10=0), 0, ABS(G10-L10)/((ABS(G10)+ABS(L10))/2)) -> 0.00025309408 | S201: =IF(AND(C10=0,M10=0), 0, ABS(C10-M10)/((ABS(C10)+ABS(M10))/2)) -> 0 | T201: =IF(AND(D10=0,N10=0), 0, ABS(D10-N10)/((ABS(D10)+ABS(N10))/2)) -> 0.032769831 | U201: =IF(AND(E10=0,O10=0), 0, ABS(E10-O10)/((ABS(E10)+ABS(O10))/2)) -> 0 | V201: =IF(AND(F10=0,P10=0), 0, ABS(F10-P10)/((ABS(F10)+ABS(P10))/2)) -> 1.409396 | W201: =IF(AND(G10=0,Q10=0), 0, ABS(G10-Q10)/((ABS(G10)+ABS(Q10))/2)) -> 0.00026581774
B202: 7 | C202: =ABS(H11-C11) -> 0 | D202: =ABS(I11-D11) -> 11 | E202: =ABS(J11-E11) -> 0 | F202: =ABS(K11-F11) -> 59 | G202: =ABS(L11-G11) -> 70 | H202: =ABS(M11-C11) -> 0 | I202: =ABS(N11-D11) -> 31 | J202: =ABS(O11-E11) -> 0 | K202: =ABS(P11-F11) -> 51 | L202: =ABS(Q11-G11) -> 20 | M202: =IF(AND(C11=0,H11=0), 0, ABS(C11-H11)/((ABS(C11)+ABS(H11))/2)) -> 0 | N202: =IF(AND(D11=0,I11=0), 0, ABS(D11-I11)/((ABS(D11)+ABS(I11))/2)) -> 0.0046818472 | O202: =IF(AND(E11=0,J11=0), 0, ABS(E11-J11)/((ABS(E11)+ABS(J11))/2)) -> 0 | P202: =IF(AND(F11=0,K11=0), 0, ABS(F11-K11)/((ABS(F11)+ABS(K11))/2)) -> 1.7101449 | Q202: =IF(AND(G11=0,L11=0), 0, ABS(G11-L11)/((ABS(G11)+ABS(L11))/2)) -> 0.00044411735 | S202: =IF(AND(C11=0,M11=0), 0, ABS(C11-M11)/((ABS(C11)+ABS(M11))/2)) -> 0 | T202: =IF(AND(D11=0,N11=0), 0, ABS(D11-N11)/((ABS(D11)+ABS(N11))/2)) -> 0.013250695 | U202: =IF(AND(E11=0,O11=0), 0, ABS(E11-O11)/((ABS(E11)+ABS(O11))/2)) -> 0 | V202: =IF(AND(F11=0,P11=0), 0, ABS(F11-P11)/((ABS(F11)+ABS(P11))/2)) -> 0.5698324 | W202: =IF(AND(G11=0,Q11=0), 0, ABS(G11-Q11)/((ABS(G11)+ABS(Q11))/2)) -> 0.00012692691
B203: 8 | C203: =ABS(H12-C12) -> 0 | D203: =ABS(I12-D12) -> 12 | E203: =ABS(J12-E12) -> 0 | F203: =ABS(K12-F12) -> 95 | G203: =ABS(L12-G12) -> 83 | H203: =ABS(M12-C12) -> 0 | I203: =ABS(N12-D12) -> 28 | J203: =ABS(O12-E12) -> 0 | K203: =ABS(P12-F12) -> 50 | L203: =ABS(Q12-G12) -> 22 | M203: =IF(AND(C12=0,H12=0), 0, ABS(C12-H12)/((ABS(C12)+ABS(H12))/2)) -> 0 | N203: =IF(AND(D12=0,I12=0), 0, ABS(D12-I12)/((ABS(D12)+ABS(I12))/2)) -> 0.0042208934 | O203: =IF(AND(E12=0,J12=0), 0, ABS(E12-J12)/((ABS(E12)+ABS(J12))/2)) -> 0 | P203: =IF(AND(F12=0,K12=0), 0, ABS(F12-K12)/((ABS(F12)+ABS(K12))/2)) -> 2 | Q203: =IF(AND(G12=0,L12=0), 0, ABS(G12-L12)/((ABS(G12)+ABS(L12))/2)) -> 0.00052829396 | S203: =IF(AND(C12=0,M12=0), 0, ABS(C12-M12)/((ABS(C12)+ABS(M12))/2)) -> 0 | T203: =IF(AND(D12=0,N12=0), 0, ABS(D12-N12)/((ABS(D12)+ABS(N12))/2)) -> 0.0099185264 | U203: =IF(AND(E12=0,O12=0), 0, ABS(E12-O12)/((ABS(E12)+ABS(O12))/2)) -> 0 | V203: =IF(AND(F12=0,P12=0), 0, ABS(F12-P12)/((ABS(F12)+ABS(P12))/2)) -> 0.41666667 | W203: =IF(AND(G12=0,Q12=0), 0, ABS(G12-Q12)/((ABS(G12)+ABS(Q12))/2)) -> 0.00014007653
B204: 9 | C204: =ABS(H13-C13) -> 0 | D204: =ABS(I13-D13) -> 12 | E204: =ABS(J13-E13) -> 0 | F204: =ABS(K13-F13) -> 9 | G204: =ABS(L13-G13) -> 21 | H204: =ABS(M13-C13) -> 0 | I204: =ABS(N13-D13) -> 63 | J204: =ABS(O13-E13) -> 0 | K204: =ABS(P13-F13) -> 96 | L204: =ABS(Q13-G13) -> 33 | M204: =IF(AND(C13=0,H13=0), 0, ABS(C13-H13)/((ABS(C13)+ABS(H13))/2)) -> 0 | N204: =IF(AND(D13=0,I13=0), 0, ABS(D13-I13)/((ABS(D13)+ABS(I13))/2)) -> 0.0035513466 | O204: =IF(AND(E13=0,J13=0), 0, ABS(E13-J13)/((ABS(E13)+ABS(J13))/2)) -> 0 | P204: =IF(AND(F13=0,K13=0), 0, ABS(F13-K13)/((ABS(F13)+ABS(K13))/2)) -> 2 | Q204: =IF(AND(G13=0,L13=0), 0, ABS(G13-L13)/((ABS(G13)+ABS(L13))/2)) -> 0.00013408549 | S204: =IF(AND(C13=0,M13=0), 0, ABS(C13-M13)/((ABS(C13)+ABS(M13))/2)) -> 0 | T204: =IF(AND(D13=0,N13=0), 0, ABS(D13-N13)/((ABS(D13)+ABS(N13))/2)) -> 0.018786343 | U204: =IF(AND(E13=0,O13=0), 0, ABS(E13-O13)/((ABS(E13)+ABS(O13))/2)) -> 0 | V204: =IF(AND(F13=0,P13=0), 0, ABS(F13-P13)/((ABS(F13)+ABS(P13))/2)) -> 1.6842105 | W204: =IF(AND(G13=0,Q13=0), 0, ABS(G13-Q13)/((ABS(G13)+ABS(Q13))/2)) -> 0.0002107421
B205: 10 | C205: =ABS(H14-C14) -> 0 | D205: =ABS(I14-D14) -> 15 | E205: =ABS(J14-E14) -> 0 | F205: =ABS(K14-F14) -> 116 | G205: =ABS(L14-G14) -> 101 | H205: =ABS(M14-C14) -> 0 | I205: =ABS(N14-D14) -> 36 | J205: =ABS(O14-E14) -> 0 | K205: =ABS(P14-F14) -> 46 | L205: =ABS(Q14-G14) -> 10 | M205: =IF(AND(C14=0,H14=0), 0, ABS(C14-H14)/((ABS(C14)+ABS(H14))/2)) -> 0 | N205: =IF(AND(D14=0,I14=0), 0, ABS(D14-I14)/((ABS(D14)+ABS(I14))/2)) -> 0.0038875211 | O205: =IF(AND(E14=0,J14=0), 0, ABS(E14-J14)/((ABS(E14)+ABS(J14))/2)) -> 0 | P205: =IF(AND(F14=0,K14=0), 0, ABS(F14-K14)/((ABS(F14)+ABS(K14))/2)) -> 2 | Q205: =IF(AND(G14=0,L14=0), 0, ABS(G14-L14)/((ABS(G14)+ABS(L14))/2)) -> 0.00064708954 | S205: =IF(AND(C14=0,M14=0), 0, ABS(C14-M14)/((ABS(C14)+ABS(M14))/2)) -> 0 | T205: =IF(AND(D14=0,N14=0), 0, ABS(D14-N14)/((ABS(D14)+ABS(N14))/2)) -> 0.0093921211 | U205: =IF(AND(E14=0,O14=0), 0, ABS(E14-O14)/((ABS(E14)+ABS(O14))/2)) -> 0 | V205: =IF(AND(F14=0,P14=0), 0, ABS(F14-P14)/((ABS(F14)+ABS(P14))/2)) -> 0.33093525 | W205: =IF(AND(G14=0,Q14=0), 0, ABS(G14-Q14)/((ABS(G14)+ABS(Q14))/2)) -> 6.4091061e-05
B206: 11 | C206: =ABS(H15-C15) -> 0 | D206: =ABS(I15-D15) -> 4 | E206: =ABS(J15-E15) -> 0 | F206: =ABS(K15-F15) -> 101 | G206: =ABS(L15-G15) -> 105 | H206: =ABS(M15-C15) -> 0 | I206: =ABS(N15-D15) -> 34 | J206: =ABS(O15-E15) -> 0 | K206: =ABS(P15-F15) -> 56 | L206: =ABS(Q15-G15) -> 22 | M206: =IF(AND(C15=0,H15=0), 0, ABS(C15-H15)/((ABS(C15)+ABS(H15))/2)) -> 0 | N206: =IF(AND(D15=0,I15=0), 0, ABS(D15-I15)/((ABS(D15)+ABS(I15))/2)) -> 0.00091303355 | O206: =IF(AND(E15=0,J15=0), 0, ABS(E15-J15)/((ABS(E15)+ABS(J15))/2)) -> 0 | P206: =IF(AND(F15=0,K15=0), 0, ABS(F15-K15)/((ABS(F15)+ABS(K15))/2)) -> 2 | Q206: =IF(AND(G15=0,L15=0), 0, ABS(G15-L15)/((ABS(G15)+ABS(L15))/2)) -> 0.00067494384 | S206: =IF(AND(C15=0,M15=0), 0, ABS(C15-M15)/((ABS(C15)+ABS(M15))/2)) -> 0 | T206: =IF(AND(D15=0,N15=0), 0, ABS(D15-N15)/((ABS(D15)+ABS(N15))/2)) -> 0.0077874485 | U206: =IF(AND(E15=0,O15=0), 0, ABS(E15-O15)/((ABS(E15)+ABS(O15))/2)) -> 0 | V206: =IF(AND(F15=0,P15=0), 0, ABS(F15-P15)/((ABS(F15)+ABS(P15))/2)) -> 0.43410853 | W206: =IF(AND(G15=0,Q15=0), 0, ABS(G15-Q15)/((ABS(G15)+ABS(Q15))/2)) -> 0.00014147455
... B376: 181 | C376: =ABS(H185-C185) -> 0 | D376: =ABS(I185-D185) -> 4 | E376: =ABS(J185-E185) -> 0 | F376: =ABS(K185-F185) -> 0 | G376: =ABS(L185-G185) -> 4 | H376: =ABS(M185-C185) -> 0 | I376: =ABS(N185-D185) -> 22 | J376: =ABS(O185-E185) -> 0 | K376: =ABS(P185-F185) -> 34 | L376: =ABS(Q185-G185) -> 12 | M376: =IF(AND(C185=0,H185=0), 0, ABS(C185-H185)/((ABS(C185)+ABS(H185))/2)) -> 0 | N376: =IF(AND(D185=0,I185=0), 0, ABS(D185-I185)/((ABS(D185)+ABS(I185))/2)) -> 0.014814815 | O376: =IF(AND(E185=0,J185=0), 0, ABS(E185-J185)/((ABS(E185)+ABS(J185))/2)) -> 0 | P376: =IF(AND(F185=0,K185=0), 0, ABS(F185-K185)/((ABS(F185)+ABS(K185))/2)) -> 0 | Q376: =IF(AND(G185=0,L185=0), 0, ABS(G185-L185)/((ABS(G185)+ABS(L185))/2)) -> 2.5042259e-05 | S376: =IF(AND(C185=0,M185=0), 0, ABS(C185-M185)/((ABS(C185)+ABS(M185))/2)) -> 0 | T376: =IF(AND(D185=0,N185=0), 0, ABS(D185-N185)/((ABS(D185)+ABS(N185))/2)) -> 0.084291188 | U376: =IF(AND(E185=0,O185=0), 0, ABS(E185-O185)/((ABS(E185)+ABS(O185))/2)) -> 0 | V376: =IF(AND(F185=0,P185=0), 0, ABS(F185-P185)/((ABS(F185)+ABS(P185))/2)) -> 2 | W376: =IF(AND(G185=0,Q185=0), 0, ABS(G185-Q185)/((ABS(G185)+ABS(Q185))/2)) -> 7.5130539e-05
B377: 182 | C377: =ABS(H186-C186) -> 0 | D377: =ABS(I186-D186) -> 4 | E377: =ABS(J186-E186) -> 0 | F377: =ABS(K186-F186) -> 0 | G377: =ABS(L186-G186) -> 4 | H377: =ABS(M186-C186) -> 0 | I377: =ABS(N186-D186) -> 11 | J377: =ABS(O186-E186) -> 0 | K377: =ABS(P186-F186) -> 18 | L377: =ABS(Q186-G186) -> 7 | M377: =IF(AND(C186=0,H186=0), 0, ABS(C186-H186)/((ABS(C186)+ABS(H186))/2)) -> 0 | N377: =IF(AND(D186=0,I186=0), 0, ABS(D186-I186)/((ABS(D186)+ABS(I186))/2)) -> 0.051948052 | O377: =IF(AND(E186=0,J186=0), 0, ABS(E186-J186)/((ABS(E186)+ABS(J186))/2)) -> 0 | P377: =IF(AND(F186=0,K186=0), 0, ABS(F186-K186)/((ABS(F186)+ABS(K186))/2)) -> 0 | Q377: =IF(AND(G186=0,L186=0), 0, ABS(G186-L186)/((ABS(G186)+ABS(L186))/2)) -> 2.5012037e-05 | R377: SMAPE | S377: =IF(AND(C186=0,M186=0), 0, ABS(C186-M186)/((ABS(C186)+ABS(M186))/2)) -> 0 | T377: =IF(AND(D186=0,N186=0), 0, ABS(D186-N186)/((ABS(D186)+ABS(N186))/2)) -> 0.14965986 | U377: =IF(AND(E186=0,O186=0), 0, ABS(E186-O186)/((ABS(E186)+ABS(O186))/2)) -> 0 | V377: =IF(AND(F186=0,P186=0), 0, ABS(F186-P186)/((ABS(F186)+ABS(P186))/2)) -> 2 | W377: =IF(AND(G186=0,Q186=0), 0, ABS(G186-Q186)/((ABS(G186)+ABS(Q186))/2)) -> 4.377257e-05 | X377: SMAPE
B378: Total | C378: =SUM(C195:C377)/183 -> 17.879781 | D378: =SUM(D195:D377)/183 -> 641.68306 | E378: =SUM(E195:E377)/183 -> 566.47541 | F378: =SUM(F195:F377)/183 -> 148.84153 | G378: =SUM(G195:G377)/183 -> 96.36612 | H378: =SUM(H195:H377)/183 -> 18.043716 | I378: =SUM(I195:I377)/183 -> 82.131148 | J378: =SUM(J195:J377)/183 -> 8.7868852 | ... L378: =SUM(L195:L377)/183 -> 41.825137 | M378: =SUM(M195:M377)/COUNT(M195:M377) -> 0.11836945 | N378: =SUM(N195:N377)/COUNT(N195:N377) -> 0.054590202 | O378: =SUM(O195:O377)/COUNT(O195:O377) -> 0.8852459 | P378: =SUM(P195:P377)/COUNT(P195:P377) -> 1.1571475 | Q378: =SUM(Q195:Q377)/COUNT(Q195:Q377) -> 0.00065972842 | R378: =SUM(M195:Q377)/COUNT(M195:Q377) -> 0.44320255 | S378: =SUM(S195:S377)/COUNT(S195:S377) -> 0.13268319 | T378: =SUM(T195:T377)/COUNT(T195:T377) -> 0.010510363 | U378: =SUM(U195:U377)/COUNT(U195:U377) -> 0.010061437 | V378: =SUM(V195:V377)/COUNT(V195:V377) -> 0.84477927 | W378: =SUM(W195:W377)/COUNT(W195:W377) -> 0.00028637712 | X378: =SUM(S195:W377)/COUNT(S195:W377) -> 0.19966413

Sheet Color classification
B1: image | C1: Pre-alignement | H1: Post-alignement
H2: Random correction | M2: Color classification
A3: 4_filled_cylinder/f_cyl_axis_unal/Col_class | C3: #c78637 | D3: #e3bb37 | E3: #e65a49 | F3: #f08a8c | G3: #ffffff | H3: #c78637 | I3: #e3bb37 | J3: #e65a49 | K3: #f08a8c | L3: #ffffff | M3: #c78637 | N3: #e3bb37 | O3: #e65a49 | P3: #f08a8c | Q3: #ffffff
B4: 0 | C4: 0 | D4: 60 | E4: 0 | F4: 38 | G4: 159902 | H4: 0 | I4: 60 | J4: =0 -> 0 | K4: 38 | L4: 159902 | M4: 0 | N4: 60 | O4: 0 | P4: 38 | Q4: 159902
B5: 1 | C5: 0 | D5: 272 | E5: 0 | F5: 0 | G5: 159728 | H5: 0 | I5: 254 | J5: =0 -> 0 | K5: 0 | L5: 159746 | M5: 0 | N5: 268 | O5: 0 | P5: 4 | Q5: 159728
B6: 2 | C6: 0 | D6: 502 | E6: 0 | F6: 40 | G6: 159458 | H6: 0 | I6: 517 | J6: =0 -> 0 | K6: 1 | L6: 159482 | M6: 0 | N6: 497 | O6: 0 | P6: 45 | Q6: 159458
B7: 3 | C7: 0 | D7: 830 | E7: 0 | F7: 0 | G7: 159170 | H7: 0 | I7: 815 | J7: =0 -> 0 | K7: 0 | L7: 159185 | M7: 0 | N7: 813 | O7: 0 | P7: 26 | Q7: 159161
B8: 4 | C8: 0 | D8: 1176 | E8: 0 | F8: 0 | G8: 158824 | H8: 0 | I8: 1171 | J8: =0 -> 0 | K8: 0 | L8: 158829 | M8: 0 | N8: 1157 | O8: 0 | P8: 30 | Q8: 158813
B9: 5 | C9: 0 | D9: 1559 | E9: 0 | F9: 0 | G9: 158441 | H9: 0 | I9: 1550 | J9: =0 -> 0 | K9: 0 | L9: 158450 | M9: 0 | N9: 1531 | O9: 0 | P9: 39 | Q9: 158430
B10: 6 | C10: 0 | D10: 1976 | E10: 0 | F10: 0 | G10: 158024 | H10: 0 | I10: 1956 | J10: =0 -> 0 | K10: 0 | L10: 158044 | M10: 0 | N10: 1942 | O10: 0 | P10: 63 | Q10: 157995
B11: 7 | C11: 0 | D11: 2419 | E11: 0 | F11: 0 | G11: 157581 | H11: 0 | I11: 2392 | J11: =0 -> 0 | K11: 0 | L11: 157608 | M11: 0 | N11: 2389 | O11: 0 | P11: 49 | Q11: 157562
B12: 8 | C12: 0 | D12: 2865 | E12: 0 | F12: 52 | G12: 157083 | H12: 0 | I12: 2878 | J12: =0 -> 0 | K12: 0 | L12: 157122 | M12: 0 | N12: 2845 | O12: 0 | P12: 88 | Q12: 157067
B13: 9 | C13: 0 | D13: 3394 | E13: 0 | F13: 0 | G13: 156606 | H13: 0 | I13: 3350 | J13: =0 -> 0 | K13: 0 | L13: 156650 | M13: 0 | N13: 3359 | O13: 0 | P13: 53 | Q13: 156588
B14: 10 | C14: 0 | D14: 3884 | E14: 0 | F14: 61 | G14: 156055 | H14: 0 | I14: 3895 | J14: =0 -> 0 | K14: 0 | L14: 156105 | M14: 0 | N14: 3849 | O14: 0 | P14: 111 | Q14: 156040
B15: 11 | C15: 0 | D15: 4428 | E15: 0 | F15: 44 | G15: 155528 | H15: 0 | I15: 4419 | J15: =0 -> 0 | K15: 0 | L15: 155581 | M15: 0 | N15: 4391 | O15: 0 | P15: 96 | Q15: 155513
... B186: 182 | C186: 0 | D186: 79 | E186: 0 | F186: 0 | G186: 159921 | H186: 0 | I186: 80 | J186: =0 -> 0 | K186: 0 | L186: 159920 | M186: 0 | N186: 73 | O186: 0 | P186: 9 | Q186: 159918
B187: Total | C187: =SUM(C4:C186) -> 243709 | D187: =SUM(D4:D186) -> 1874251 | E187: =SUM(E4:E186) -> 103741 | F187: =SUM(F4:F186) -> 53441 | G187: =SUM(G4:G186) -> 27004858 | H187: =SUM(H4:H186) -> 240950 | I187: =SUM(I4:I186) -> 1984977 | J187: =SUM(J4:J186) -> 0 | ... Q187: =SUM(Q4:Q186) -> 27000142
B192: image | C192: Absolute Error | M192: SMAPE
C193: Random correction | H193: Color classification | M193: Random correction | S193: Color classification
A194: 4_filled_cylinder/f_cyl_axis_unal/Col_clust | C194: #c78637 | D194: #e3bb37 | E194: #e65a49 | F194: #f08a8c | G194: #ffffff | H194: #c78637 | I194: #e3bb37 | J194: #e65a49 | K194: #f08a8c | L194: #ffffff | M194: #c78637 | N194: #e3bb37 | O194: #e65a49 | P194: #f08a8c | Q194: #ffffff | S194: #c78637 | T194: #e3bb37 | U194: #e65a49 | V194: #f08a8c | W194: #ffffff
B195: 0 | C195: =ABS(H4-C4) -> 0 | D195: =ABS(I4-D4) -> 0 | E195: =ABS(J4-E4) -> 0 | F195: =ABS(K4-F4) -> 0 | G195: =ABS(L4-G4) -> 0 | H195: =ABS(M4-C4) -> 0 | I195: =ABS(N4-D4) -> 0 | J195: =ABS(O4-E4) -> 0 | K195: =ABS(P4-F4) -> 0 | L195: =ABS(Q4-G4) -> 0 | M195: =IF(AND(C4=0,H4=0), 0, ABS(C4-H4)/((ABS(C4)+ABS(H4))/2)) -> 0 | N195: =IF(AND(D4=0,I4=0), 0, ABS(D4-I4)/((ABS(D4)+ABS(I4))/2)) -> 0 | O195: =IF(AND(E4=0,J4=0), 0, ABS(E4-J4)/((ABS(E4)+ABS(J4))/2)) -> 0 | P195: =IF(AND(F4=0,K4=0), 0, ABS(F4-K4)/((ABS(F4)+ABS(K4))/2)) -> 0 | Q195: =IF(AND(G4=0,L4=0), 0, ABS(G4-L4)/((ABS(G4)+ABS(L4))/2)) -> 0 | S195: =IF(AND(C4=0,M4=0), 0, ABS(C4-M4)/((ABS(C4)+ABS(M4))/2)) -> 0 | T195: =IF(AND(D4=0,N4=0), 0, ABS(D4-N4)/((ABS(D4)+ABS(N4))/2)) -> 0 | U195: =IF(AND(E4=0,O4=0), 0, ABS(E4-O4)/((ABS(E4)+ABS(O4))/2)) -> 0 | V195: =IF(AND(F4=0,P4=0), 0, ABS(F4-P4)/((ABS(F4)+ABS(P4))/2)) -> 0 | W195: =IF(AND(G4=0,Q4=0), 0, ABS(G4-Q4)/((ABS(G4)+ABS(Q4))/2)) -> 0
B196: 1 | C196: =ABS(H5-C5) -> 0 | D196: =ABS(I5-D5) -> 18 | E196: =ABS(J5-E5) -> 0 | F196: =ABS(K5-F5) -> 0 | G196: =ABS(L5-G5) -> 18 | H196: =ABS(M5-C5) -> 0 | I196: =ABS(N5-D5) -> 4 | J196: =ABS(O5-E5) -> 0 | K196: =ABS(P5-F5) -> 4 | L196: =ABS(Q5-G5) -> 0 | M196: =IF(AND(C5=0,H5=0), 0, ABS(C5-H5)/((ABS(C5)+ABS(H5))/2)) -> 0 | N196: =IF(AND(D5=0,I5=0), 0, ABS(D5-I5)/((ABS(D5)+ABS(I5))/2)) -> 0.068441065 | O196: =IF(AND(E5=0,J5=0), 0, ABS(E5-J5)/((ABS(E5)+ABS(J5))/2)) -> 0 | P196: =IF(AND(F5=0,K5=0), 0, ABS(F5-K5)/((ABS(F5)+ABS(K5))/2)) -> 0 | Q196: =IF(AND(G5=0,L5=0), 0, ABS(G5-L5)/((ABS(G5)+ABS(L5))/2)) -> 0.00011268523 | S196: =IF(AND(C5=0,M5=0), 0, ABS(C5-M5)/((ABS(C5)+ABS(M5))/2)) -> 0 | T196: =IF(AND(D5=0,N5=0), 0, ABS(D5-N5)/((ABS(D5)+ABS(N5))/2)) -> 0.014814815 | U196: =IF(AND(E5=0,O5=0), 0, ABS(E5-O5)/((ABS(E5)+ABS(O5))/2)) -> 0 | V196: =IF(AND(F5=0,P5=0), 0, ABS(F5-P5)/((ABS(F5)+ABS(P5))/2)) -> 2 | W196: =IF(AND(G5=0,Q5=0), 0, ABS(G5-Q5)/((ABS(G5)+ABS(Q5))/2)) -> 0
B197: 2 | C197: =ABS(H6-C6) -> 0 | D197: =ABS(I6-D6) -> 15 | E197: =ABS(J6-E6) -> 0 | F197: =ABS(K6-F6) -> 39 | G197: =ABS(L6-G6) -> 24 | H197: =ABS(M6-C6) -> 0 | I197: =ABS(N6-D6) -> 5 | J197: =ABS(O6-E6) -> 0 | K197: =ABS(P6-F6) -> 5 | L197: =ABS(Q6-G6) -> 0 | M197: =IF(AND(C6=0,H6=0), 0, ABS(C6-H6)/((ABS(C6)+ABS(H6))/2)) -> 0 | N197: =IF(AND(D6=0,I6=0), 0, ABS(D6-I6)/((ABS(D6)+ABS(I6))/2)) -> 0.029440628 | O197: =IF(AND(E6=0,J6=0), 0, ABS(E6-J6)/((ABS(E6)+ABS(J6))/2)) -> 0 | P197: =IF(AND(F6=0,K6=0), 0, ABS(F6-K6)/((ABS(F6)+ABS(K6))/2)) -> 1.902439 | Q197: =IF(AND(G6=0,L6=0), 0, ABS(G6-L6)/((ABS(G6)+ABS(L6))/2)) -> 0.00015049853 | S197: =IF(AND(C6=0,M6=0), 0, ABS(C6-M6)/((ABS(C6)+ABS(M6))/2)) -> 0 | T197: =IF(AND(D6=0,N6=0), 0, ABS(D6-N6)/((ABS(D6)+ABS(N6))/2)) -> 0.01001001 | U197: =IF(AND(E6=0,O6=0), 0, ABS(E6-O6)/((ABS(E6)+ABS(O6))/2)) -> 0 | V197: =IF(AND(F6=0,P6=0), 0, ABS(F6-P6)/((ABS(F6)+ABS(P6))/2)) -> 0.11764706 | W197: =IF(AND(G6=0,Q6=0), 0, ABS(G6-Q6)/((ABS(G6)+ABS(Q6))/2)) -> 0
B198: 3 | C198: =ABS(H7-C7) -> 0 | D198: =ABS(I7-D7) -> 15 | E198: =ABS(J7-E7) -> 0 | F198: =ABS(K7-F7) -> 0 | G198: =ABS(L7-G7) -> 15 | H198: =ABS(M7-C7) -> 0 | I198: =ABS(N7-D7) -> 17 | J198: =ABS(O7-E7) -> 0 | K198: =ABS(P7-F7) -> 26 | L198: =ABS(Q7-G7) -> 9 | M198: =IF(AND(C7=0,H7=0), 0, ABS(C7-H7)/((ABS(C7)+ABS(H7))/2)) -> 0 | N198: =IF(AND(D7=0,I7=0), 0, ABS(D7-I7)/((ABS(D7)+ABS(I7))/2)) -> 0.018237082 | O198: =IF(AND(E7=0,J7=0), 0, ABS(E7-J7)/((ABS(E7)+ABS(J7))/2)) -> 0 | P198: =IF(AND(F7=0,K7=0), 0, ABS(F7-K7)/((ABS(F7)+ABS(K7))/2)) -> 0 | Q198: =IF(AND(G7=0,L7=0), 0, ABS(G7-L7)/((ABS(G7)+ABS(L7))/2)) -> 9.4234424e-05 | S198: =IF(AND(C7=0,M7=0), 0, ABS(C7-M7)/((ABS(C7)+ABS(M7))/2)) -> 0 | T198: =IF(AND(D7=0,N7=0), 0, ABS(D7-N7)/((ABS(D7)+ABS(N7))/2)) -> 0.020693853 | U198: =IF(AND(E7=0,O7=0), 0, ABS(E7-O7)/((ABS(E7)+ABS(O7))/2)) -> 0 | V198: =IF(AND(F7=0,P7=0), 0, ABS(F7-P7)/((ABS(F7)+ABS(P7))/2)) -> 2 | W198: =IF(AND(G7=0,Q7=0), 0, ABS(G7-Q7)/((ABS(G7)+ABS(Q7))/2)) -> 5.6544917e-05
B199: 4 | C199: =ABS(H8-C8) -> 0 | D199: =ABS(I8-D8) -> 5 | E199: =ABS(J8-E8) -> 0 | F199: =ABS(K8-F8) -> 0 | G199: =ABS(L8-G8) -> 5 | H199: =ABS(M8-C8) -> 0 | I199: =ABS(N8-D8) -> 19 | J199: =ABS(O8-E8) -> 0 | K199: =ABS(P8-F8) -> 30 | L199: =ABS(Q8-G8) -> 11 | M199: =IF(AND(C8=0,H8=0), 0, ABS(C8-H8)/((ABS(C8)+ABS(H8))/2)) -> 0 | N199: =IF(AND(D8=0,I8=0), 0, ABS(D8-I8)/((ABS(D8)+ABS(I8))/2)) -> 0.0042607584 | O199: =IF(AND(E8=0,J8=0), 0, ABS(E8-J8)/((ABS(E8)+ABS(J8))/2)) -> 0 | P199: =IF(AND(F8=0,K8=0), 0, ABS(F8-K8)/((ABS(F8)+ABS(K8))/2)) -> 0 | Q199: =IF(AND(G8=0,L8=0), 0, ABS(G8-L8)/((ABS(G8)+ABS(L8))/2)) -> 3.1480893e-05 | S199: =IF(AND(C8=0,M8=0), 0, ABS(C8-M8)/((ABS(C8)+ABS(M8))/2)) -> 0 | T199: =IF(AND(D8=0,N8=0), 0, ABS(D8-N8)/((ABS(D8)+ABS(N8))/2)) -> 0.016288041 | U199: =IF(AND(E8=0,O8=0), 0, ABS(E8-O8)/((ABS(E8)+ABS(O8))/2)) -> 0 | V199: =IF(AND(F8=0,P8=0), 0, ABS(F8-P8)/((ABS(F8)+ABS(P8))/2)) -> 2 | W199: =IF(AND(G8=0,Q8=0), 0, ABS(G8-Q8)/((ABS(G8)+ABS(Q8))/2)) -> 6.9261453e-05
B200: 5 | C200: =ABS(H9-C9) -> 0 | D200: =ABS(I9-D9) -> 9 | E200: =ABS(J9-E9) -> 0 | F200: =ABS(K9-F9) -> 0 | G200: =ABS(L9-G9) -> 9 | H200: =ABS(M9-C9) -> 0 | I200: =ABS(N9-D9) -> 28 | J200: =ABS(O9-E9) -> 0 | K200: =ABS(P9-F9) -> 39 | L200: =ABS(Q9-G9) -> 11 | M200: =IF(AND(C9=0,H9=0), 0, ABS(C9-H9)/((ABS(C9)+ABS(H9))/2)) -> 0 | N200: =IF(AND(D9=0,I9=0), 0, ABS(D9-I9)/((ABS(D9)+ABS(I9))/2)) -> 0.005789643 | O200: =IF(AND(E9=0,J9=0), 0, ABS(E9-J9)/((ABS(E9)+ABS(J9))/2)) -> 0 | P200: =IF(AND(F9=0,K9=0), 0, ABS(F9-K9)/((ABS(F9)+ABS(K9))/2)) -> 0 | Q200: =IF(AND(G9=0,L9=0), 0, ABS(G9-L9)/((ABS(G9)+ABS(L9))/2)) -> 5.6801866e-05 | S200: =IF(AND(C9=0,M9=0), 0, ABS(C9-M9)/((ABS(C9)+ABS(M9))/2)) -> 0 | T200: =IF(AND(D9=0,N9=0), 0, ABS(D9-N9)/((ABS(D9)+ABS(N9))/2)) -> 0.018122977 | U200: =IF(AND(E9=0,O9=0), 0, ABS(E9-O9)/((ABS(E9)+ABS(O9))/2)) -> 0 | V200: =IF(AND(F9=0,P9=0), 0, ABS(F9-P9)/((ABS(F9)+ABS(P9))/2)) -> 2 | W200: =IF(AND(G9=0,Q9=0), 0, ABS(G9-Q9)/((ABS(G9)+ABS(Q9))/2)) -> 6.9428884e-05
B201: 6 | C201: =ABS(H10-C10) -> 0 | D201: =ABS(I10-D10) -> 20 | E201: =ABS(J10-E10) -> 0 | F201: =ABS(K10-F10) -> 0 | G201: =ABS(L10-G10) -> 20 | H201: =ABS(M10-C10) -> 0 | I201: =ABS(N10-D10) -> 34 | J201: =ABS(O10-E10) -> 0 | K201: =ABS(P10-F10) -> 63 | L201: =ABS(Q10-G10) -> 29 | M201: =IF(AND(C10=0,H10=0), 0, ABS(C10-H10)/((ABS(C10)+ABS(H10))/2)) -> 0 | N201: =IF(AND(D10=0,I10=0), 0, ABS(D10-I10)/((ABS(D10)+ABS(I10))/2)) -> 0.01017294 | O201: =IF(AND(E10=0,J10=0), 0, ABS(E10-J10)/((ABS(E10)+ABS(J10))/2)) -> 0 | P201: =IF(AND(F10=0,K10=0), 0, ABS(F10-K10)/((ABS(F10)+ABS(K10))/2)) -> 0 | Q201: =IF(AND(G10=0,L10=0), 0, ABS(G10-L10)/((ABS(G10)+ABS(L10))/2)) -> 0.00012655505 | S201: =IF(AND(C10=0,M10=0), 0, ABS(C10-M10)/((ABS(C10)+ABS(M10))/2)) -> 0 | T201: =IF(AND(D10=0,N10=0), 0, ABS(D10-N10)/((ABS(D10)+ABS(N10))/2)) -> 0.017355794 | U201: =IF(AND(E10=0,O10=0), 0, ABS(E10-O10)/((ABS(E10)+ABS(O10))/2)) -> 0 | V201: =IF(AND(F10=0,P10=0), 0, ABS(F10-P10)/((ABS(F10)+ABS(P10))/2)) -> 2 | W201: =IF(AND(G10=0,Q10=0), 0, ABS(G10-Q10)/((ABS(G10)+ABS(Q10))/2)) -> 0.00018353327
B202: 7 | C202: =ABS(H11-C11) -> 0 | D202: =ABS(I11-D11) -> 27 | E202: =ABS(J11-E11) -> 0 | F202: =ABS(K11-F11) -> 0 | G202: =ABS(L11-G11) -> 27 | H202: =ABS(M11-C11) -> 0 | I202: =ABS(N11-D11) -> 30 | J202: =ABS(O11-E11) -> 0 | K202: =ABS(P11-F11) -> 49 | L202: =ABS(Q11-G11) -> 19 | M202: =IF(AND(C11=0,H11=0), 0, ABS(C11-H11)/((ABS(C11)+ABS(H11))/2)) -> 0 | N202: =IF(AND(D11=0,I11=0), 0, ABS(D11-I11)/((ABS(D11)+ABS(I11))/2)) -> 0.011224278 | O202: =IF(AND(E11=0,J11=0), 0, ABS(E11-J11)/((ABS(E11)+ABS(J11))/2)) -> 0 | P202: =IF(AND(F11=0,K11=0), 0, ABS(F11-K11)/((ABS(F11)+ABS(K11))/2)) -> 0 | Q202: =IF(AND(G11=0,L11=0), 0, ABS(G11-L11)/((ABS(G11)+ABS(L11))/2)) -> 0.00017132578 | S202: =IF(AND(C11=0,M11=0), 0, ABS(C11-M11)/((ABS(C11)+ABS(M11))/2)) -> 0 | T202: =IF(AND(D11=0,N11=0), 0, ABS(D11-N11)/((ABS(D11)+ABS(N11))/2)) -> 0.012479201 | U202: =IF(AND(E11=0,O11=0), 0, ABS(E11-O11)/((ABS(E11)+ABS(O11))/2)) -> 0 | V202: =IF(AND(F11=0,P11=0), 0, ABS(F11-P11)/((ABS(F11)+ABS(P11))/2)) -> 2 | W202: =IF(AND(G11=0,Q11=0), 0, ABS(G11-Q11)/((ABS(G11)+ABS(Q11))/2)) -> 0.00012058018
B203: 8 | C203: =ABS(H12-C12) -> 0 | D203: =ABS(I12-D12) -> 13 | E203: =ABS(J12-E12) -> 0 | F203: =ABS(K12-F12) -> 52 | G203: =ABS(L12-G12) -> 39 | H203: =ABS(M12-C12) -> 0 | I203: =ABS(N12-D12) -> 20 | J203: =ABS(O12-E12) -> 0 | K203: =ABS(P12-F12) -> 36 | L203: =ABS(Q12-G12) -> 16 | M203: =IF(AND(C12=0,H12=0), 0, ABS(C12-H12)/((ABS(C12)+ABS(H12))/2)) -> 0 | N203: =IF(AND(D12=0,I12=0), 0, ABS(D12-I12)/((ABS(D12)+ABS(I12))/2)) -> 0.0045272506 | O203: =IF(AND(E12=0,J12=0), 0, ABS(E12-J12)/((ABS(E12)+ABS(J12))/2)) -> 0 | P203: =IF(AND(F12=0,K12=0), 0, ABS(F12-K12)/((ABS(F12)+ABS(K12))/2)) -> 2 | Q203: =IF(AND(G12=0,L12=0), 0, ABS(G12-L12)/((ABS(G12)+ABS(L12))/2)) -> 0.00024824557 | S203: =IF(AND(C12=0,M12=0), 0, ABS(C12-M12)/((ABS(C12)+ABS(M12))/2)) -> 0 | T203: =IF(AND(D12=0,N12=0), 0, ABS(D12-N12)/((ABS(D12)+ABS(N12))/2)) -> 0.0070052539 | U203: =IF(AND(E12=0,O12=0), 0, ABS(E12-O12)/((ABS(E12)+ABS(O12))/2)) -> 0 | V203: =IF(AND(F12=0,P12=0), 0, ABS(F12-P12)/((ABS(F12)+ABS(P12))/2)) -> 0.51428571 | W203: =IF(AND(G12=0,Q12=0), 0, ABS(G12-Q12)/((ABS(G12)+ABS(Q12))/2)) -> 0.00010186217
B204: 9 | C204: =ABS(H13-C13) -> 0 | D204: =ABS(I13-D13) -> 44 | E204: =ABS(J13-E13) -> 0 | F204: =ABS(K13-F13) -> 0 | G204: =ABS(L13-G13) -> 44 | H204: =ABS(M13-C13) -> 0 | I204: =ABS(N13-D13) -> 35 | J204: =ABS(O13-E13) -> 0 | K204: =ABS(P13-F13) -> 53 | L204: =ABS(Q13-G13) -> 18 | M204: =IF(AND(C13=0,H13=0), 0, ABS(C13-H13)/((ABS(C13)+ABS(H13))/2)) -> 0 | N204: =IF(AND(D13=0,I13=0), 0, ABS(D13-I13)/((ABS(D13)+ABS(I13))/2)) -> 0.013048636 | O204: =IF(AND(E13=0,J13=0), 0, ABS(E13-J13)/((ABS(E13)+ABS(J13))/2)) -> 0 | P204: =IF(AND(F13=0,K13=0), 0, ABS(F13-K13)/((ABS(F13)+ABS(K13))/2)) -> 0 | Q204: =IF(AND(G13=0,L13=0), 0, ABS(G13-L13)/((ABS(G13)+ABS(L13))/2)) -> 0.0002809204 | S204: =IF(AND(C13=0,M13=0), 0, ABS(C13-M13)/((ABS(C13)+ABS(M13))/2)) -> 0 | T204: =IF(AND(D13=0,N13=0), 0, ABS(D13-N13)/((ABS(D13)+ABS(N13))/2)) -> 0.010365763 | U204: =IF(AND(E13=0,O13=0), 0, ABS(E13-O13)/((ABS(E13)+ABS(O13))/2)) -> 0 | V204: =IF(AND(F13=0,P13=0), 0, ABS(F13-P13)/((ABS(F13)+ABS(P13))/2)) -> 2 | W204: =IF(AND(G13=0,Q13=0), 0, ABS(G13-Q13)/((ABS(G13)+ABS(Q13))/2)) -> 0.00011494473
B205: 10 | C205: =ABS(H14-C14) -> 0 | D205: =ABS(I14-D14) -> 11 | E205: =ABS(J14-E14) -> 0 | F205: =ABS(K14-F14) -> 61 | G205: =ABS(L14-G14) -> 50 | H205: =ABS(M14-C14) -> 0 | I205: =ABS(N14-D14) -> 35 | J205: =ABS(O14-E14) -> 0 | K205: =ABS(P14-F14) -> 50 | L205: =ABS(Q14-G14) -> 15 | M205: =IF(AND(C14=0,H14=0), 0, ABS(C14-H14)/((ABS(C14)+ABS(H14))/2)) -> 0 | N205: =IF(AND(D14=0,I14=0), 0, ABS(D14-I14)/((ABS(D14)+ABS(I14))/2)) -> 0.002828127 | O205: =IF(AND(E14=0,J14=0), 0, ABS(E14-J14)/((ABS(E14)+ABS(J14))/2)) -> 0 | P205: =IF(AND(F14=0,K14=0), 0, ABS(F14-K14)/((ABS(F14)+ABS(K14))/2)) -> 2 | Q205: =IF(AND(G14=0,L14=0), 0, ABS(G14-L14)/((ABS(G14)+ABS(L14))/2)) -> 0.00032034854 | S205: =IF(AND(C14=0,M14=0), 0, ABS(C14-M14)/((ABS(C14)+ABS(M14))/2)) -> 0 | T205: =IF(AND(D14=0,N14=0), 0, ABS(D14-N14)/((ABS(D14)+ABS(N14))/2)) -> 0.0090521143 | U205: =IF(AND(E14=0,O14=0), 0, ABS(E14-O14)/((ABS(E14)+ABS(O14))/2)) -> 0 | V205: =IF(AND(F14=0,P14=0), 0, ABS(F14-P14)/((ABS(F14)+ABS(P14))/2)) -> 0.58139535 | W205: =IF(AND(G14=0,Q14=0), 0, ABS(G14-Q14)/((ABS(G14)+ABS(Q14))/2)) -> 9.6124577e-05
B206: 11 | C206: =ABS(H15-C15) -> 0 | D206: =ABS(I15-D15) -> 9 | E206: =ABS(J15-E15) -> 0 | F206: =ABS(K15-F15) -> 44 | G206: =ABS(L15-G15) -> 53 | H206: =ABS(M15-C15) -> 0 | I206: =ABS(N15-D15) -> 37 | J206: =ABS(O15-E15) -> 0 | K206: =ABS(P15-F15) -> 52 | L206: =ABS(Q15-G15) -> 15 | M206: =IF(AND(C15=0,H15=0), 0, ABS(C15-H15)/((ABS(C15)+ABS(H15))/2)) -> 0 | N206: =IF(AND(D15=0,I15=0), 0, ABS(D15-I15)/((ABS(D15)+ABS(I15))/2)) -> 0.002034588 | O206: =IF(AND(E15=0,J15=0), 0, ABS(E15-J15)/((ABS(E15)+ABS(J15))/2)) -> 0 | P206: =IF(AND(F15=0,K15=0), 0, ABS(F15-K15)/((ABS(F15)+ABS(K15))/2)) -> 2 | Q206: =IF(AND(G15=0,L15=0), 0, ABS(G15-L15)/((ABS(G15)+ABS(L15))/2)) -> 0.0003407166 | S206: =IF(AND(C15=0,M15=0), 0, ABS(C15-M15)/((ABS(C15)+ABS(M15))/2)) -> 0 | T206: =IF(AND(D15=0,N15=0), 0, ABS(D15-N15)/((ABS(D15)+ABS(N15))/2)) -> 0.008390974 | U206: =IF(AND(E15=0,O15=0), 0, ABS(E15-O15)/((ABS(E15)+ABS(O15))/2)) -> 0 | V206: =IF(AND(F15=0,P15=0), 0, ABS(F15-P15)/((ABS(F15)+ABS(P15))/2)) -> 0.74285714 | W206: =IF(AND(G15=0,Q15=0), 0, ABS(G15-Q15)/((ABS(G15)+ABS(Q15))/2)) -> 9.6450307e-05
... B376: 181 | C376: =ABS(H185-C185) -> 0 | D376: =ABS(I185-D185) -> 13 | E376: =ABS(J185-E185) -> 0 | F376: =ABS(K185-F185) -> 0 | G376: =ABS(L185-G185) -> 13 | H376: =ABS(M185-C185) -> 0 | I376: =ABS(N185-D185) -> 12 | J376: =ABS(O185-E185) -> 0 | K376: =ABS(P185-F185) -> 15 | L376: =ABS(Q185-G185) -> 3 | M376: =IF(AND(C185=0,H185=0), 0, ABS(C185-H185)/((ABS(C185)+ABS(H185))/2)) -> 0 | N376: =IF(AND(D185=0,I185=0), 0, ABS(D185-I185)/((ABS(D185)+ABS(I185))/2)) -> 0.048964218 | O376: =IF(AND(E185=0,J185=0), 0, ABS(E185-J185)/((ABS(E185)+ABS(J185))/2)) -> 0 | P376: =IF(AND(F185=0,K185=0), 0, ABS(F185-K185)/((ABS(F185)+ABS(K185))/2)) -> 0 | Q376: =IF(AND(G185=0,L185=0), 0, ABS(G185-L185)/((ABS(G185)+ABS(L185))/2)) -> 8.1385048e-05 | S376: =IF(AND(C185=0,M185=0), 0, ABS(C185-M185)/((ABS(C185)+ABS(M185))/2)) -> 0 | T376: =IF(AND(D185=0,N185=0), 0, ABS(D185-N185)/((ABS(D185)+ABS(N185))/2)) -> 0.045112782 | U376: =IF(AND(E185=0,O185=0), 0, ABS(E185-O185)/((ABS(E185)+ABS(O185))/2)) -> 0 | V376: =IF(AND(F185=0,P185=0), 0, ABS(F185-P185)/((ABS(F185)+ABS(P185))/2)) -> 2 | W376: =IF(AND(G185=0,Q185=0), 0, ABS(G185-Q185)/((ABS(G185)+ABS(Q185))/2)) -> 1.8782106e-05
B377: 182 | C377: =ABS(H186-C186) -> 0 | D377: =ABS(I186-D186) -> 1 | E377: =ABS(J186-E186) -> 0 | F377: =ABS(K186-F186) -> 0 | G377: =ABS(L186-G186) -> 1 | H377: =ABS(M186-C186) -> 0 | I377: =ABS(N186-D186) -> 6 | J377: =ABS(O186-E186) -> 0 | K377: =ABS(P186-F186) -> 9 | L377: =ABS(Q186-G186) -> 3 | M377: =IF(AND(C186=0,H186=0), 0, ABS(C186-H186)/((ABS(C186)+ABS(H186))/2)) -> 0 | N377: =IF(AND(D186=0,I186=0), 0, ABS(D186-I186)/((ABS(D186)+ABS(I186))/2)) -> 0.012578616 | O377: =IF(AND(E186=0,J186=0), 0, ABS(E186-J186)/((ABS(E186)+ABS(J186))/2)) -> 0 | P377: =IF(AND(F186=0,K186=0), 0, ABS(F186-K186)/((ABS(F186)+ABS(K186))/2)) -> 0 | Q377: =IF(AND(G186=0,L186=0), 0, ABS(G186-L186)/((ABS(G186)+ABS(L186))/2)) -> 6.253107e-06 | R377: SMAPE | S377: =IF(AND(C186=0,M186=0), 0, ABS(C186-M186)/((ABS(C186)+ABS(M186))/2)) -> 0 | T377: =IF(AND(D186=0,N186=0), 0, ABS(D186-N186)/((ABS(D186)+ABS(N186))/2)) -> 0.078947368 | U377: =IF(AND(E186=0,O186=0), 0, ABS(E186-O186)/((ABS(E186)+ABS(O186))/2)) -> 0 | V377: =IF(AND(F186=0,P186=0), 0, ABS(F186-P186)/((ABS(F186)+ABS(P186))/2)) -> 2 | W377: =IF(AND(G186=0,Q186=0), 0, ABS(G186-Q186)/((ABS(G186)+ABS(Q186))/2)) -> 1.8759438e-05 | X377: SMAPE
B378: Total | C378: =SUM(C195:C377)/183 -> 19.196721 | D378: =SUM(D195:D377)/183 -> 612.98361 | E378: =SUM(E195:E377)/183 -> 566.89071 | F378: =SUM(F195:F377)/183 -> 78.726776 | G378: =SUM(G195:G377)/183 -> 55.775956 | H378: =SUM(H195:H377)/183 -> 17.273224 | I378: =SUM(I195:I377)/183 -> 60.79235 | J378: =SUM(J195:J377)/183 -> 8.6721311 | ... L378: =SUM(L195:L377)/183 -> 25.79235 | M378: =SUM(M195:M377)/COUNT(M195:M377) -> 0.12353668 | N378: =SUM(N195:N377)/COUNT(N195:N377) -> 0.051963873 | O378: =SUM(O195:O377)/COUNT(O195:O377) -> 0.8852459 | P378: =SUM(P195:P377)/COUNT(P195:P377) -> 0.98399001 | Q378: =SUM(Q195:Q377)/COUNT(Q195:Q377) -> 0.00038205259 | R378: =SUM(M195:Q377)/COUNT(M195:Q377) -> 0.4090237 | S378: =SUM(S195:S377)/COUNT(S195:S377) -> 0.1326169 | T378: =SUM(T195:T377)/COUNT(T195:T377) -> 0.0072891988 | U378: =SUM(U195:U377)/COUNT(U195:U377) -> 0.015165885 | V378: =SUM(V195:V377)/COUNT(V195:V377) -> 1.0071437 | W378: =SUM(W195:W377)/COUNT(W195:W377) -> 0.00017657501 | X378: =SUM(S195:W377)/COUNT(S195:W377) -> 0.23247845

Sheet Comparison with original
B1: image | C1: Original | H1: Clustering | R1: Classification
H2: Random correction | M2: Color classification | R2: Random correction | W2: Color classification
A3: 4_filled_cylinder/f_cyl_axis_unal | C3: #c78637 | D3: #e3bb37 | E3: #e65a49 | F3: #f08a8c | G3: #ffffff | H3: #c88637 | I3: #e3bb37 | J3: #e65a49 | K3: #efab8c | L3: #fdfdfd | M3: #c88637 | N3: #e3bb37 | O3: #e65a49 | P3: #efab8c | Q3: #fdfdfd | R3: #c78637 | S3: #e3bb37 | T3: #e65a49 | U3: #f08a8c | V3: #ffffff | W3: #c78637 | X3: #e3bb37 | Y3: #e65a49 | Z3: #f08a8c | AA3: #ffffff
B4: 0 | C4: 0 | D4: 79 | E4: 0 | F4: 0 | G4: 159921 | H4: ='Color clustering'!H4 -> 0 | I4: ='Color clustering'!I4 -> 60 | J4: ='Color clustering'!J4 -> 0 | K4: ='Color clustering'!K4 -> 38 | L4: ='Color clustering'!L4 -> 159902 | M4: ='Color clustering'!M4 -> 0 | N4: ='Color clustering'!N4 -> 60 | O4: ='Color clustering'!O4 -> 0 | ... Q4: ='Color clustering'!Q4 -> 159902 | R4: ='Color classification'!H4 -> 0 | S4: ='Color classification'!I4 -> 60 | T4: ='Color classification'!J4 -> 0 | U4: ='Color classification'!K4 -> 38 | V4: ='Color classification'!L4 -> 159902 | W4: ='Color classification'!M4 -> 0 | X4: ='Color classification'!N4 -> 60 | Y4: ='Color classification'!O4 -> 0 | ... AA4: ='Color classification'!Q4 -> 159902
B5: 1 | C5: 0 | D5: 272 | E5: 0 | F5: 0 | G5: 159728 | H5: ='Color clustering'!H5 -> 0 | I5: ='Color clustering'!I5 -> 259 | J5: ='Color clustering'!J5 -> 0 | K5: ='Color clustering'!K5 -> 0 | L5: ='Color clustering'!L5 -> 159741 | M5: ='Color clustering'!M5 -> 0 | N5: ='Color clustering'!N5 -> 259 | O5: ='Color clustering'!O5 -> 0 | ... Q5: ='Color clustering'!Q5 -> 159726 | R5: ='Color classification'!H5 -> 0 | S5: ='Color classification'!I5 -> 254 | T5: ='Color classification'!J5 -> 0 | U5: ='Color classification'!K5 -> 0 | V5: ='Color classification'!L5 -> 159746 | W5: ='Color classification'!M5 -> 0 | X5: ='Color classification'!N5 -> 268 | Y5: ='Color classification'!O5 -> 0 | ... AA5: ='Color classification'!Q5 -> 159728
B6: 2 | C6: 0 | D6: 529 | E6: 0 | F6: 0 | G6: 159471 | H6: ='Color clustering'!H6 -> 0 | I6: ='Color clustering'!I6 -> 492 | J6: ='Color clustering'!J6 -> 0 | K6: ='Color clustering'!K6 -> 0 | L6: ='Color clustering'!L6 -> 159508 | M6: ='Color clustering'!M6 -> 0 | N6: ='Color clustering'!N6 -> 479 | O6: ='Color clustering'!O6 -> 0 | ... Q6: ='Color clustering'!Q6 -> 159438 | R6: ='Color classification'!H6 -> 0 | S6: ='Color classification'!I6 -> 517 | T6: ='Color classification'!J6 -> 0 | U6: ='Color classification'!K6 -> 1 | V6: ='Color classification'!L6 -> 159482 | W6: ='Color classification'!M6 -> 0 | X6: ='Color classification'!N6 -> 497 | Y6: ='Color classification'!O6 -> 0 | ... AA6: ='Color classification'!Q6 -> 159458
B7: 3 | C7: 0 | D7: 830 | E7: 0 | F7: 0 | G7: 159170 | H7: ='Color clustering'!H7 -> 0 | I7: ='Color clustering'!I7 -> 803 | J7: ='Color clustering'!J7 -> 0 | K7: ='Color clustering'!K7 -> 0 | L7: ='Color clustering'!L7 -> 159197 | M7: ='Color clustering'!M7 -> 0 | N7: ='Color clustering'!N7 -> 795 | O7: ='Color clustering'!O7 -> 0 | ... Q7: ='Color clustering'!Q7 -> 159148 | R7: ='Color classification'!H7 -> 0 | S7: ='Color classification'!I7 -> 815 | T7: ='Color classification'!J7 -> 0 | U7: ='Color classification'!K7 -> 0 | V7: ='Color classification'!L7 -> 159185 | W7: ='Color classification'!M7 -> 0 | X7: ='Color classification'!N7 -> 813 | Y7: ='Color classification'!O7 -> 0 | ... AA7: ='Color classification'!Q7 -> 159161
B8: 4 | C8: 0 | D8: 1176 | E8: 0 | F8: 0 | G8: 158824 | H8: ='Color clustering'!H8 -> 0 | I8: ='Color clustering'!I8 -> 1137 | J8: ='Color clustering'!J8 -> 0 | K8: ='Color clustering'!K8 -> 0 | L8: ='Color clustering'!L8 -> 158863 | M8: ='Color clustering'!M8 -> 0 | N8: ='Color clustering'!N8 -> 1117 | O8: ='Color clustering'!O8 -> 0 | ... Q8: ='Color clustering'!Q8 -> 158807 | R8: ='Color classification'!H8 -> 0 | S8: ='Color classification'!I8 -> 1171 | T8: ='Color classification'!J8 -> 0 | U8: ='Color classification'!K8 -> 0 | V8: ='Color classification'!L8 -> 158829 | W8: ='Color classification'!M8 -> 0 | X8: ='Color classification'!N8 -> 1157 | Y8: ='Color classification'!O8 -> 0 | ... AA8: ='Color classification'!Q8 -> 158813
B9: 5 | C9: 0 | D9: 1559 | E9: 0 | F9: 0 | G9: 158441 | H9: ='Color clustering'!H9 -> 0 | I9: ='Color clustering'!I9 -> 1544 | J9: ='Color clustering'!J9 -> 0 | K9: ='Color clustering'!K9 -> 0 | L9: ='Color clustering'!L9 -> 158456 | M9: ='Color clustering'!M9 -> 0 | N9: ='Color clustering'!N9 -> 1512 | O9: ='Color clustering'!O9 -> 0 | ... Q9: ='Color clustering'!Q9 -> 158416 | R9: ='Color classification'!H9 -> 0 | S9: ='Color classification'!I9 -> 1550 | T9: ='Color classification'!J9 -> 0 | U9: ='Color classification'!K9 -> 0 | V9: ='Color classification'!L9 -> 158450 | W9: ='Color classification'!M9 -> 0 | X9: ='Color classification'!N9 -> 1531 | Y9: ='Color classification'!O9 -> 0 | ... AA9: ='Color classification'!Q9 -> 158430
B10: 6 | C10: 0 | D10: 1976 | E10: 0 | F10: 0 | G10: 158024 | H10: ='Color clustering'!H10 -> 0 | I10: ='Color clustering'!I10 -> 1936 | J10: ='Color clustering'!J10 -> 0 | K10: ='Color clustering'!K10 -> 0 | L10: ='Color clustering'!L10 -> 158064 | M10: ='Color clustering'!M10 -> 0 | N10: ='Color clustering'!N10 -> 1891 | O10: ='Color clustering'!O10 -> 0 | ... Q10: ='Color clustering'!Q10 -> 157982 | R10: ='Color classification'!H10 -> 0 | S10: ='Color classification'!I10 -> 1956 | T10: ='Color classification'!J10 -> 0 | U10: ='Color classification'!K10 -> 0 | V10: ='Color classification'!L10 -> 158044 | W10: ='Color classification'!M10 -> 0 | X10: ='Color classification'!N10 -> 1942 | Y10: ='Color classification'!O10 -> 0 | ... AA10: ='Color classification'!Q10 -> 157995
B11: 7 | C11: 0 | D11: 2419 | E11: 0 | F11: 0 | G11: 157581 | H11: ='Color clustering'!H11 -> 0 | I11: ='Color clustering'!I11 -> 2344 | J11: ='Color clustering'!J11 -> 0 | K11: ='Color clustering'!K11 -> 5 | L11: ='Color clustering'!L11 -> 157651 | M11: ='Color clustering'!M11 -> 0 | N11: ='Color clustering'!N11 -> 2324 | O11: ='Color clustering'!O11 -> 0 | ... Q11: ='Color clustering'!Q11 -> 157561 | R11: ='Color classification'!H11 -> 0 | S11: ='Color classification'!I11 -> 2392 | T11: ='Color classification'!J11 -> 0 | U11: ='Color classification'!K11 -> 0 | V11: ='Color classification'!L11 -> 157608 | W11: ='Color classification'!M11 -> 0 | X11: ='Color classification'!N11 -> 2389 | Y11: ='Color classification'!O11 -> 0 | ... AA11: ='Color classification'!Q11 -> 157562
B12: 8 | C12: 0 | D12: 2900 | E12: 0 | F12: 0 | G12: 157100 | H12: ='Color clustering'!H12 -> 0 | I12: ='Color clustering'!I12 -> 2849 | J12: ='Color clustering'!J12 -> 0 | K12: ='Color clustering'!K12 -> 0 | L12: ='Color clustering'!L12 -> 157151 | M12: ='Color clustering'!M12 -> 0 | N12: ='Color clustering'!N12 -> 2809 | O12: ='Color clustering'!O12 -> 0 | ... Q12: ='Color clustering'!Q12 -> 157046 | R12: ='Color classification'!H12 -> 0 | S12: ='Color classification'!I12 -> 2878 | T12: ='Color classification'!J12 -> 0 | U12: ='Color classification'!K12 -> 0 | V12: ='Color classification'!L12 -> 157122 | W12: ='Color classification'!M12 -> 0 | X12: ='Color classification'!N12 -> 2845 | Y12: ='Color classification'!O12 -> 0 | ... AA12: ='Color classification'!Q12 -> 157067
B13: 9 | C13: 0 | D13: 3394 | E13: 0 | F13: 0 | G13: 156606 | H13: ='Color clustering'!H13 -> 0 | I13: ='Color clustering'!I13 -> 3373 | J13: ='Color clustering'!J13 -> 0 | K13: ='Color clustering'!K13 -> 0 | L13: ='Color clustering'!L13 -> 156627 | M13: ='Color clustering'!M13 -> 0 | N13: ='Color clustering'!N13 -> 3322 | O13: ='Color clustering'!O13 -> 0 | ... Q13: ='Color clustering'!Q13 -> 156573 | R13: ='Color classification'!H13 -> 0 | S13: ='Color classification'!I13 -> 3350 | T13: ='Color classification'!J13 -> 0 | U13: ='Color classification'!K13 -> 0 | V13: ='Color classification'!L13 -> 156650 | W13: ='Color classification'!M13 -> 0 | X13: ='Color classification'!N13 -> 3359 | Y13: ='Color classification'!O13 -> 0 | ... AA13: ='Color classification'!Q13 -> 156588
B14: 10 | C14: 0 | D14: 3925 | E14: 0 | F14: 0 | G14: 156075 | H14: ='Color clustering'!H14 -> 0 | I14: ='Color clustering'!I14 -> 3866 | J14: ='Color clustering'!J14 -> 0 | K14: ='Color clustering'!K14 -> 0 | L14: ='Color clustering'!L14 -> 156134 | M14: ='Color clustering'!M14 -> 0 | N14: ='Color clustering'!N14 -> 3815 | O14: ='Color clustering'!O14 -> 0 | ... Q14: ='Color clustering'!Q14 -> 156023 | R14: ='Color classification'!H14 -> 0 | S14: ='Color classification'!I14 -> 3895 | T14: ='Color classification'!J14 -> 0 | U14: ='Color classification'!K14 -> 0 | V14: ='Color classification'!L14 -> 156105 | W14: ='Color classification'!M14 -> 0 | X14: ='Color classification'!N14 -> 3849 | Y14: ='Color classification'!O14 -> 0 | ... AA14: ='Color classification'!Q14 -> 156040
B15: 11 | C15: 0 | D15: 4472 | E15: 0 | F15: 0 | G15: 155528 | H15: ='Color clustering'!H15 -> 0 | I15: ='Color clustering'!I15 -> 4379 | J15: ='Color clustering'!J15 -> 0 | K15: ='Color clustering'!K15 -> 0 | L15: ='Color clustering'!L15 -> 155621 | M15: ='Color clustering'!M15 -> 0 | N15: ='Color clustering'!N15 -> 4349 | O15: ='Color clustering'!O15 -> 0 | ... Q15: ='Color clustering'!Q15 -> 155494 | R15: ='Color classification'!H15 -> 0 | S15: ='Color classification'!I15 -> 4419 | T15: ='Color classification'!J15 -> 0 | U15: ='Color classification'!K15 -> 0 | V15: ='Color classification'!L15 -> 155581 | W15: ='Color classification'!M15 -> 0 | X15: ='Color classification'!N15 -> 4391 | Y15: ='Color classification'!O15 -> 0 | ... AA15: ='Color classification'!Q15 -> 155513
... B186: 182 | C186: 0 | D186: 79 | E186: 0 | F186: 0 | G186: 159921 | H186: ='Color clustering'!H186 -> 0 | I186: ='Color clustering'!I186 -> 75 | J186: ='Color clustering'!J186 -> 0 | K186: ='Color clustering'!K186 -> 0 | L186: ='Color clustering'!L186 -> 159925 | M186: ='Color clustering'!M186 -> 0 | N186: ='Color clustering'!N186 -> 68 | O186: ='Color clustering'!O186 -> 0 | ... Q186: ='Color clustering'!Q186 -> 159914 | R186: ='Color classification'!H186 -> 0 | S186: ='Color classification'!I186 -> 80 | T186: ='Color classification'!J186 -> 0 | U186: ='Color classification'!K186 -> 0 | V186: ='Color classification'!L186 -> 159920 | W186: ='Color classification'!M186 -> 0 | X186: ='Color classification'!N186 -> 73 | Y186: ='Color classification'!O186 -> 0 | ... AA186: ='Color classification'!Q186 -> 159918
B187: Total | C187: =SUM(C4:C186) -> 240143 | D187: =SUM(D4:D186) -> 1885811 | E187: =SUM(E4:E186) -> 105525 | F187: =SUM(F4:F186) -> 38964 | G187: =SUM(G4:G186) -> 27009557 | H187: =SUM(H4:H186) -> 241221 | I187: =SUM(I4:I186) -> 1982369 | J187: =SUM(J4:J186) -> 0 | ... AA187: =SUM(AA4:AA186) -> 27000142
B192: image | C192: Abolute Error Clustering | M192: Abolute Error Classification | W192: SMAPE Clustering | AI192: SMAPE Classification
C193: Random correction | H193: Color classification | M193: Random correction | R193: Color classification | W193: Random correction | AC193: Color classification | AI193: Random correction | AO193: Color classification
A194: 4_filled_cylinder/f_cyl_axis_unal | C194: #c88637 | D194: #e3bb37 | E194: #e65a49 | F194: #efab8c | G194: #fdfdfd | H194: #c88637 | I194: #e3bb37 | J194: #e65a49 | K194: #efab8c | L194: #fdfdfd | M194: #c78637 | N194: #e3bb37 | O194: #e65a49 | P194: #f08a8c | Q194: #ffffff | R194: #c78637 | S194: #e3bb37 | T194: #e65a49 | U194: #f08a8c | V194: #ffffff | W194: #c88637 | X194: #e3bb37 | Y194: #e65a49 | Z194: #efab8c | AA194: #fdfdfd | AC194: #c88637 | AD194: #e3bb37 | AE194: #e65a49 | AF194: #efab8c | AG194: #fdfdfd | AI194: #c78637 | AJ194: #e3bb37 | AK194: #e65a49 | AL194: #f08a8c | AM194: #ffffff | AO194: #c78637 | AP194: #e3bb37 | AQ194: #e65a49 | AR194: #f08a8c | AS194: #ffffff
B195: 0 | C195: =ABS(H4-C4) -> 0 | D195: =ABS(I4-D4) -> 19 | E195: =ABS(J4-E4) -> 0 | F195: =ABS(K4-F4) -> 38 | G195: =ABS(L4-G4) -> 19 | H195: =ABS(M4-C4) -> 0 | I195: =ABS(N4-D4) -> 19 | J195: =ABS(O4-E4) -> 0 | K195: =ABS(P4-F4) -> 38 | L195: =ABS(Q4-G4) -> 19 | M195: =ABS(R4-C4) -> 0 | N195: =ABS(S4-D4) -> 19 | O195: =ABS(T4-E4) -> 0 | P195: =ABS(U4-F4) -> 38 | Q195: =ABS(V4-G4) -> 19 | R195: =ABS(W4-C4) -> 0 | S195: =ABS(X4-D4) -> 19 | T195: =ABS(Y4-E4) -> 0 | U195: =ABS(Z4-F4) -> 38 | V195: =ABS(AA4-G4) -> 19 | W195: =IF(AND(C4=0,H4=0), 0, ABS(C4-H4)/((ABS(C4)+ABS(H4))/2)) -> 0 | X195: =IF(AND(D4=0,I4=0), 0, ABS(D4-I4)/((ABS(D4)+ABS(I4))/2)) -> 0.27338129 | Y195: =IF(AND(E4=0,J4=0), 0, ABS(E4-J4)/((ABS(E4)+ABS(J4))/2)) -> 0 | Z195: =IF(AND(F4=0,K4=0), 0, ABS(F4-K4)/((ABS(F4)+ABS(K4))/2)) -> 2 | AA195: =IF(AND(G4=0,L4=0), 0, ABS(G4-L4)/((ABS(G4)+ABS(L4))/2)) -> 0.00011881572 | AC195: =IF(AND(C4=0,M4=0), 0, ABS(C4-M4)/((ABS(C4)+ABS(M4))/2)) -> 0 | AD195: =IF(AND(D4=0,N4=0), 0, ABS(D4-N4)/((ABS(D4)+ABS(N4))/2)) -> 0.27338129 | AE195: =IF(AND(E4=0,O4=0), 0, ABS(E4-O4)/((ABS(E4)+ABS(O4))/2)) -> 0 | AF195: =IF(AND(F4=0,P4=0), 0, ABS(F4-P4)/((ABS(F4)+ABS(P4))/2)) -> 2 | AG195: =IF(AND(G4=0,Q4=0), 0, ABS(G4-Q4)/((ABS(G4)+ABS(Q4))/2)) -> 0.00011881572 | AI195: =IF(AND(C4=0,R4=0), 0, ABS(C4-R4)/((ABS(C4)+ABS(R4))/2)) -> 0 | AJ195: =IF(AND(D4=0,S4=0), 0, ABS(D4-S4)/((ABS(D4)+ABS(S4))/2)) -> 0.27338129 | AK195: =IF(AND(E4=0,T4=0), 0, ABS(E4-T4)/((ABS(E4)+ABS(T4))/2)) -> 0 | AL195: =IF(AND(F4=0,U4=0), 0, ABS(F4-U4)/((ABS(F4)+ABS(U4))/2)) -> 2 | AM195: =IF(AND(G4=0,V4=0), 0, ABS(G4-V4)/((ABS(G4)+ABS(V4))/2)) -> 0.00011881572 | AO195: =IF(AND(C4=0,W4=0), 0, ABS(C4-W4)/((ABS(C4)+ABS(W4))/2)) -> 0 | AP195: =IF(AND(D4=0,X4=0), 0, ABS(D4-X4)/((ABS(D4)+ABS(X4))/2)) -> 0.27338129 | AQ195: =IF(AND(E4=0,Y4=0), 0, ABS(E4-Y4)/((ABS(E4)+ABS(Y4))/2)) -> 0 | AR195: =IF(AND(F4=0,Z4=0), 0, ABS(F4-Z4)/((ABS(F4)+ABS(Z4))/2)) -> 2 | AS195: =IF(AND(G4=0,AA4=0), 0, ABS(G4-AA4)/((ABS(G4)+ABS(AA4))/2)) -> 0.00011881572
B196: 1 | C196: =ABS(H5-C5) -> 0 | D196: =ABS(I5-D5) -> 13 | E196: =ABS(J5-E5) -> 0 | F196: =ABS(K5-F5) -> 0 | G196: =ABS(L5-G5) -> 13 | H196: =ABS(M5-C5) -> 0 | I196: =ABS(N5-D5) -> 13 | J196: =ABS(O5-E5) -> 0 | K196: =ABS(P5-F5) -> 15 | L196: =ABS(Q5-G5) -> 2 | M196: =ABS(R5-C5) -> 0 | N196: =ABS(S5-D5) -> 18 | O196: =ABS(T5-E5) -> 0 | P196: =ABS(U5-F5) -> 0 | Q196: =ABS(V5-G5) -> 18 | R196: =ABS(W5-C5) -> 0 | S196: =ABS(X5-D5) -> 4 | T196: =ABS(Y5-E5) -> 0 | U196: =ABS(Z5-F5) -> 4 | V196: =ABS(AA5-G5) -> 0 | W196: =IF(AND(C5=0,H5=0), 0, ABS(C5-H5)/((ABS(C5)+ABS(H5))/2)) -> 0 | X196: =IF(AND(D5=0,I5=0), 0, ABS(D5-I5)/((ABS(D5)+ABS(I5))/2)) -> 0.048964218 | Y196: =IF(AND(E5=0,J5=0), 0, ABS(E5-J5)/((ABS(E5)+ABS(J5))/2)) -> 0 | Z196: =IF(AND(F5=0,K5=0), 0, ABS(F5-K5)/((ABS(F5)+ABS(K5))/2)) -> 0 | AA196: =IF(AND(G5=0,L5=0), 0, ABS(G5-L5)/((ABS(G5)+ABS(L5))/2)) -> 8.1385048e-05 | AC196: =IF(AND(C5=0,M5=0), 0, ABS(C5-M5)/((ABS(C5)+ABS(M5))/2)) -> 0 | AD196: =IF(AND(D5=0,N5=0), 0, ABS(D5-N5)/((ABS(D5)+ABS(N5))/2)) -> 0.048964218 | AE196: =IF(AND(E5=0,O5=0), 0, ABS(E5-O5)/((ABS(E5)+ABS(O5))/2)) -> 0 | AF196: =IF(AND(F5=0,P5=0), 0, ABS(F5-P5)/((ABS(F5)+ABS(P5))/2)) -> 2 | AG196: =IF(AND(G5=0,Q5=0), 0, ABS(G5-Q5)/((ABS(G5)+ABS(Q5))/2)) -> 1.2521365e-05 | AI196: =IF(AND(C5=0,R5=0), 0, ABS(C5-R5)/((ABS(C5)+ABS(R5))/2)) -> 0 | AJ196: =IF(AND(D5=0,S5=0), 0, ABS(D5-S5)/((ABS(D5)+ABS(S5))/2)) -> 0.068441065 | AK196: =IF(AND(E5=0,T5=0), 0, ABS(E5-T5)/((ABS(E5)+ABS(T5))/2)) -> 0 | AL196: =IF(AND(F5=0,U5=0), 0, ABS(F5-U5)/((ABS(F5)+ABS(U5))/2)) -> 0 | AM196: =IF(AND(G5=0,V5=0), 0, ABS(G5-V5)/((ABS(G5)+ABS(V5))/2)) -> 0.00011268523 | AO196: =IF(AND(C5=0,W5=0), 0, ABS(C5-W5)/((ABS(C5)+ABS(W5))/2)) -> 0 | AP196: =IF(AND(D5=0,X5=0), 0, ABS(D5-X5)/((ABS(D5)+ABS(X5))/2)) -> 0.014814815 | AQ196: =IF(AND(E5=0,Y5=0), 0, ABS(E5-Y5)/((ABS(E5)+ABS(Y5))/2)) -> 0 | AR196: =IF(AND(F5=0,Z5=0), 0, ABS(F5-Z5)/((ABS(F5)+ABS(Z5))/2)) -> 2 | AS196: =IF(AND(G5=0,AA5=0), 0, ABS(G5-AA5)/((ABS(G5)+ABS(AA5))/2)) -> 0
B197: 2 | C197: =ABS(H6-C6) -> 0 | D197: =ABS(I6-D6) -> 37 | E197: =ABS(J6-E6) -> 0 | F197: =ABS(K6-F6) -> 0 | G197: =ABS(L6-G6) -> 37 | H197: =ABS(M6-C6) -> 0 | I197: =ABS(N6-D6) -> 50 | J197: =ABS(O6-E6) -> 0 | K197: =ABS(P6-F6) -> 83 | L197: =ABS(Q6-G6) -> 33 | M197: =ABS(R6-C6) -> 0 | N197: =ABS(S6-D6) -> 12 | O197: =ABS(T6-E6) -> 0 | P197: =ABS(U6-F6) -> 1 | Q197: =ABS(V6-G6) -> 11 | R197: =ABS(W6-C6) -> 0 | S197: =ABS(X6-D6) -> 32 | T197: =ABS(Y6-E6) -> 0 | U197: =ABS(Z6-F6) -> 45 | V197: =ABS(AA6-G6) -> 13 | W197: =IF(AND(C6=0,H6=0), 0, ABS(C6-H6)/((ABS(C6)+ABS(H6))/2)) -> 0 | X197: =IF(AND(D6=0,I6=0), 0, ABS(D6-I6)/((ABS(D6)+ABS(I6))/2)) -> 0.072477963 | Y197: =IF(AND(E6=0,J6=0), 0, ABS(E6-J6)/((ABS(E6)+ABS(J6))/2)) -> 0 | Z197: =IF(AND(F6=0,K6=0), 0, ABS(F6-K6)/((ABS(F6)+ABS(K6))/2)) -> 0 | AA197: =IF(AND(G6=0,L6=0), 0, ABS(G6-L6)/((ABS(G6)+ABS(L6))/2)) -> 0.00023199019 | AC197: =IF(AND(C6=0,M6=0), 0, ABS(C6-M6)/((ABS(C6)+ABS(M6))/2)) -> 0 | AD197: =IF(AND(D6=0,N6=0), 0, ABS(D6-N6)/((ABS(D6)+ABS(N6))/2)) -> 0.099206349 | AE197: =IF(AND(E6=0,O6=0), 0, ABS(E6-O6)/((ABS(E6)+ABS(O6))/2)) -> 0 | AF197: =IF(AND(F6=0,P6=0), 0, ABS(F6-P6)/((ABS(F6)+ABS(P6))/2)) -> 2 | AG197: =IF(AND(G6=0,Q6=0), 0, ABS(G6-Q6)/((ABS(G6)+ABS(Q6))/2)) -> 0.00020695559 | AI197: =IF(AND(C6=0,R6=0), 0, ABS(C6-R6)/((ABS(C6)+ABS(R6))/2)) -> 0 | AJ197: =IF(AND(D6=0,S6=0), 0, ABS(D6-S6)/((ABS(D6)+ABS(S6))/2)) -> 0.022944551 | AK197: =IF(AND(E6=0,T6=0), 0, ABS(E6-T6)/((ABS(E6)+ABS(T6))/2)) -> 0 | AL197: =IF(AND(F6=0,U6=0), 0, ABS(F6-U6)/((ABS(F6)+ABS(U6))/2)) -> 2 | AM197: =IF(AND(G6=0,V6=0), 0, ABS(G6-V6)/((ABS(G6)+ABS(V6))/2)) -> 6.897568e-05 | AO197: =IF(AND(C6=0,W6=0), 0, ABS(C6-W6)/((ABS(C6)+ABS(W6))/2)) -> 0 | AP197: =IF(AND(D6=0,X6=0), 0, ABS(D6-X6)/((ABS(D6)+ABS(X6))/2)) -> 0.062378168 | AQ197: =IF(AND(E6=0,Y6=0), 0, ABS(E6-Y6)/((ABS(E6)+ABS(Y6))/2)) -> 0 | AR197: =IF(AND(F6=0,Z6=0), 0, ABS(F6-Z6)/((ABS(F6)+ABS(Z6))/2)) -> 2 | AS197: =IF(AND(G6=0,AA6=0), 0, ABS(G6-AA6)/((ABS(G6)+ABS(AA6))/2)) -> 8.1522847e-05
B198: 3 | C198: =ABS(H7-C7) -> 0 | D198: =ABS(I7-D7) -> 27 | E198: =ABS(J7-E7) -> 0 | F198: =ABS(K7-F7) -> 0 | G198: =ABS(L7-G7) -> 27 | H198: =ABS(M7-C7) -> 0 | I198: =ABS(N7-D7) -> 35 | J198: =ABS(O7-E7) -> 0 | K198: =ABS(P7-F7) -> 57 | L198: =ABS(Q7-G7) -> 22 | M198: =ABS(R7-C7) -> 0 | N198: =ABS(S7-D7) -> 15 | O198: =ABS(T7-E7) -> 0 | P198: =ABS(U7-F7) -> 0 | Q198: =ABS(V7-G7) -> 15 | R198: =ABS(W7-C7) -> 0 | S198: =ABS(X7-D7) -> 17 | T198: =ABS(Y7-E7) -> 0 | U198: =ABS(Z7-F7) -> 26 | V198: =ABS(AA7-G7) -> 9 | W198: =IF(AND(C7=0,H7=0), 0, ABS(C7-H7)/((ABS(C7)+ABS(H7))/2)) -> 0 | X198: =IF(AND(D7=0,I7=0), 0, ABS(D7-I7)/((ABS(D7)+ABS(I7))/2)) -> 0.033067973 | Y198: =IF(AND(E7=0,J7=0), 0, ABS(E7-J7)/((ABS(E7)+ABS(J7))/2)) -> 0 | Z198: =IF(AND(F7=0,K7=0), 0, ABS(F7-K7)/((ABS(F7)+ABS(K7))/2)) -> 0 | AA198: =IF(AND(G7=0,L7=0), 0, ABS(G7-L7)/((ABS(G7)+ABS(L7))/2)) -> 0.00016961557 | AC198: =IF(AND(C7=0,M7=0), 0, ABS(C7-M7)/((ABS(C7)+ABS(M7))/2)) -> 0 | AD198: =IF(AND(D7=0,N7=0), 0, ABS(D7-N7)/((ABS(D7)+ABS(N7))/2)) -> 0.043076923 | AE198: =IF(AND(E7=0,O7=0), 0, ABS(E7-O7)/((ABS(E7)+ABS(O7))/2)) -> 0 | AF198: =IF(AND(F7=0,P7=0), 0, ABS(F7-P7)/((ABS(F7)+ABS(P7))/2)) -> 2 | AG198: =IF(AND(G7=0,Q7=0), 0, ABS(G7-Q7)/((ABS(G7)+ABS(Q7))/2)) -> 0.00013822655 | AI198: =IF(AND(C7=0,R7=0), 0, ABS(C7-R7)/((ABS(C7)+ABS(R7))/2)) -> 0 | AJ198: =IF(AND(D7=0,S7=0), 0, ABS(D7-S7)/((ABS(D7)+ABS(S7))/2)) -> 0.018237082 | AK198: =IF(AND(E7=0,T7=0), 0, ABS(E7-T7)/((ABS(E7)+ABS(T7))/2)) -> 0 | AL198: =IF(AND(F7=0,U7=0), 0, ABS(F7-U7)/((ABS(F7)+ABS(U7))/2)) -> 0 | AM198: =IF(AND(G7=0,V7=0), 0, ABS(G7-V7)/((ABS(G7)+ABS(V7))/2)) -> 9.4234424e-05 | AO198: =IF(AND(C7=0,W7=0), 0, ABS(C7-W7)/((ABS(C7)+ABS(W7))/2)) -> 0 | AP198: =IF(AND(D7=0,X7=0), 0, ABS(D7-X7)/((ABS(D7)+ABS(X7))/2)) -> 0.020693853 | AQ198: =IF(AND(E7=0,Y7=0), 0, ABS(E7-Y7)/((ABS(E7)+ABS(Y7))/2)) -> 0 | AR198: =IF(AND(F7=0,Z7=0), 0, ABS(F7-Z7)/((ABS(F7)+ABS(Z7))/2)) -> 2 | AS198: =IF(AND(G7=0,AA7=0), 0, ABS(G7-AA7)/((ABS(G7)+ABS(AA7))/2)) -> 5.6544917e-05
