Workbook

Sheet all objects (voxels 1x1x1)
B1: object | C1: #f6b354 | F1: #fabeb3 | I1: #d76c3a
A2: 7_clot_2_pt3/Col_class | C2: Volume | D2: Surface | E2: V/S | F2: Volume | G2: Surface | H2: V/S | I2: Volume | J2: Surface | K2: V/S
B3: 1 | C3: 1 | D3: 6 | E3: 0.16666667 | F3: 6438888 | G3: 11369212 | H3: 0.56634426 | I3: 3 | J3: 16 | K3: 0.1875
B4: 2 | C4: 2 | D4: 10 | E4: 0.2 | F4: 9 | G4: 36 | H4: 0.25 | I4: 4 | J4: 18 | K4: 0.22222222
B5: 3 | C5: 1 | D5: 6 | E5: 0.16666667 | F5: 3 | G5: 14 | H5: 0.21428571 | I5: 2 | J5: 10 | K5: 0.2
B6: 4 | C6: 1 | D6: 6 | E6: 0.16666667 | F6: 6 | G6: 26 | H6: 0.23076923 | I6: 1 | J6: 6 | K6: 0.16666667
B7: 5 | C7: 2 | D7: 10 | E7: 0.2 | F7: 2 | G7: 10 | H7: 0.2 | I7: 4 | J7: 18 | K7: 0.22222222
B8: 6 | C8: 2 | D8: 10 | E8: 0.2 | F8: 7 | G8: 30 | H8: 0.23333333 | I8: 1 | J8: 6 | K8: 0.16666667
B9: 7 | C9: 6 | D9: 30 | E9: 0.2 | F9: 4 | G9: 20 | H9: 0.2 | I9: 1 | J9: 6 | K9: 0.16666667
B10: 8 | C10: 7 | D10: 38 | E10: 0.18421053 | F10: 14 | G10: 60 | H10: 0.23333333 | I10: 2 | J10: 12 | K10: 0.16666667
B11: 9 | C11: 1 | D11: 6 | E11: 0.16666667 | F11: 1 | G11: 6 | H11: 0.16666667 | I11: 3 | J11: 16 | K11: 0.1875
B12: 10 | C12: 4 | D12: 18 | E12: 0.22222222 | F12: 1 | G12: 6 | H12: 0.16666667 | I12: 1 | J12: 6 | K12: 0.16666667
B13: 11 | C13: 6 | D13: 32 | E13: 0.1875 | F13: 1 | G13: 6 | H13: 0.16666667 | I13: 1 | J13: 6 | K13: 0.16666667
B14: 12 | C14: 2 | D14: 10 | E14: 0.2 | F14: 5 | G14: 24 | H14: 0.20833333 | I14: 19 | J14: 78 | K14: 0.24358974
... B631: 629 | C631: 2 | D631: 12 | E631: 0.16666667 | F631: 1 | G631: 6 | H631: 0.16666667 | I631: 1 | J631: 6 | K631: 0.16666667
B632: 630 | C632: 1 | D632: 6 | E632: 0.16666667 | F632: 1 | G632: 6 | H632: 0.16666667
B633: 631 | C633: 1 | D633: 6 | E633: 0.16666667 | F633: 2 | G633: 12 | H633: 0.16666667
B634: 632 | C634: 3 | D634: 16 | E634: 0.1875 | F634: 3 | G634: 14 | H634: 0.21428571
B635: 633 | C635: 5 | D635: 24 | E635: 0.20833333 | F635: 1 | G635: 6 | H635: 0.16666667
B636: 634 | C636: 12 | D636: 60 | E636: 0.2 | F636: 24 | G636: 98 | H636: 0.24489796
B637: 635 | C637: 1 | D637: 6 | E637: 0.16666667 | F637: 1 | G637: 6 | H637: 0.16666667
B638: 636 | C638: 1 | D638: 6 | E638: 0.16666667 | F638: 1 | G638: 6 | H638: 0.16666667
B639: 637 | C639: 1 | D639: 6 | E639: 0.16666667 | F639: 1 | G639: 6 | H639: 0.16666667
B640: 638 | C640: 1 | D640: 6 | E640: 0.16666667 | F640: 1 | G640: 6 | H640: 0.16666667
B641: 639 | C641: 1 | D641: 6 | E641: 0.16666667 | F641: 3 | G641: 18 | H641: 0.16666667
B642: 640 | C642: 1 | D642: 6 | E642: 0.16666667 | F642: 1 | G642: 6 | H642: 0.16666667
B643: 641 | C643: 2 | D643: 12 | E643: 0.16666667 | F643: 13 | G643: 70 | H643: 0.18571429
... B755: 753 | C755: 14 | D755: 70 | E755: 0.2 | F755: 1 | G755: 6 | H755: 0.16666667
B756: 754 | C756: 1 | D756: 6 | E756: 0.16666667
B757: 755 | C757: 2 | D757: 12 | E757: 0.16666667 | F757: 2 | G757: 10 | H757: 0.2
B758: 756 | C758: 8 | D758: 40 | E758: 0.2 | F758: 2 | G758: 10 | H758: 0.2
B759: 757 | C759: 1 | D759: 6 | E759: 0.16666667 | F759: 1 | G759: 6 | H759: 0.16666667
B760: 758 | C760: 1 | D760: 6 | E760: 0.16666667 | F760: 1 | G760: 6 | H760: 0.16666667
B761: 759 | C761: 2 | D761: 12 | E761: 0.16666667 | F761: 1 | G761: 6 | H761: 0.16666667
B762: 760 | C762: 1 | D762: 6 | E762: 0.16666667 | F762: 1 | G762: 6 | H762: 0.16666667
B763: 761 | C763: 27 | D763: 108 | E763: 0.25 | F763: 1 | G763: 6 | H763: 0.16666667
B764: 762 | C764: 1 | D764: 6 | E764: 0.16666667 | F764: 1 | G764: 6 | H764: 0.16666667
B765: 763 | C765: 1 | D765: 6 | E765: 0.16666667 | F765: 3 | G765: 14 | H765: 0.21428571
B766: 764 | C766: 1 | D766: 6 | E766: 0.16666667 | F766: 2 | G766: 12 | H766: 0.16666667
B767: 765 | C767: 6 | D767: 32 | E767: 0.1875 | F767: 1 | G767: 6 | H767: 0.16666667
...

Sheet Volume distribution
A1: #fabeb3 | B1: #f6b354 | C1: #d76c3a | E1: categories | F1: Volume | J1: Categories | K1: Volume | L1: Volume | M1: Volume
A2: ='all objects (voxels 1x1x1)'!F3 -> 6438888 | B2: ='all objects (voxels 1x1x1)'!C3 -> 1 | C2: ='all objects (voxels 1x1x1)'!I3 -> 3 | E2: [1, 100[ | F2: =COUNTIF(A$2:A$790, "<100") -> 786 | G2: =COUNTIF(B$2:B$808, "<100") -> 803 | H2: =COUNTIF(C$2:C$630, "<100") -> 626 | J2: [1, 10[ | K2: =COUNTIF(A$2:A$790, "<10") -> 749 | L2: =COUNTIF(A$2:A$437, "<10") -> 414 | M2: =COUNTIF(A$2:A$149, "<10") -> 142
A3: ='all objects (voxels 1x1x1)'!F4 -> 9 | B3: ='all objects (voxels 1x1x1)'!C4 -> 2 | C3: ='all objects (voxels 1x1x1)'!I4 -> 4 | E3: [100, 200[ | F3: =COUNTIF(A$2:A$790, "<200")-SUM(F2) -> 1 | G3: =COUNTIF(B$2:B$808, "<200")-SUM(G2) -> 0 | H3: =COUNTIF(C$2:C$630, "<200")-SUM(H2) -> 1 | J3: [10, 20[ | K3: =COUNTIF(A$2:A$790, "<20")-SUM(K2) -> 25 | L3: =COUNTIF(B$2:B$808, "<20")-SUM(L2) -> 370 | M3: =COUNTIF(C$2:C$630, "<20")-SUM(M2) -> 451
A4: ='all objects (voxels 1x1x1)'!F5 -> 3 | B4: ='all objects (voxels 1x1x1)'!C5 -> 1 | C4: ='all objects (voxels 1x1x1)'!I5 -> 2 | E4: [200, 300[ | F4: =COUNTIF(A$2:A$790, "<300")-SUM(F2:F3) -> 1 | G4: =COUNTIF(B$2:B$808, "<300")-SUM(G2:G3) -> 1 | H4: =COUNTIF(C$2:C$630, "<300")-SUM(H2:H3) -> 0 | J4: [20, 30[ | K4: =COUNTIF(A$2:A$790, "<30")-SUM(K2:K3) -> 6 | L4: =COUNTIF(B$2:B$808, "<30")-SUM(L2:L3) -> 9 | M4: =COUNTIF(C$2:C$630, "<30")-SUM(M2:M3) -> 16
A5: ='all objects (voxels 1x1x1)'!F6 -> 6 | B5: ='all objects (voxels 1x1x1)'!C6 -> 1 | C5: ='all objects (voxels 1x1x1)'!I6 -> 1 | E5: [300,400[ | F5: =COUNTIF(A$2:A$790, "<400")-SUM(F2:F4) -> 0 | G5: =COUNTIF(B$2:B$808, "<400")-SUM(G2:G4) -> 0 | H5: =COUNTIF(C$2:C$630, "<400")-SUM(H2:H4) -> 1 | J5: [30, 40[ | K5: =COUNTIF(A$2:A$790, "<40")-SUM(K2:K4) -> 4 | L5: =COUNTIF(B$2:B$808, "<40")-SUM(L2:L4) -> 5 | M5: =COUNTIF(C$2:C$630, "<40")-SUM(M2:M4) -> 8
A6: ='all objects (voxels 1x1x1)'!F7 -> 2 | B6: ='all objects (voxels 1x1x1)'!C7 -> 2 | C6: ='all objects (voxels 1x1x1)'!I7 -> 4 | E6: [400, 500[ | F6: =COUNTIF(A$2:A$790, "<500")-SUM(F2:F5) -> 0 | G6: =COUNTIF(B$2:B$808, "<500")-SUM(G2:G5) -> 1 | H6: =COUNTIF(C$2:C$630, "<500")-SUM(H2:H5) -> 0 | J6: [40, 50[ | K6: =COUNTIF(A$2:A$790, "<50")-SUM(K2:K5) -> 1 | L6: =COUNTIF(B$2:B$808, "<50")-SUM(L2:L5) -> 0 | M6: =COUNTIF(C$2:C$630, "<50")-SUM(M2:M5) -> 3
A7: ='all objects (voxels 1x1x1)'!F8 -> 7 | B7: ='all objects (voxels 1x1x1)'!C8 -> 2 | C7: ='all objects (voxels 1x1x1)'!I8 -> 1 | E7: [500, 600[ | F7: =COUNTIF(A$2:A$790, "<600")-SUM(F2:F6) -> 0 | G7: =COUNTIF(B$2:B$808, "<600")-SUM(G2:G6) -> 0 | H7: =COUNTIF(C$2:C$630, "<600")-SUM(H2:H6) -> 0 | J7: [50, 60[ | K7: =COUNTIF(A$2:A$790, "<60")-SUM(K2:K6) -> 1 | L7: =COUNTIF(B$2:B$808, "<60")-SUM(L2:L6) -> 1 | M7: =COUNTIF(C$2:C$630, "<60")-SUM(M2:M6) -> 5
A8: ='all objects (voxels 1x1x1)'!F9 -> 4 | B8: ='all objects (voxels 1x1x1)'!C9 -> 6 | C8: ='all objects (voxels 1x1x1)'!I9 -> 1 | J8: [60, 70[ | K8: =COUNTIF(A$2:A$790, "<70")-SUM(K2:K7) -> 0 | L8: =COUNTIF(B$2:B$808, "<70")-SUM(L2:L7) -> 3 | M8: =COUNTIF(C$2:C$630, "<70")-SUM(M2:M7) -> 0
A9: ='all objects (voxels 1x1x1)'!F10 -> 14 | B9: ='all objects (voxels 1x1x1)'!C10 -> 7 | C9: ='all objects (voxels 1x1x1)'!I10 -> 2 | J9: [70, 80[ | K9: =COUNTIF(A$2:A$790, "<80")-SUM(K2:K8) -> 0 | L9: =COUNTIF(B$2:B$808, "<80")-SUM(L2:L8) -> 0 | M9: =COUNTIF(C$2:C$630, "<80")-SUM(M2:M8) -> 1
A10: ='all objects (voxels 1x1x1)'!F11 -> 1 | B10: ='all objects (voxels 1x1x1)'!C11 -> 1 | C10: ='all objects (voxels 1x1x1)'!I11 -> 3 | J10: [80, 90[ | K10: =COUNTIF(A$2:A$790, "<80")-SUM(K2:K9) -> 0 | L10: =COUNTIF(B$2:B$808, "<80")-SUM(L2:L9) -> 0 | M10: =COUNTIF(C$2:C$630, "<80")-SUM(M2:M9) -> 0
A11: ='all objects (voxels 1x1x1)'!F12 -> 1 | B11: ='all objects (voxels 1x1x1)'!C12 -> 4 | C11: ='all objects (voxels 1x1x1)'!I12 -> 1 | J11: [90, 100] | K11: =COUNTIF(A$2:A$790, "<=100")-SUM(K2:K10) -> 0 | L11: =COUNTIF(B$2:B$808, "<=100")-SUM(L2:L10) -> 1 | M11: =COUNTIF(C$2:C$630, "<=100")-SUM(M2:M10) -> 0
A12: ='all objects (voxels 1x1x1)'!F13 -> 1 | B12: ='all objects (voxels 1x1x1)'!C13 -> 6 | C12: ='all objects (voxels 1x1x1)'!I13 -> 1
A13: ='all objects (voxels 1x1x1)'!F14 -> 5 | B13: ='all objects (voxels 1x1x1)'!C14 -> 2 | C13: ='all objects (voxels 1x1x1)'!I14 -> 19
A14: ='all objects (voxels 1x1x1)'!F15 -> 1 | B14: ='all objects (voxels 1x1x1)'!C15 -> 4 | C14: ='all objects (voxels 1x1x1)'!I15 -> 1
A15: ='all objects (voxels 1x1x1)'!F16 -> 1 | B15: ='all objects (voxels 1x1x1)'!C16 -> 5 | C15: ='all objects (voxels 1x1x1)'!I16 -> 1
A16: ='all objects (voxels 1x1x1)'!F17 -> 1 | B16: ='all objects (voxels 1x1x1)'!C17 -> 1 | C16: ='all objects (voxels 1x1x1)'!I17 -> 5
A17: ='all objects (voxels 1x1x1)'!F18 -> 1 | B17: ='all objects (voxels 1x1x1)'!C18 -> 1 | C17: ='all objects (voxels 1x1x1)'!I18 -> 1
A18: ='all objects (voxels 1x1x1)'!F19 -> 1 | B18: ='all objects (voxels 1x1x1)'!C19 -> 25 | C18: ='all objects (voxels 1x1x1)'!I19 -> 1
A19: ='all objects (voxels 1x1x1)'!F20 -> 2 | B19: ='all objects (voxels 1x1x1)'!C20 -> 1 | C19: ='all objects (voxels 1x1x1)'!I20 -> 1
A20: ='all objects (voxels 1x1x1)'!F21 -> 2 | B20: ='all objects (voxels 1x1x1)'!C21 -> 1 | C20: ='all objects (voxels 1x1x1)'!I21 -> 2
A21: ='all objects (voxels 1x1x1)'!F22 -> 8 | B21: ='all objects (voxels 1x1x1)'!C22 -> 2 | C21: ='all objects (voxels 1x1x1)'!I22 -> 1
A22: ='all objects (voxels 1x1x1)'!F23 -> 1 | B22: ='all objects (voxels 1x1x1)'!C23 -> 5 | C22: ='all objects (voxels 1x1x1)'!I23 -> 7
A23: ='all objects (voxels 1x1x1)'!F24 -> 1 | B23: ='all objects (voxels 1x1x1)'!C24 -> 12 | C23: ='all objects (voxels 1x1x1)'!I24 -> 1
... A808: ='all objects (voxels 1x1x1)'!F809 -> 0 | B808: ='all objects (voxels 1x1x1)'!C809 -> 1 | C808: ='all objects (voxels 1x1x1)'!I809 -> 0

Sheet most interest. (voxels real siz
A1: Object | B1: #fabeb3
B2: Volume (μm³) | C2: Surface (μm²) | D2: SA/V | E2: Bounding box | I2: % of the bbox occupied by the object
E3: dimentions | H3: volume
A5: 1 | B5: 4.0481662e+08 | C5: 1.8709639e+08 | D5: =C5/B5 -> 0.46217565 | E5: 117.018 | F5: 4645.26 | G5: 6345 | H5: 3.449009e+09 | I5: =(B5*100)/H5 -> 11.737187
A6: 420 | B6: 7984.564 | C6: 9502.968 | D6: =C6/B6 -> 1.1901674 | E6: 17.73 | F6: 46.098 | G6: 200 | H6: 163463.51 | I6: =(B6*100)/H6 -> 4.8846156
A7: 450 | B7: 13139.951 | C7: 14214.098 | D7: =C7/B7 -> 1.0817467 | E7: 17.73 | F7: 60.282 | G7: 230 | H7: 245823.97 | I7: =(B7*100)/H7 -> 5.3452684
A8: 101 | B8: 1886.117 | C8: 2311.425 | D8: =C8/B8 -> 1.225494 | E8: 7.092 | F8: 39.006 | G8: 45 | H8: 12448.375 | I8: =(B8*100)/H8 -> 15.151512
A9: 319 | B9: 1446.023 | C9: 1537.092 | D9: =C9/B9 -> 1.0629789 | E9: 10.638 | F9: 39.006 | G9: 45 | H9: 18672.562 | I9: =(B9*100)/H9 -> 7.744106
A10: 331 | B10: 2766.306 | C10: 2908.458 | D10: =C10/B10 -> 1.0513869 | E10: 10.638 | F10: 35.46 | G10: 70 | H10: 26405.644 | I10: =(B10*100)/H10 -> 10.476192
A11: 383 | B11: 3646.494 | C11: 3305.567 | D11: =C11/B11 -> 0.90650554 | E11: 3.546 | F11: 31.914 | G11: 80 | H11: 9053.364 | I11: =(B11*100)/H11 -> 40.27778
A12: 459 | B12: 1760.376 | C12: 2144.436 | D12: =C12/B12 -> 1.2181693 | E12: 10.638 | F12: 39.006 | G12: 35 | H12: 14523.104 | I12: =(B12*100)/H12 -> 12.12121
A13: 472 | B13: 2137.6 | C13: 2472.626 | D13: =C13/B13 -> 1.15673 | E13: 7.092 | F13: 35.46 | G13: 70 | H13: 17603.762 | I13: =(B13*100)/H13 -> 12.142859
A14: 500 | B14: 2011.859 | C14: 2215.356 | D14: =C14/B14 -> 1.1011487 | E14: 10.638 | F14: 17.73 | G14: 50 | H14: 9430.587 | I14: =(B14*100)/H14 -> 21.333338
A15: 524 | B15: 1320.282 | C15: 1294.659 | D15: =C15/B15 -> 0.98059278 | E15: 7.092 | F15: 31.914 | G15: 35 | H15: 7921.693 | I15: =(B15*100)/H15 -> 16.666665
A16: 634 | B16: 1508.894 | C16: 1613.799 | D16: =C16/B16 -> 1.0695244 | E16: 3.546 | F16: 28.368 | G16: 40 | H16: 4023.717 | I16: =(B16*100)/H16 -> 37.500003
... A18: 699 | B18: 2137.6 | C18: 2549.333 | D18: =C18/B18 -> 1.1926146 | E18: 14.184 | F18: 35.46 | G18: 75 | H18: 37722.348 | I18: =(B18*100)/H18 -> 5.6666674
A21: Object | B21: #f6b354
B22: Volume (μm³) | C22: Surface (μm²) | D22: SA/V | E22: Bounding box | I22: % of the bbox occupied by the object
E23: dimentions | H23: volume
A25: 36 | B25: 7605139.7 | C25: 5705058.6 | D25: =C25/B25 -> 0.75015829 | E25: 17.73 | F25: 1088.622 | G25: 2290 | H25: 44199904 | I25: =(B25*100)/H25 -> 17.206236
A26: 452 | B26: 12888.469 | C26: 13447.553 | D26: =C26/B26 -> 1.0433786 | E26: 17.73 | F26: 81.558 | G26: 100 | H26: 144602.33 | I26: =(B26*100)/H26 -> 8.9130435
A27: 535 | B27: 2.4830346e+08 | C27: 2.0863531e+08 | D27: =C27/B27 -> 0.84024326 | E27: 117.018 | F27: 4340.304 | G27: 6030 | H27: 3.062599e+09 | I27: =(B27*100)/H27 -> 8.107606
A28: 739 | B28: 30177.878 | C28: 32128.561 | D28: =C28/B28 -> 1.0646395 | E28: 31.914 | F28: 195.03 | G28: 115 | H28: 715781.55 | I28: =(B28*100)/H28 -> 4.2160737
A29: 17 | B29: 1571.764 | C29: 1755.639 | D29: =C29/B29 -> 1.1169864 | E29: 3.546 | F29: 24.822 | G29: 55 | H29: 4841.035 | I29: =(B29*100)/H29 -> 32.46752
A30: 38 | B30: 2263.341 | C30: 2691.173 | D30: =C30/B30 -> 1.1890268 | E30: 7.092 | F30: 42.552 | G30: 55 | H30: 16597.833 | I30: =(B30*100)/H30 -> 13.636364
A31: 85 | B31: 2137.6 | C31: 2640.876 | D31: =C31/B31 -> 1.2354397 | E31: 14.184 | F31: 28.368 | G31: 65 | H31: 26154.161 | I31: =(B31*100)/H31 -> 8.1730781
A32: 173 | B32: 1760.376 | C32: 2275.965 | D32: =C32/B32 -> 1.2928857 | E32: 10.638 | F32: 21.276 | G32: 45 | H32: 15277.551 | I32: =(B32*100)/H32 -> 11.522632
A33: 269 | B33: 2263.341 | C33: 2635.089 | D33: =C33/B33 -> 1.1642475 | E33: 10.638 | F33: 28.368 | G33: 40 | H33: 12071.151 | I33: =(B67*100)/H67 -> 36.363629
A34: 311 | B34: 1446.023 | C34: 1714.392 | D34: =C34/B34 -> 1.1855911 | E34: 7.092 | F34: 35.46 | G34: 35 | H34: 8801.881 | I34: =(B34*100)/H34 -> 16.428568
A35: 376 | B35: 1634.635 | C35: 1977.448 | D35: =C35/B35 -> 1.2097184 | E35: 10.638 | F35: 28.368 | G35: 35 | H35: 10562.257 | I35: =(B35*100)/H35 -> 15.47619
A36: 462 | B36: 3772.235 | C36: 3752.448 | D36: =C36/B36 -> 0.99475457 | E36: 14.184 | F36: 42.552 | G36: 50 | H36: 30177.878 | I36: =(B36*100)/H36 -> 12.500001
A37: 496 | B37: 3520.752 | C37: 4005.193 | D37: =C37/B37 -> 1.1375959 | E37: 14.184 | F37: 46.098 | G37: 70 | H37: 45769.782 | I37: =(B37*100)/H37 -> 7.6923067
A38: 502 | B38: 1634.635 | C38: 2098.665 | D38: =C38/B38 -> 1.2838738 | E38: 10.638 | F38: 39.006 | G38: 35 | H38: 14523.104 | I38: =(B38*100)/H38 -> 11.255411
A39: 503 | B39: 4149.458 | C39: 4481.009 | D39: =C39/B39 -> 1.0799022 | E39: 14.184 | F39: 42.552 | G39: 70 | H39: 42249.03 | I39: =(B39*100)/H39 -> 9.8214279
A40: 526 | B40: 5784.093 | C40: 6307.568 | D40: =C40/B40 -> 1.0905025 | E40: 17.73 | F40: 60.282 | G40: 70 | H40: 74815.99 | I40: =(B40*100)/H40 -> 7.731092
A41: 660 | B41: 1383.153 | C41: 1664.095 | D41: =C41/B41 -> 1.2031171 | E41: 14.184 | F41: 31.914 | G41: 30 | H41: 13580.045 | I41: =(B41*100)/H41 -> 10.185187
A42: 677 | B42: 2263.341 | C42: 2689.91 | D42: =C42/B42 -> 1.1884687 | E42: 17.73 | F42: 31.914 | G42: 45 | H42: 25462.585 | I42: =(B42*100)/H42 -> 8.8888893
A43: 691 | B43: 1886.117 | C43: 1977.448 | D43: =C43/B43 -> 1.0484228 | E43: 14.184 | F43: 28.368 | G43: 50 | H43: 20118.585 | I43: =(B43*100)/H43 -> 9.3749983
A44: 721 | B44: 1571.764 | C44: 1785.312 | D44: =C44/B44 -> 1.1358652 | E44: 10.638 | F44: 24.822 | G44: 50 | H44: 13202.822 | I44: =(B44*100)/H44 -> 11.904758
A45: 761 | B45: 1697.506 | C45: 1749.852 | D45: =C45/B45 -> 1.030837 | E45: 10.638 | F45: 35.46 | G45: 30 | H45: 11316.704 | I45: =(B45*100)/H45 -> 15.000004
...
